django.request ERROR 2023-10-19 11:54:30,733 log 60138 140054707037760 Internal Server Error: /addroutes/
Traceback (most recent call last):
  File "/home/antony.jose/.local/lib/python3.10/site-packages/django/core/handlers/exception.py", line 55, in inner
    response = get_response(request)
  File "/home/antony.jose/.local/lib/python3.10/site-packages/django/core/handlers/base.py", line 197, in _get_response
    response = wrapped_callback(request, *callback_args, **callback_kwargs)
  File "/home/antony.jose/.local/lib/python3.10/site-packages/django/views/decorators/csrf.py", line 56, in wrapper_view
    return view_func(*args, **kwargs)
  File "/home/antony.jose/.local/lib/python3.10/site-packages/django/views/generic/base.py", line 104, in view
    return self.dispatch(request, *args, **kwargs)
  File "/home/antony.jose/.local/lib/python3.10/site-packages/rest_framework/views.py", line 509, in dispatch
    response = self.handle_exception(exc)
  File "/home/antony.jose/.local/lib/python3.10/site-packages/rest_framework/views.py", line 469, in handle_exception
    self.raise_uncaught_exception(exc)
  File "/home/antony.jose/.local/lib/python3.10/site-packages/rest_framework/views.py", line 480, in raise_uncaught_exception
    raise exc
  File "/home/antony.jose/.local/lib/python3.10/site-packages/rest_framework/views.py", line 506, in dispatch
    response = handler(request, *args, **kwargs)
  File "/home/antony.jose/Bus_buddy_new/Bus-Buddy/source_code/web/bus_buddy_back_end/bus_owner/views.py", line 153, in post
    routes_id=serializer.data.id
AttributeError: 'ReturnDict' object has no attribute 'id'
django.request ERROR 2023-10-19 11:57:36,402 log 60658 139742409647680 Internal Server Error: /addroutes/
Traceback (most recent call last):
  File "/home/antony.jose/.local/lib/python3.10/site-packages/django/core/handlers/exception.py", line 55, in inner
    response = get_response(request)
  File "/home/antony.jose/.local/lib/python3.10/site-packages/django/core/handlers/base.py", line 197, in _get_response
    response = wrapped_callback(request, *callback_args, **callback_kwargs)
  File "/home/antony.jose/.local/lib/python3.10/site-packages/django/views/decorators/csrf.py", line 56, in wrapper_view
    return view_func(*args, **kwargs)
  File "/home/antony.jose/.local/lib/python3.10/site-packages/django/views/generic/base.py", line 104, in view
    return self.dispatch(request, *args, **kwargs)
  File "/home/antony.jose/.local/lib/python3.10/site-packages/rest_framework/views.py", line 509, in dispatch
    response = self.handle_exception(exc)
  File "/home/antony.jose/.local/lib/python3.10/site-packages/rest_framework/views.py", line 469, in handle_exception
    self.raise_uncaught_exception(exc)
  File "/home/antony.jose/.local/lib/python3.10/site-packages/rest_framework/views.py", line 480, in raise_uncaught_exception
    raise exc
  File "/home/antony.jose/.local/lib/python3.10/site-packages/rest_framework/views.py", line 506, in dispatch
    response = handler(request, *args, **kwargs)
  File "/home/antony.jose/Bus_buddy_new/Bus-Buddy/source_code/web/bus_buddy_back_end/bus_owner/views.py", line 154, in post
    print(serializer.data.id)
AttributeError: 'ReturnDict' object has no attribute 'id'
django.request ERROR 2023-10-19 12:25:33,113 log 62156 139631683958336 Internal Server Error: /addroutes/
Traceback (most recent call last):
  File "/home/antony.jose/.local/lib/python3.10/site-packages/rest_framework/serializers.py", line 962, in create
    instance = ModelClass._default_manager.create(**validated_data)
  File "/home/antony.jose/.local/lib/python3.10/site-packages/django/db/models/manager.py", line 87, in manager_method
    return getattr(self.get_queryset(), name)(*args, **kwargs)
  File "/home/antony.jose/.local/lib/python3.10/site-packages/django/db/models/query.py", line 656, in create
    obj = self.model(**kwargs)
  File "/home/antony.jose/.local/lib/python3.10/site-packages/django/db/models/base.py", line 567, in __init__
    raise TypeError(
TypeError: Routes() got unexpected keyword arguments: 'location'

During handling of the above exception, another exception occurred:

Traceback (most recent call last):
  File "/home/antony.jose/.local/lib/python3.10/site-packages/django/core/handlers/exception.py", line 55, in inner
    response = get_response(request)
  File "/home/antony.jose/.local/lib/python3.10/site-packages/django/core/handlers/base.py", line 197, in _get_response
    response = wrapped_callback(request, *callback_args, **callback_kwargs)
  File "/home/antony.jose/.local/lib/python3.10/site-packages/django/views/decorators/csrf.py", line 56, in wrapper_view
    return view_func(*args, **kwargs)
  File "/home/antony.jose/.local/lib/python3.10/site-packages/django/views/generic/base.py", line 104, in view
    return self.dispatch(request, *args, **kwargs)
  File "/home/antony.jose/.local/lib/python3.10/site-packages/rest_framework/views.py", line 509, in dispatch
    response = self.handle_exception(exc)
  File "/home/antony.jose/.local/lib/python3.10/site-packages/rest_framework/views.py", line 469, in handle_exception
    self.raise_uncaught_exception(exc)
  File "/home/antony.jose/.local/lib/python3.10/site-packages/rest_framework/views.py", line 480, in raise_uncaught_exception
    raise exc
  File "/home/antony.jose/.local/lib/python3.10/site-packages/rest_framework/views.py", line 506, in dispatch
    response = handler(request, *args, **kwargs)
  File "/home/antony.jose/Bus_buddy_new/Bus-Buddy/source_code/web/bus_buddy_back_end/bus_owner/views.py", line 150, in post
    serializer.save()
  File "/home/antony.jose/.local/lib/python3.10/site-packages/rest_framework/serializers.py", line 212, in save
    self.instance = self.create(validated_data)
  File "/home/antony.jose/.local/lib/python3.10/site-packages/rest_framework/serializers.py", line 981, in create
    raise TypeError(msg)
TypeError: Got a `TypeError` when calling `Routes.objects.create()`. This may be because you have a writable field on the serializer class that is not a valid argument to `Routes.objects.create()`. You may need to make the field read-only, or override the RoutesSerializer.create() method to handle this correctly.
Original exception was:
 Traceback (most recent call last):
  File "/home/antony.jose/.local/lib/python3.10/site-packages/rest_framework/serializers.py", line 962, in create
    instance = ModelClass._default_manager.create(**validated_data)
  File "/home/antony.jose/.local/lib/python3.10/site-packages/django/db/models/manager.py", line 87, in manager_method
    return getattr(self.get_queryset(), name)(*args, **kwargs)
  File "/home/antony.jose/.local/lib/python3.10/site-packages/django/db/models/query.py", line 656, in create
    obj = self.model(**kwargs)
  File "/home/antony.jose/.local/lib/python3.10/site-packages/django/db/models/base.py", line 567, in __init__
    raise TypeError(
TypeError: Routes() got unexpected keyword arguments: 'location'

django.request ERROR 2023-10-24 05:47:10,257 log 34356 140556202133056 Internal Server Error: /addroutes/
Traceback (most recent call last):
  File "/home/antony.jose/.local/lib/python3.10/site-packages/rest_framework/serializers.py", line 962, in create
    instance = ModelClass._default_manager.create(**validated_data)
  File "/home/antony.jose/.local/lib/python3.10/site-packages/django/db/models/manager.py", line 87, in manager_method
    return getattr(self.get_queryset(), name)(*args, **kwargs)
  File "/home/antony.jose/.local/lib/python3.10/site-packages/django/db/models/query.py", line 656, in create
    obj = self.model(**kwargs)
  File "/home/antony.jose/.local/lib/python3.10/site-packages/django/db/models/base.py", line 567, in __init__
    raise TypeError(
TypeError: Routes() got unexpected keyword arguments: 'location'

During handling of the above exception, another exception occurred:

Traceback (most recent call last):
  File "/home/antony.jose/.local/lib/python3.10/site-packages/django/core/handlers/exception.py", line 55, in inner
    response = get_response(request)
  File "/home/antony.jose/.local/lib/python3.10/site-packages/django/core/handlers/base.py", line 197, in _get_response
    response = wrapped_callback(request, *callback_args, **callback_kwargs)
  File "/home/antony.jose/.local/lib/python3.10/site-packages/django/views/decorators/csrf.py", line 56, in wrapper_view
    return view_func(*args, **kwargs)
  File "/home/antony.jose/.local/lib/python3.10/site-packages/django/views/generic/base.py", line 104, in view
    return self.dispatch(request, *args, **kwargs)
  File "/home/antony.jose/.local/lib/python3.10/site-packages/rest_framework/views.py", line 509, in dispatch
    response = self.handle_exception(exc)
  File "/home/antony.jose/.local/lib/python3.10/site-packages/rest_framework/views.py", line 469, in handle_exception
    self.raise_uncaught_exception(exc)
  File "/home/antony.jose/.local/lib/python3.10/site-packages/rest_framework/views.py", line 480, in raise_uncaught_exception
    raise exc
  File "/home/antony.jose/.local/lib/python3.10/site-packages/rest_framework/views.py", line 506, in dispatch
    response = handler(request, *args, **kwargs)
  File "/home/antony.jose/Bus_buddy_new/Bus-Buddy/source_code/web/bus_buddy_back_end/bus_owner/views.py", line 150, in post
    serializer.save()
  File "/home/antony.jose/.local/lib/python3.10/site-packages/rest_framework/serializers.py", line 212, in save
    self.instance = self.create(validated_data)
  File "/home/antony.jose/.local/lib/python3.10/site-packages/rest_framework/serializers.py", line 981, in create
    raise TypeError(msg)
TypeError: Got a `TypeError` when calling `Routes.objects.create()`. This may be because you have a writable field on the serializer class that is not a valid argument to `Routes.objects.create()`. You may need to make the field read-only, or override the RoutesSerializer.create() method to handle this correctly.
Original exception was:
 Traceback (most recent call last):
  File "/home/antony.jose/.local/lib/python3.10/site-packages/rest_framework/serializers.py", line 962, in create
    instance = ModelClass._default_manager.create(**validated_data)
  File "/home/antony.jose/.local/lib/python3.10/site-packages/django/db/models/manager.py", line 87, in manager_method
    return getattr(self.get_queryset(), name)(*args, **kwargs)
  File "/home/antony.jose/.local/lib/python3.10/site-packages/django/db/models/query.py", line 656, in create
    obj = self.model(**kwargs)
  File "/home/antony.jose/.local/lib/python3.10/site-packages/django/db/models/base.py", line 567, in __init__
    raise TypeError(
TypeError: Routes() got unexpected keyword arguments: 'location'

django.request ERROR 2023-10-24 06:47:56,254 log 40690 139931565418048 Internal Server Error: /Add-Routes/
Traceback (most recent call last):
  File "/home/antony.jose/.local/lib/python3.10/site-packages/django/core/handlers/exception.py", line 55, in inner
    response = get_response(request)
  File "/home/antony.jose/.local/lib/python3.10/site-packages/django/core/handlers/base.py", line 197, in _get_response
    response = wrapped_callback(request, *callback_args, **callback_kwargs)
  File "/home/antony.jose/.local/lib/python3.10/site-packages/django/views/decorators/csrf.py", line 56, in wrapper_view
    return view_func(*args, **kwargs)
  File "/home/antony.jose/.local/lib/python3.10/site-packages/django/views/generic/base.py", line 104, in view
    return self.dispatch(request, *args, **kwargs)
  File "/home/antony.jose/.local/lib/python3.10/site-packages/rest_framework/views.py", line 509, in dispatch
    response = self.handle_exception(exc)
  File "/home/antony.jose/.local/lib/python3.10/site-packages/rest_framework/views.py", line 469, in handle_exception
    self.raise_uncaught_exception(exc)
  File "/home/antony.jose/.local/lib/python3.10/site-packages/rest_framework/views.py", line 480, in raise_uncaught_exception
    raise exc
  File "/home/antony.jose/.local/lib/python3.10/site-packages/rest_framework/views.py", line 506, in dispatch
    response = handler(request, *args, **kwargs)
  File "/home/antony.jose/Bus_buddy_new/Bus-Buddy/source_code/web/bus_buddy_back_end/bus_owner/views.py", line 149, in post
    if serializer.is_valid():
  File "/home/antony.jose/.local/lib/python3.10/site-packages/rest_framework/serializers.py", line 227, in is_valid
    self._validated_data = self.run_validation(self.initial_data)
  File "/home/antony.jose/.local/lib/python3.10/site-packages/rest_framework/serializers.py", line 426, in run_validation
    value = self.to_internal_value(data)
  File "/home/antony.jose/.local/lib/python3.10/site-packages/rest_framework/serializers.py", line 483, in to_internal_value
    validated_value = field.run_validation(primitive_value)
  File "/home/antony.jose/.local/lib/python3.10/site-packages/rest_framework/serializers.py", line 618, in run_validation
    value = self.to_internal_value(data)
  File "/home/antony.jose/.local/lib/python3.10/site-packages/rest_framework/serializers.py", line 666, in to_internal_value
    validated = self.child.run_validation(item)
  File "/home/antony.jose/.local/lib/python3.10/site-packages/rest_framework/serializers.py", line 426, in run_validation
    value = self.to_internal_value(data)
  File "/home/antony.jose/.local/lib/python3.10/site-packages/rest_framework/serializers.py", line 479, in to_internal_value
    for field in fields:
  File "/home/antony.jose/.local/lib/python3.10/site-packages/rest_framework/serializers.py", line 362, in _writable_fields
    for field in self.fields.values():
  File "/home/antony.jose/.local/lib/python3.10/site-packages/django/utils/functional.py", line 57, in __get__
    res = instance.__dict__[self.name] = self.func(instance)
  File "/home/antony.jose/.local/lib/python3.10/site-packages/rest_framework/serializers.py", line 356, in fields
    for key, value in self.get_fields().items():
  File "/home/antony.jose/.local/lib/python3.10/site-packages/rest_framework/serializers.py", line 1052, in get_fields
    field_names = self.get_field_names(declared_fields, info)
  File "/home/antony.jose/.local/lib/python3.10/site-packages/rest_framework/serializers.py", line 1148, in get_field_names
    assert field_name in fields, (
AssertionError: The field 'pick_and_drop' was declared on serializer StartStopLocationsSerializer, but has not been included in the 'fields' option.
django.request ERROR 2023-10-24 06:49:04,087 log 40845 140503422068288 Internal Server Error: /Add-Routes/
Traceback (most recent call last):
  File "/home/antony.jose/.local/lib/python3.10/site-packages/rest_framework/serializers.py", line 962, in create
    instance = ModelClass._default_manager.create(**validated_data)
  File "/home/antony.jose/.local/lib/python3.10/site-packages/django/db/models/manager.py", line 87, in manager_method
    return getattr(self.get_queryset(), name)(*args, **kwargs)
  File "/home/antony.jose/.local/lib/python3.10/site-packages/django/db/models/query.py", line 656, in create
    obj = self.model(**kwargs)
  File "/home/antony.jose/.local/lib/python3.10/site-packages/django/db/models/base.py", line 567, in __init__
    raise TypeError(
TypeError: Routes() got unexpected keyword arguments: 'location'

During handling of the above exception, another exception occurred:

Traceback (most recent call last):
  File "/home/antony.jose/.local/lib/python3.10/site-packages/django/core/handlers/exception.py", line 55, in inner
    response = get_response(request)
  File "/home/antony.jose/.local/lib/python3.10/site-packages/django/core/handlers/base.py", line 197, in _get_response
    response = wrapped_callback(request, *callback_args, **callback_kwargs)
  File "/home/antony.jose/.local/lib/python3.10/site-packages/django/views/decorators/csrf.py", line 56, in wrapper_view
    return view_func(*args, **kwargs)
  File "/home/antony.jose/.local/lib/python3.10/site-packages/django/views/generic/base.py", line 104, in view
    return self.dispatch(request, *args, **kwargs)
  File "/home/antony.jose/.local/lib/python3.10/site-packages/rest_framework/views.py", line 509, in dispatch
    response = self.handle_exception(exc)
  File "/home/antony.jose/.local/lib/python3.10/site-packages/rest_framework/views.py", line 469, in handle_exception
    self.raise_uncaught_exception(exc)
  File "/home/antony.jose/.local/lib/python3.10/site-packages/rest_framework/views.py", line 480, in raise_uncaught_exception
    raise exc
  File "/home/antony.jose/.local/lib/python3.10/site-packages/rest_framework/views.py", line 506, in dispatch
    response = handler(request, *args, **kwargs)
  File "/home/antony.jose/Bus_buddy_new/Bus-Buddy/source_code/web/bus_buddy_back_end/bus_owner/views.py", line 150, in post
    serializer.save()
  File "/home/antony.jose/.local/lib/python3.10/site-packages/rest_framework/serializers.py", line 212, in save
    self.instance = self.create(validated_data)
  File "/home/antony.jose/.local/lib/python3.10/site-packages/rest_framework/serializers.py", line 981, in create
    raise TypeError(msg)
TypeError: Got a `TypeError` when calling `Routes.objects.create()`. This may be because you have a writable field on the serializer class that is not a valid argument to `Routes.objects.create()`. You may need to make the field read-only, or override the RoutesSerializer.create() method to handle this correctly.
Original exception was:
 Traceback (most recent call last):
  File "/home/antony.jose/.local/lib/python3.10/site-packages/rest_framework/serializers.py", line 962, in create
    instance = ModelClass._default_manager.create(**validated_data)
  File "/home/antony.jose/.local/lib/python3.10/site-packages/django/db/models/manager.py", line 87, in manager_method
    return getattr(self.get_queryset(), name)(*args, **kwargs)
  File "/home/antony.jose/.local/lib/python3.10/site-packages/django/db/models/query.py", line 656, in create
    obj = self.model(**kwargs)
  File "/home/antony.jose/.local/lib/python3.10/site-packages/django/db/models/base.py", line 567, in __init__
    raise TypeError(
TypeError: Routes() got unexpected keyword arguments: 'location'

django.request ERROR 2023-10-24 10:19:24,280 log 57215 140483357566528 Internal Server Error: /View-Routes/1/
Traceback (most recent call last):
  File "/home/antony.jose/.local/lib/python3.10/site-packages/rest_framework/fields.py", line 446, in get_attribute
    return get_attribute(instance, self.source_attrs)
  File "/home/antony.jose/.local/lib/python3.10/site-packages/rest_framework/fields.py", line 94, in get_attribute
    instance = instance[attr]
KeyError: 'user'

During handling of the above exception, another exception occurred:

Traceback (most recent call last):
  File "/home/antony.jose/.local/lib/python3.10/site-packages/django/core/handlers/exception.py", line 55, in inner
    response = get_response(request)
  File "/home/antony.jose/.local/lib/python3.10/site-packages/django/core/handlers/base.py", line 197, in _get_response
    response = wrapped_callback(request, *callback_args, **callback_kwargs)
  File "/home/antony.jose/.local/lib/python3.10/site-packages/django/views/decorators/csrf.py", line 56, in wrapper_view
    return view_func(*args, **kwargs)
  File "/home/antony.jose/.local/lib/python3.10/site-packages/django/views/generic/base.py", line 104, in view
    return self.dispatch(request, *args, **kwargs)
  File "/home/antony.jose/.local/lib/python3.10/site-packages/rest_framework/views.py", line 509, in dispatch
    response = self.handle_exception(exc)
  File "/home/antony.jose/.local/lib/python3.10/site-packages/rest_framework/views.py", line 469, in handle_exception
    self.raise_uncaught_exception(exc)
  File "/home/antony.jose/.local/lib/python3.10/site-packages/rest_framework/views.py", line 480, in raise_uncaught_exception
    raise exc
  File "/home/antony.jose/.local/lib/python3.10/site-packages/rest_framework/views.py", line 506, in dispatch
    response = handler(request, *args, **kwargs)
  File "/home/antony.jose/Bus_buddy_new/Bus-Buddy/source_code/web/bus_buddy_back_end/bus_owner/views.py", line 166, in get
    return Response(serializer.data)
  File "/home/antony.jose/.local/lib/python3.10/site-packages/rest_framework/serializers.py", line 768, in data
    ret = super().data
  File "/home/antony.jose/.local/lib/python3.10/site-packages/rest_framework/serializers.py", line 253, in data
    self._data = self.to_representation(self.instance)
  File "/home/antony.jose/.local/lib/python3.10/site-packages/rest_framework/serializers.py", line 686, in to_representation
    return [
  File "/home/antony.jose/.local/lib/python3.10/site-packages/rest_framework/serializers.py", line 687, in <listcomp>
    self.child.to_representation(item) for item in iterable
  File "/home/antony.jose/.local/lib/python3.10/site-packages/rest_framework/serializers.py", line 509, in to_representation
    attribute = field.get_attribute(instance)
  File "/home/antony.jose/.local/lib/python3.10/site-packages/rest_framework/relations.py", line 190, in get_attribute
    return super().get_attribute(instance)
  File "/home/antony.jose/.local/lib/python3.10/site-packages/rest_framework/fields.py", line 479, in get_attribute
    raise type(exc)(msg)
KeyError: "Got KeyError when attempting to get a value for field `user` on serializer `ViewRoutesSerializer`.\nThe serializer field might be named incorrectly and not match any attribute or key on the `dict` instance.\nOriginal exception text was: 'user'."
django.request ERROR 2023-10-24 10:21:39,292 log 57732 139716548617792 Internal Server Error: /View-Routes/1/
Traceback (most recent call last):
  File "/home/antony.jose/.local/lib/python3.10/site-packages/rest_framework/fields.py", line 446, in get_attribute
    return get_attribute(instance, self.source_attrs)
  File "/home/antony.jose/.local/lib/python3.10/site-packages/rest_framework/fields.py", line 94, in get_attribute
    instance = instance[attr]
KeyError: 'start_point'

During handling of the above exception, another exception occurred:

Traceback (most recent call last):
  File "/home/antony.jose/.local/lib/python3.10/site-packages/django/core/handlers/exception.py", line 55, in inner
    response = get_response(request)
  File "/home/antony.jose/.local/lib/python3.10/site-packages/django/core/handlers/base.py", line 197, in _get_response
    response = wrapped_callback(request, *callback_args, **callback_kwargs)
  File "/home/antony.jose/.local/lib/python3.10/site-packages/django/views/decorators/csrf.py", line 56, in wrapper_view
    return view_func(*args, **kwargs)
  File "/home/antony.jose/.local/lib/python3.10/site-packages/django/views/generic/base.py", line 104, in view
    return self.dispatch(request, *args, **kwargs)
  File "/home/antony.jose/.local/lib/python3.10/site-packages/rest_framework/views.py", line 509, in dispatch
    response = self.handle_exception(exc)
  File "/home/antony.jose/.local/lib/python3.10/site-packages/rest_framework/views.py", line 469, in handle_exception
    self.raise_uncaught_exception(exc)
  File "/home/antony.jose/.local/lib/python3.10/site-packages/rest_framework/views.py", line 480, in raise_uncaught_exception
    raise exc
  File "/home/antony.jose/.local/lib/python3.10/site-packages/rest_framework/views.py", line 506, in dispatch
    response = handler(request, *args, **kwargs)
  File "/home/antony.jose/Bus_buddy_new/Bus-Buddy/source_code/web/bus_buddy_back_end/bus_owner/views.py", line 166, in get
    return Response(serializer.data)
  File "/home/antony.jose/.local/lib/python3.10/site-packages/rest_framework/serializers.py", line 768, in data
    ret = super().data
  File "/home/antony.jose/.local/lib/python3.10/site-packages/rest_framework/serializers.py", line 253, in data
    self._data = self.to_representation(self.instance)
  File "/home/antony.jose/.local/lib/python3.10/site-packages/rest_framework/serializers.py", line 686, in to_representation
    return [
  File "/home/antony.jose/.local/lib/python3.10/site-packages/rest_framework/serializers.py", line 687, in <listcomp>
    self.child.to_representation(item) for item in iterable
  File "/home/antony.jose/.local/lib/python3.10/site-packages/rest_framework/serializers.py", line 509, in to_representation
    attribute = field.get_attribute(instance)
  File "/home/antony.jose/.local/lib/python3.10/site-packages/rest_framework/relations.py", line 190, in get_attribute
    return super().get_attribute(instance)
  File "/home/antony.jose/.local/lib/python3.10/site-packages/rest_framework/fields.py", line 479, in get_attribute
    raise type(exc)(msg)
KeyError: "Got KeyError when attempting to get a value for field `start_point` on serializer `ViewRoutesSerializer`.\nThe serializer field might be named incorrectly and not match any attribute or key on the `dict` instance.\nOriginal exception text was: 'start_point'."
