django.request ERROR 2023-10-11 07:27:06,322 log 62823 140488380249664 Internal Server Error: /user/registration/
Traceback (most recent call last):
  File "/home/farsana.ka/Documents/Bus Buddy/source_code/web/env/lib/python3.10/site-packages/django/core/handlers/exception.py", line 55, in inner
    response = get_response(request)
  File "/home/farsana.ka/Documents/Bus Buddy/source_code/web/env/lib/python3.10/site-packages/django/core/handlers/base.py", line 197, in _get_response
    response = wrapped_callback(request, *callback_args, **callback_kwargs)
  File "/home/farsana.ka/Documents/Bus Buddy/source_code/web/env/lib/python3.10/site-packages/django/views/decorators/csrf.py", line 56, in wrapper_view
    return view_func(*args, **kwargs)
  File "/home/farsana.ka/Documents/Bus Buddy/source_code/web/env/lib/python3.10/site-packages/django/views/generic/base.py", line 104, in view
    return self.dispatch(request, *args, **kwargs)
  File "/home/farsana.ka/Documents/Bus Buddy/source_code/web/env/lib/python3.10/site-packages/rest_framework/views.py", line 509, in dispatch
    response = self.handle_exception(exc)
  File "/home/farsana.ka/Documents/Bus Buddy/source_code/web/env/lib/python3.10/site-packages/rest_framework/views.py", line 469, in handle_exception
    self.raise_uncaught_exception(exc)
  File "/home/farsana.ka/Documents/Bus Buddy/source_code/web/env/lib/python3.10/site-packages/rest_framework/views.py", line 480, in raise_uncaught_exception
    raise exc
  File "/home/farsana.ka/Documents/Bus Buddy/source_code/web/env/lib/python3.10/site-packages/rest_framework/views.py", line 506, in dispatch
    response = handler(request, *args, **kwargs)
  File "/home/farsana.ka/Documents/Bus Buddy/source_code/web/bus_buddy_back_end/normal_user/views.py", line 15, in post
    if serialized_data.is_valid():
  File "/home/farsana.ka/Documents/Bus Buddy/source_code/web/env/lib/python3.10/site-packages/rest_framework/serializers.py", line 227, in is_valid
    self._validated_data = self.run_validation(self.initial_data)
  File "/home/farsana.ka/Documents/Bus Buddy/source_code/web/env/lib/python3.10/site-packages/rest_framework/serializers.py", line 426, in run_validation
    value = self.to_internal_value(data)
  File "/home/farsana.ka/Documents/Bus Buddy/source_code/web/env/lib/python3.10/site-packages/rest_framework/serializers.py", line 479, in to_internal_value
    for field in fields:
  File "/home/farsana.ka/Documents/Bus Buddy/source_code/web/env/lib/python3.10/site-packages/rest_framework/serializers.py", line 362, in _writable_fields
    for field in self.fields.values():
  File "/home/farsana.ka/Documents/Bus Buddy/source_code/web/env/lib/python3.10/site-packages/django/utils/functional.py", line 57, in __get__
    res = instance.__dict__[self.name] = self.func(instance)
  File "/home/farsana.ka/Documents/Bus Buddy/source_code/web/env/lib/python3.10/site-packages/rest_framework/serializers.py", line 356, in fields
    for key, value in self.get_fields().items():
  File "/home/farsana.ka/Documents/Bus Buddy/source_code/web/env/lib/python3.10/site-packages/rest_framework/serializers.py", line 1027, in get_fields
    assert hasattr(self, 'Meta'), (
AssertionError: Class UserModelSerializer missing "Meta" attribute
django.request ERROR 2023-10-11 08:37:24,738 log 67433 140543587771968 Internal Server Error: /user/registration/
Traceback (most recent call last):
  File "/home/farsana.ka/Documents/Bus Buddy/source_code/web/env/lib/python3.10/site-packages/django/core/handlers/exception.py", line 55, in inner
    response = get_response(request)
  File "/home/farsana.ka/Documents/Bus Buddy/source_code/web/env/lib/python3.10/site-packages/django/core/handlers/base.py", line 197, in _get_response
    response = wrapped_callback(request, *callback_args, **callback_kwargs)
  File "/home/farsana.ka/Documents/Bus Buddy/source_code/web/env/lib/python3.10/site-packages/django/views/decorators/csrf.py", line 56, in wrapper_view
    return view_func(*args, **kwargs)
  File "/home/farsana.ka/Documents/Bus Buddy/source_code/web/env/lib/python3.10/site-packages/django/views/generic/base.py", line 104, in view
    return self.dispatch(request, *args, **kwargs)
  File "/home/farsana.ka/Documents/Bus Buddy/source_code/web/env/lib/python3.10/site-packages/rest_framework/views.py", line 509, in dispatch
    response = self.handle_exception(exc)
  File "/home/farsana.ka/Documents/Bus Buddy/source_code/web/env/lib/python3.10/site-packages/rest_framework/views.py", line 469, in handle_exception
    self.raise_uncaught_exception(exc)
  File "/home/farsana.ka/Documents/Bus Buddy/source_code/web/env/lib/python3.10/site-packages/rest_framework/views.py", line 480, in raise_uncaught_exception
    raise exc
  File "/home/farsana.ka/Documents/Bus Buddy/source_code/web/env/lib/python3.10/site-packages/rest_framework/views.py", line 506, in dispatch
    response = handler(request, *args, **kwargs)
  File "/home/farsana.ka/Documents/Bus Buddy/source_code/web/bus_buddy_back_end/normal_user/views.py", line 15, in post
    if serialized_data.is_valid():
  File "/home/farsana.ka/Documents/Bus Buddy/source_code/web/env/lib/python3.10/site-packages/rest_framework/serializers.py", line 227, in is_valid
    self._validated_data = self.run_validation(self.initial_data)
  File "/home/farsana.ka/Documents/Bus Buddy/source_code/web/env/lib/python3.10/site-packages/rest_framework/serializers.py", line 426, in run_validation
    value = self.to_internal_value(data)
  File "/home/farsana.ka/Documents/Bus Buddy/source_code/web/env/lib/python3.10/site-packages/rest_framework/serializers.py", line 483, in to_internal_value
    validated_value = field.run_validation(primitive_value)
  File "/home/farsana.ka/Documents/Bus Buddy/source_code/web/env/lib/python3.10/site-packages/rest_framework/fields.py", line 548, in run_validation
    self.run_validators(value)
  File "/home/farsana.ka/Documents/Bus Buddy/source_code/web/env/lib/python3.10/site-packages/rest_framework/fields.py", line 562, in run_validators
    validator(value)
TypeError: max_digit() missing 1 required positional argument: 'value'
django.request ERROR 2023-10-11 08:42:35,333 log 67843 140370548614720 Internal Server Error: /user/registration/
Traceback (most recent call last):
  File "/home/farsana.ka/Documents/Bus Buddy/source_code/web/env/lib/python3.10/site-packages/django/core/handlers/exception.py", line 55, in inner
    response = get_response(request)
  File "/home/farsana.ka/Documents/Bus Buddy/source_code/web/env/lib/python3.10/site-packages/django/core/handlers/base.py", line 197, in _get_response
    response = wrapped_callback(request, *callback_args, **callback_kwargs)
  File "/home/farsana.ka/Documents/Bus Buddy/source_code/web/env/lib/python3.10/site-packages/django/views/decorators/csrf.py", line 56, in wrapper_view
    return view_func(*args, **kwargs)
  File "/home/farsana.ka/Documents/Bus Buddy/source_code/web/env/lib/python3.10/site-packages/django/views/generic/base.py", line 104, in view
    return self.dispatch(request, *args, **kwargs)
  File "/home/farsana.ka/Documents/Bus Buddy/source_code/web/env/lib/python3.10/site-packages/rest_framework/views.py", line 509, in dispatch
    response = self.handle_exception(exc)
  File "/home/farsana.ka/Documents/Bus Buddy/source_code/web/env/lib/python3.10/site-packages/rest_framework/views.py", line 469, in handle_exception
    self.raise_uncaught_exception(exc)
  File "/home/farsana.ka/Documents/Bus Buddy/source_code/web/env/lib/python3.10/site-packages/rest_framework/views.py", line 480, in raise_uncaught_exception
    raise exc
  File "/home/farsana.ka/Documents/Bus Buddy/source_code/web/env/lib/python3.10/site-packages/rest_framework/views.py", line 506, in dispatch
    response = handler(request, *args, **kwargs)
  File "/home/farsana.ka/Documents/Bus Buddy/source_code/web/bus_buddy_back_end/normal_user/views.py", line 15, in post
    if serialized_data.is_valid():
  File "/home/farsana.ka/Documents/Bus Buddy/source_code/web/env/lib/python3.10/site-packages/rest_framework/serializers.py", line 227, in is_valid
    self._validated_data = self.run_validation(self.initial_data)
  File "/home/farsana.ka/Documents/Bus Buddy/source_code/web/env/lib/python3.10/site-packages/rest_framework/serializers.py", line 426, in run_validation
    value = self.to_internal_value(data)
  File "/home/farsana.ka/Documents/Bus Buddy/source_code/web/env/lib/python3.10/site-packages/rest_framework/serializers.py", line 483, in to_internal_value
    validated_value = field.run_validation(primitive_value)
  File "/home/farsana.ka/Documents/Bus Buddy/source_code/web/env/lib/python3.10/site-packages/rest_framework/fields.py", line 548, in run_validation
    self.run_validators(value)
  File "/home/farsana.ka/Documents/Bus Buddy/source_code/web/env/lib/python3.10/site-packages/rest_framework/fields.py", line 562, in run_validators
    validator(value)
TypeError: max_digit() missing 1 required positional argument: 'value'
django.request ERROR 2023-10-11 10:38:29,925 log 82101 140478381028928 Internal Server Error: /bus-owner/registration/
Traceback (most recent call last):
  File "/home/farsana.ka/.local/lib/python3.10/site-packages/django/core/handlers/exception.py", line 55, in inner
    response = get_response(request)
  File "/home/farsana.ka/.local/lib/python3.10/site-packages/django/core/handlers/base.py", line 197, in _get_response
    response = wrapped_callback(request, *callback_args, **callback_kwargs)
  File "/home/farsana.ka/.local/lib/python3.10/site-packages/django/views/decorators/csrf.py", line 56, in wrapper_view
    return view_func(*args, **kwargs)
  File "/home/farsana.ka/.local/lib/python3.10/site-packages/django/views/generic/base.py", line 104, in view
    return self.dispatch(request, *args, **kwargs)
  File "/home/farsana.ka/.local/lib/python3.10/site-packages/rest_framework/views.py", line 509, in dispatch
    response = self.handle_exception(exc)
  File "/home/farsana.ka/.local/lib/python3.10/site-packages/rest_framework/views.py", line 469, in handle_exception
    self.raise_uncaught_exception(exc)
  File "/home/farsana.ka/.local/lib/python3.10/site-packages/rest_framework/views.py", line 480, in raise_uncaught_exception
    raise exc
  File "/home/farsana.ka/.local/lib/python3.10/site-packages/rest_framework/views.py", line 506, in dispatch
    response = handler(request, *args, **kwargs)
  File "/home/farsana.ka/Documents/Bus Buddy/source_code/web/bus_buddy_back_end/bus_owner/views.py", line 13, in post
    serialized_data = UMS(data=request_data)
NameError: name 'UMS' is not defined
django.request ERROR 2023-10-18 04:31:34,962 log 12678 140310585634816 Internal Server Error: /bus-owner/update-profile/3
Traceback (most recent call last):
  File "/home/farsana.ka/Documents/Bus Buddy/source_code/web/env/lib/python3.10/site-packages/django/core/handlers/exception.py", line 55, in inner
    response = get_response(request)
  File "/home/farsana.ka/Documents/Bus Buddy/source_code/web/env/lib/python3.10/site-packages/django/core/handlers/base.py", line 197, in _get_response
    response = wrapped_callback(request, *callback_args, **callback_kwargs)
  File "/home/farsana.ka/Documents/Bus Buddy/source_code/web/env/lib/python3.10/site-packages/django/views/decorators/csrf.py", line 56, in wrapper_view
    return view_func(*args, **kwargs)
  File "/home/farsana.ka/Documents/Bus Buddy/source_code/web/env/lib/python3.10/site-packages/django/views/generic/base.py", line 104, in view
    return self.dispatch(request, *args, **kwargs)
  File "/home/farsana.ka/Documents/Bus Buddy/source_code/web/env/lib/python3.10/site-packages/rest_framework/views.py", line 509, in dispatch
    response = self.handle_exception(exc)
  File "/home/farsana.ka/Documents/Bus Buddy/source_code/web/env/lib/python3.10/site-packages/rest_framework/views.py", line 469, in handle_exception
    self.raise_uncaught_exception(exc)
  File "/home/farsana.ka/Documents/Bus Buddy/source_code/web/env/lib/python3.10/site-packages/rest_framework/views.py", line 480, in raise_uncaught_exception
    raise exc
  File "/home/farsana.ka/Documents/Bus Buddy/source_code/web/env/lib/python3.10/site-packages/rest_framework/views.py", line 506, in dispatch
    response = handler(request, *args, **kwargs)
  File "/home/farsana.ka/Documents/Bus Buddy/source_code/web/bus_buddy_back_end/bus_owner/views.py", line 121, in put
    flag=update_all(request, user_id)
  File "/home/farsana.ka/Documents/Bus Buddy/source_code/web/bus_buddy_back_end/bus_owner/views.py", line 59, in update_all
    current_data = User.objects.get(id=user_id)
  File "/home/farsana.ka/Documents/Bus Buddy/source_code/web/env/lib/python3.10/site-packages/django/db/models/manager.py", line 87, in manager_method
    return getattr(self.get_queryset(), name)(*args, **kwargs)
  File "/home/farsana.ka/Documents/Bus Buddy/source_code/web/env/lib/python3.10/site-packages/django/db/models/query.py", line 637, in get
    raise self.model.DoesNotExist(
account_manage.models.User.DoesNotExist: User matching query does not exist.
django.request ERROR 2023-10-18 04:31:35,575 log 12678 140310585634816 Internal Server Error: /bus-owner/update-profile/4
Traceback (most recent call last):
  File "/home/farsana.ka/Documents/Bus Buddy/source_code/web/env/lib/python3.10/site-packages/django/core/handlers/exception.py", line 55, in inner
    response = get_response(request)
  File "/home/farsana.ka/Documents/Bus Buddy/source_code/web/env/lib/python3.10/site-packages/django/core/handlers/base.py", line 197, in _get_response
    response = wrapped_callback(request, *callback_args, **callback_kwargs)
  File "/home/farsana.ka/Documents/Bus Buddy/source_code/web/env/lib/python3.10/site-packages/django/views/decorators/csrf.py", line 56, in wrapper_view
    return view_func(*args, **kwargs)
  File "/home/farsana.ka/Documents/Bus Buddy/source_code/web/env/lib/python3.10/site-packages/django/views/generic/base.py", line 104, in view
    return self.dispatch(request, *args, **kwargs)
  File "/home/farsana.ka/Documents/Bus Buddy/source_code/web/env/lib/python3.10/site-packages/rest_framework/views.py", line 509, in dispatch
    response = self.handle_exception(exc)
  File "/home/farsana.ka/Documents/Bus Buddy/source_code/web/env/lib/python3.10/site-packages/rest_framework/views.py", line 469, in handle_exception
    self.raise_uncaught_exception(exc)
  File "/home/farsana.ka/Documents/Bus Buddy/source_code/web/env/lib/python3.10/site-packages/rest_framework/views.py", line 480, in raise_uncaught_exception
    raise exc
  File "/home/farsana.ka/Documents/Bus Buddy/source_code/web/env/lib/python3.10/site-packages/rest_framework/views.py", line 506, in dispatch
    response = handler(request, *args, **kwargs)
  File "/home/farsana.ka/Documents/Bus Buddy/source_code/web/bus_buddy_back_end/bus_owner/views.py", line 121, in put
    flag=update_all(request, user_id)
  File "/home/farsana.ka/Documents/Bus Buddy/source_code/web/bus_buddy_back_end/bus_owner/views.py", line 59, in update_all
    current_data = User.objects.get(id=user_id)
  File "/home/farsana.ka/Documents/Bus Buddy/source_code/web/env/lib/python3.10/site-packages/django/db/models/manager.py", line 87, in manager_method
    return getattr(self.get_queryset(), name)(*args, **kwargs)
  File "/home/farsana.ka/Documents/Bus Buddy/source_code/web/env/lib/python3.10/site-packages/django/db/models/query.py", line 637, in get
    raise self.model.DoesNotExist(
account_manage.models.User.DoesNotExist: User matching query does not exist.
django.request ERROR 2023-10-18 04:31:35,668 log 12678 140310585634816 Internal Server Error: /bus-owner/update-profile/5
Traceback (most recent call last):
  File "/home/farsana.ka/Documents/Bus Buddy/source_code/web/env/lib/python3.10/site-packages/django/core/handlers/exception.py", line 55, in inner
    response = get_response(request)
  File "/home/farsana.ka/Documents/Bus Buddy/source_code/web/env/lib/python3.10/site-packages/django/core/handlers/base.py", line 197, in _get_response
    response = wrapped_callback(request, *callback_args, **callback_kwargs)
  File "/home/farsana.ka/Documents/Bus Buddy/source_code/web/env/lib/python3.10/site-packages/django/views/decorators/csrf.py", line 56, in wrapper_view
    return view_func(*args, **kwargs)
  File "/home/farsana.ka/Documents/Bus Buddy/source_code/web/env/lib/python3.10/site-packages/django/views/generic/base.py", line 104, in view
    return self.dispatch(request, *args, **kwargs)
  File "/home/farsana.ka/Documents/Bus Buddy/source_code/web/env/lib/python3.10/site-packages/rest_framework/views.py", line 509, in dispatch
    response = self.handle_exception(exc)
  File "/home/farsana.ka/Documents/Bus Buddy/source_code/web/env/lib/python3.10/site-packages/rest_framework/views.py", line 469, in handle_exception
    self.raise_uncaught_exception(exc)
  File "/home/farsana.ka/Documents/Bus Buddy/source_code/web/env/lib/python3.10/site-packages/rest_framework/views.py", line 480, in raise_uncaught_exception
    raise exc
  File "/home/farsana.ka/Documents/Bus Buddy/source_code/web/env/lib/python3.10/site-packages/rest_framework/views.py", line 506, in dispatch
    response = handler(request, *args, **kwargs)
  File "/home/farsana.ka/Documents/Bus Buddy/source_code/web/bus_buddy_back_end/bus_owner/views.py", line 121, in put
    flag=update_all(request, user_id)
  File "/home/farsana.ka/Documents/Bus Buddy/source_code/web/bus_buddy_back_end/bus_owner/views.py", line 59, in update_all
    current_data = User.objects.get(id=user_id)
  File "/home/farsana.ka/Documents/Bus Buddy/source_code/web/env/lib/python3.10/site-packages/django/db/models/manager.py", line 87, in manager_method
    return getattr(self.get_queryset(), name)(*args, **kwargs)
  File "/home/farsana.ka/Documents/Bus Buddy/source_code/web/env/lib/python3.10/site-packages/django/db/models/query.py", line 637, in get
    raise self.model.DoesNotExist(
account_manage.models.User.DoesNotExist: User matching query does not exist.
django.request ERROR 2023-10-18 04:31:35,769 log 12678 140310585634816 Internal Server Error: /bus-owner/update-profile/6
Traceback (most recent call last):
  File "/home/farsana.ka/Documents/Bus Buddy/source_code/web/env/lib/python3.10/site-packages/django/core/handlers/exception.py", line 55, in inner
    response = get_response(request)
  File "/home/farsana.ka/Documents/Bus Buddy/source_code/web/env/lib/python3.10/site-packages/django/core/handlers/base.py", line 197, in _get_response
    response = wrapped_callback(request, *callback_args, **callback_kwargs)
  File "/home/farsana.ka/Documents/Bus Buddy/source_code/web/env/lib/python3.10/site-packages/django/views/decorators/csrf.py", line 56, in wrapper_view
    return view_func(*args, **kwargs)
  File "/home/farsana.ka/Documents/Bus Buddy/source_code/web/env/lib/python3.10/site-packages/django/views/generic/base.py", line 104, in view
    return self.dispatch(request, *args, **kwargs)
  File "/home/farsana.ka/Documents/Bus Buddy/source_code/web/env/lib/python3.10/site-packages/rest_framework/views.py", line 509, in dispatch
    response = self.handle_exception(exc)
  File "/home/farsana.ka/Documents/Bus Buddy/source_code/web/env/lib/python3.10/site-packages/rest_framework/views.py", line 469, in handle_exception
    self.raise_uncaught_exception(exc)
  File "/home/farsana.ka/Documents/Bus Buddy/source_code/web/env/lib/python3.10/site-packages/rest_framework/views.py", line 480, in raise_uncaught_exception
    raise exc
  File "/home/farsana.ka/Documents/Bus Buddy/source_code/web/env/lib/python3.10/site-packages/rest_framework/views.py", line 506, in dispatch
    response = handler(request, *args, **kwargs)
  File "/home/farsana.ka/Documents/Bus Buddy/source_code/web/bus_buddy_back_end/bus_owner/views.py", line 121, in put
    flag=update_all(request, user_id)
  File "/home/farsana.ka/Documents/Bus Buddy/source_code/web/bus_buddy_back_end/bus_owner/views.py", line 59, in update_all
    current_data = User.objects.get(id=user_id)
  File "/home/farsana.ka/Documents/Bus Buddy/source_code/web/env/lib/python3.10/site-packages/django/db/models/manager.py", line 87, in manager_method
    return getattr(self.get_queryset(), name)(*args, **kwargs)
  File "/home/farsana.ka/Documents/Bus Buddy/source_code/web/env/lib/python3.10/site-packages/django/db/models/query.py", line 637, in get
    raise self.model.DoesNotExist(
account_manage.models.User.DoesNotExist: User matching query does not exist.
django.request ERROR 2023-10-20 08:51:26,366 log 41037 139655697682432 Internal Server Error: /bus-owner/update-profile/4
Traceback (most recent call last):
  File "/home/farsana.ka/Documents/Bus Buddy/source_code/web/env/lib/python3.10/site-packages/django/core/handlers/exception.py", line 55, in inner
    response = get_response(request)
  File "/home/farsana.ka/Documents/Bus Buddy/source_code/web/env/lib/python3.10/site-packages/django/core/handlers/base.py", line 197, in _get_response
    response = wrapped_callback(request, *callback_args, **callback_kwargs)
  File "/home/farsana.ka/Documents/Bus Buddy/source_code/web/env/lib/python3.10/site-packages/django/views/decorators/csrf.py", line 56, in wrapper_view
    return view_func(*args, **kwargs)
  File "/home/farsana.ka/Documents/Bus Buddy/source_code/web/env/lib/python3.10/site-packages/django/views/generic/base.py", line 104, in view
    return self.dispatch(request, *args, **kwargs)
  File "/home/farsana.ka/Documents/Bus Buddy/source_code/web/env/lib/python3.10/site-packages/rest_framework/views.py", line 509, in dispatch
    response = self.handle_exception(exc)
  File "/home/farsana.ka/Documents/Bus Buddy/source_code/web/env/lib/python3.10/site-packages/rest_framework/views.py", line 469, in handle_exception
    self.raise_uncaught_exception(exc)
  File "/home/farsana.ka/Documents/Bus Buddy/source_code/web/env/lib/python3.10/site-packages/rest_framework/views.py", line 480, in raise_uncaught_exception
    raise exc
  File "/home/farsana.ka/Documents/Bus Buddy/source_code/web/env/lib/python3.10/site-packages/rest_framework/views.py", line 506, in dispatch
    response = handler(request, *args, **kwargs)
  File "/home/farsana.ka/Documents/Bus Buddy/source_code/web/bus_buddy_back_end/bus_owner/views.py", line 121, in put
    flag=update_all(request, user_id)
  File "/home/farsana.ka/Documents/Bus Buddy/source_code/web/bus_buddy_back_end/bus_owner/views.py", line 59, in update_all
    current_data = User.objects.get(id=user_id)
  File "/home/farsana.ka/Documents/Bus Buddy/source_code/web/env/lib/python3.10/site-packages/django/db/models/manager.py", line 87, in manager_method
    return getattr(self.get_queryset(), name)(*args, **kwargs)
  File "/home/farsana.ka/Documents/Bus Buddy/source_code/web/env/lib/python3.10/site-packages/django/db/models/query.py", line 637, in get
    raise self.model.DoesNotExist(
account_manage.models.User.DoesNotExist: User matching query does not exist.
django.request ERROR 2023-10-20 08:51:26,531 log 41037 139655697682432 Internal Server Error: /bus-owner/update-profile/5
Traceback (most recent call last):
  File "/home/farsana.ka/Documents/Bus Buddy/source_code/web/env/lib/python3.10/site-packages/django/core/handlers/exception.py", line 55, in inner
    response = get_response(request)
  File "/home/farsana.ka/Documents/Bus Buddy/source_code/web/env/lib/python3.10/site-packages/django/core/handlers/base.py", line 197, in _get_response
    response = wrapped_callback(request, *callback_args, **callback_kwargs)
  File "/home/farsana.ka/Documents/Bus Buddy/source_code/web/env/lib/python3.10/site-packages/django/views/decorators/csrf.py", line 56, in wrapper_view
    return view_func(*args, **kwargs)
  File "/home/farsana.ka/Documents/Bus Buddy/source_code/web/env/lib/python3.10/site-packages/django/views/generic/base.py", line 104, in view
    return self.dispatch(request, *args, **kwargs)
  File "/home/farsana.ka/Documents/Bus Buddy/source_code/web/env/lib/python3.10/site-packages/rest_framework/views.py", line 509, in dispatch
    response = self.handle_exception(exc)
  File "/home/farsana.ka/Documents/Bus Buddy/source_code/web/env/lib/python3.10/site-packages/rest_framework/views.py", line 469, in handle_exception
    self.raise_uncaught_exception(exc)
  File "/home/farsana.ka/Documents/Bus Buddy/source_code/web/env/lib/python3.10/site-packages/rest_framework/views.py", line 480, in raise_uncaught_exception
    raise exc
  File "/home/farsana.ka/Documents/Bus Buddy/source_code/web/env/lib/python3.10/site-packages/rest_framework/views.py", line 506, in dispatch
    response = handler(request, *args, **kwargs)
  File "/home/farsana.ka/Documents/Bus Buddy/source_code/web/bus_buddy_back_end/bus_owner/views.py", line 121, in put
    flag=update_all(request, user_id)
  File "/home/farsana.ka/Documents/Bus Buddy/source_code/web/bus_buddy_back_end/bus_owner/views.py", line 59, in update_all
    current_data = User.objects.get(id=user_id)
  File "/home/farsana.ka/Documents/Bus Buddy/source_code/web/env/lib/python3.10/site-packages/django/db/models/manager.py", line 87, in manager_method
    return getattr(self.get_queryset(), name)(*args, **kwargs)
  File "/home/farsana.ka/Documents/Bus Buddy/source_code/web/env/lib/python3.10/site-packages/django/db/models/query.py", line 637, in get
    raise self.model.DoesNotExist(
account_manage.models.User.DoesNotExist: User matching query does not exist.
django.request ERROR 2023-10-20 08:51:26,654 log 41037 139655697682432 Internal Server Error: /bus-owner/update-profile/6
Traceback (most recent call last):
  File "/home/farsana.ka/Documents/Bus Buddy/source_code/web/env/lib/python3.10/site-packages/django/core/handlers/exception.py", line 55, in inner
    response = get_response(request)
  File "/home/farsana.ka/Documents/Bus Buddy/source_code/web/env/lib/python3.10/site-packages/django/core/handlers/base.py", line 197, in _get_response
    response = wrapped_callback(request, *callback_args, **callback_kwargs)
  File "/home/farsana.ka/Documents/Bus Buddy/source_code/web/env/lib/python3.10/site-packages/django/views/decorators/csrf.py", line 56, in wrapper_view
    return view_func(*args, **kwargs)
  File "/home/farsana.ka/Documents/Bus Buddy/source_code/web/env/lib/python3.10/site-packages/django/views/generic/base.py", line 104, in view
    return self.dispatch(request, *args, **kwargs)
  File "/home/farsana.ka/Documents/Bus Buddy/source_code/web/env/lib/python3.10/site-packages/rest_framework/views.py", line 509, in dispatch
    response = self.handle_exception(exc)
  File "/home/farsana.ka/Documents/Bus Buddy/source_code/web/env/lib/python3.10/site-packages/rest_framework/views.py", line 469, in handle_exception
    self.raise_uncaught_exception(exc)
  File "/home/farsana.ka/Documents/Bus Buddy/source_code/web/env/lib/python3.10/site-packages/rest_framework/views.py", line 480, in raise_uncaught_exception
    raise exc
  File "/home/farsana.ka/Documents/Bus Buddy/source_code/web/env/lib/python3.10/site-packages/rest_framework/views.py", line 506, in dispatch
    response = handler(request, *args, **kwargs)
  File "/home/farsana.ka/Documents/Bus Buddy/source_code/web/bus_buddy_back_end/bus_owner/views.py", line 121, in put
    flag=update_all(request, user_id)
  File "/home/farsana.ka/Documents/Bus Buddy/source_code/web/bus_buddy_back_end/bus_owner/views.py", line 59, in update_all
    current_data = User.objects.get(id=user_id)
  File "/home/farsana.ka/Documents/Bus Buddy/source_code/web/env/lib/python3.10/site-packages/django/db/models/manager.py", line 87, in manager_method
    return getattr(self.get_queryset(), name)(*args, **kwargs)
  File "/home/farsana.ka/Documents/Bus Buddy/source_code/web/env/lib/python3.10/site-packages/django/db/models/query.py", line 637, in get
    raise self.model.DoesNotExist(
account_manage.models.User.DoesNotExist: User matching query does not exist.
django.request ERROR 2023-10-20 08:51:26,832 log 41037 139655697682432 Internal Server Error: /bus-owner/update-profile/7
Traceback (most recent call last):
  File "/home/farsana.ka/Documents/Bus Buddy/source_code/web/env/lib/python3.10/site-packages/django/core/handlers/exception.py", line 55, in inner
    response = get_response(request)
  File "/home/farsana.ka/Documents/Bus Buddy/source_code/web/env/lib/python3.10/site-packages/django/core/handlers/base.py", line 197, in _get_response
    response = wrapped_callback(request, *callback_args, **callback_kwargs)
  File "/home/farsana.ka/Documents/Bus Buddy/source_code/web/env/lib/python3.10/site-packages/django/views/decorators/csrf.py", line 56, in wrapper_view
    return view_func(*args, **kwargs)
  File "/home/farsana.ka/Documents/Bus Buddy/source_code/web/env/lib/python3.10/site-packages/django/views/generic/base.py", line 104, in view
    return self.dispatch(request, *args, **kwargs)
  File "/home/farsana.ka/Documents/Bus Buddy/source_code/web/env/lib/python3.10/site-packages/rest_framework/views.py", line 509, in dispatch
    response = self.handle_exception(exc)
  File "/home/farsana.ka/Documents/Bus Buddy/source_code/web/env/lib/python3.10/site-packages/rest_framework/views.py", line 469, in handle_exception
    self.raise_uncaught_exception(exc)
  File "/home/farsana.ka/Documents/Bus Buddy/source_code/web/env/lib/python3.10/site-packages/rest_framework/views.py", line 480, in raise_uncaught_exception
    raise exc
  File "/home/farsana.ka/Documents/Bus Buddy/source_code/web/env/lib/python3.10/site-packages/rest_framework/views.py", line 506, in dispatch
    response = handler(request, *args, **kwargs)
  File "/home/farsana.ka/Documents/Bus Buddy/source_code/web/bus_buddy_back_end/bus_owner/views.py", line 121, in put
    flag=update_all(request, user_id)
  File "/home/farsana.ka/Documents/Bus Buddy/source_code/web/bus_buddy_back_end/bus_owner/views.py", line 59, in update_all
    current_data = User.objects.get(id=user_id)
  File "/home/farsana.ka/Documents/Bus Buddy/source_code/web/env/lib/python3.10/site-packages/django/db/models/manager.py", line 87, in manager_method
    return getattr(self.get_queryset(), name)(*args, **kwargs)
  File "/home/farsana.ka/Documents/Bus Buddy/source_code/web/env/lib/python3.10/site-packages/django/db/models/query.py", line 637, in get
    raise self.model.DoesNotExist(
account_manage.models.User.DoesNotExist: User matching query does not exist.
django.request ERROR 2023-10-20 08:58:42,564 log 41487 140045926572032 Internal Server Error: /bus-owner/update-profile/1
Traceback (most recent call last):
  File "/home/farsana.ka/Documents/Bus Buddy/source_code/web/env/lib/python3.10/site-packages/django/core/handlers/exception.py", line 55, in inner
    response = get_response(request)
  File "/home/farsana.ka/Documents/Bus Buddy/source_code/web/env/lib/python3.10/site-packages/django/core/handlers/base.py", line 197, in _get_response
    response = wrapped_callback(request, *callback_args, **callback_kwargs)
  File "/home/farsana.ka/Documents/Bus Buddy/source_code/web/env/lib/python3.10/site-packages/django/views/decorators/csrf.py", line 56, in wrapper_view
    return view_func(*args, **kwargs)
  File "/home/farsana.ka/Documents/Bus Buddy/source_code/web/env/lib/python3.10/site-packages/django/views/generic/base.py", line 104, in view
    return self.dispatch(request, *args, **kwargs)
  File "/home/farsana.ka/Documents/Bus Buddy/source_code/web/env/lib/python3.10/site-packages/rest_framework/views.py", line 509, in dispatch
    response = self.handle_exception(exc)
  File "/home/farsana.ka/Documents/Bus Buddy/source_code/web/env/lib/python3.10/site-packages/rest_framework/views.py", line 469, in handle_exception
    self.raise_uncaught_exception(exc)
  File "/home/farsana.ka/Documents/Bus Buddy/source_code/web/env/lib/python3.10/site-packages/rest_framework/views.py", line 480, in raise_uncaught_exception
    raise exc
  File "/home/farsana.ka/Documents/Bus Buddy/source_code/web/env/lib/python3.10/site-packages/rest_framework/views.py", line 506, in dispatch
    response = handler(request, *args, **kwargs)
  File "/home/farsana.ka/Documents/Bus Buddy/source_code/web/bus_buddy_back_end/bus_owner/views.py", line 109, in put
    response=update_all(request, user_id)
  File "/home/farsana.ka/Documents/Bus Buddy/source_code/web/bus_buddy_back_end/bus_owner/views.py", line 59, in update_all
    current_data = User.objects.get(id=user_id)
  File "/home/farsana.ka/Documents/Bus Buddy/source_code/web/env/lib/python3.10/site-packages/django/db/models/manager.py", line 87, in manager_method
    return getattr(self.get_queryset(), name)(*args, **kwargs)
  File "/home/farsana.ka/Documents/Bus Buddy/source_code/web/env/lib/python3.10/site-packages/django/db/models/query.py", line 637, in get
    raise self.model.DoesNotExist(
account_manage.models.User.DoesNotExist: User matching query does not exist.
django.request ERROR 2023-10-20 12:20:58,690 log 52600 140479656097344 Internal Server Error: /user/update-profile/31
Traceback (most recent call last):
  File "/home/farsana.ka/Documents/Bus Buddy/source_code/web/env/lib/python3.10/site-packages/django/core/handlers/exception.py", line 55, in inner
    response = get_response(request)
  File "/home/farsana.ka/Documents/Bus Buddy/source_code/web/env/lib/python3.10/site-packages/django/core/handlers/base.py", line 220, in _get_response
    response = response.render()
  File "/home/farsana.ka/Documents/Bus Buddy/source_code/web/env/lib/python3.10/site-packages/django/template/response.py", line 114, in render
    self.content = self.rendered_content
  File "/home/farsana.ka/Documents/Bus Buddy/source_code/web/env/lib/python3.10/site-packages/rest_framework/response.py", line 70, in rendered_content
    ret = renderer.render(self.data, accepted_media_type, context)
  File "/home/farsana.ka/Documents/Bus Buddy/source_code/web/env/lib/python3.10/site-packages/rest_framework/renderers.py", line 99, in render
    ret = json.dumps(
  File "/home/farsana.ka/Documents/Bus Buddy/source_code/web/env/lib/python3.10/site-packages/rest_framework/utils/json.py", line 25, in dumps
    return json.dumps(*args, **kwargs)
  File "/usr/lib/python3.10/json/__init__.py", line 238, in dumps
    **kw).encode(obj)
  File "/usr/lib/python3.10/json/encoder.py", line 199, in encode
    chunks = self.iterencode(o, _one_shot=True)
  File "/usr/lib/python3.10/json/encoder.py", line 257, in iterencode
    return _iterencode(o, 0)
  File "/home/farsana.ka/Documents/Bus Buddy/source_code/web/env/lib/python3.10/site-packages/rest_framework/utils/encoders.py", line 67, in default
    return super().default(obj)
  File "/usr/lib/python3.10/json/encoder.py", line 179, in default
    raise TypeError(f'Object of type {o.__class__.__name__} '
TypeError: Object of type ListSerializer is not JSON serializable
django.request ERROR 2023-10-20 12:23:30,934 log 52600 140479656097344 Internal Server Error: /user/update-profile/31
Traceback (most recent call last):
  File "/home/farsana.ka/Documents/Bus Buddy/source_code/web/env/lib/python3.10/site-packages/django/core/handlers/exception.py", line 55, in inner
    response = get_response(request)
  File "/home/farsana.ka/Documents/Bus Buddy/source_code/web/env/lib/python3.10/site-packages/django/core/handlers/base.py", line 220, in _get_response
    response = response.render()
  File "/home/farsana.ka/Documents/Bus Buddy/source_code/web/env/lib/python3.10/site-packages/django/template/response.py", line 114, in render
    self.content = self.rendered_content
  File "/home/farsana.ka/Documents/Bus Buddy/source_code/web/env/lib/python3.10/site-packages/rest_framework/response.py", line 70, in rendered_content
    ret = renderer.render(self.data, accepted_media_type, context)
  File "/home/farsana.ka/Documents/Bus Buddy/source_code/web/env/lib/python3.10/site-packages/rest_framework/renderers.py", line 99, in render
    ret = json.dumps(
  File "/home/farsana.ka/Documents/Bus Buddy/source_code/web/env/lib/python3.10/site-packages/rest_framework/utils/json.py", line 25, in dumps
    return json.dumps(*args, **kwargs)
  File "/usr/lib/python3.10/json/__init__.py", line 238, in dumps
    **kw).encode(obj)
  File "/usr/lib/python3.10/json/encoder.py", line 199, in encode
    chunks = self.iterencode(o, _one_shot=True)
  File "/usr/lib/python3.10/json/encoder.py", line 257, in iterencode
    return _iterencode(o, 0)
  File "/home/farsana.ka/Documents/Bus Buddy/source_code/web/env/lib/python3.10/site-packages/rest_framework/utils/encoders.py", line 67, in default
    return super().default(obj)
  File "/usr/lib/python3.10/json/encoder.py", line 179, in default
    raise TypeError(f'Object of type {o.__class__.__name__} '
TypeError: Object of type ListSerializer is not JSON serializable
django.request ERROR 2023-10-20 12:23:36,104 log 52600 140479656097344 Internal Server Error: /user/update-profile/31
Traceback (most recent call last):
  File "/home/farsana.ka/Documents/Bus Buddy/source_code/web/env/lib/python3.10/site-packages/django/core/handlers/exception.py", line 55, in inner
    response = get_response(request)
  File "/home/farsana.ka/Documents/Bus Buddy/source_code/web/env/lib/python3.10/site-packages/django/core/handlers/base.py", line 220, in _get_response
    response = response.render()
  File "/home/farsana.ka/Documents/Bus Buddy/source_code/web/env/lib/python3.10/site-packages/django/template/response.py", line 114, in render
    self.content = self.rendered_content
  File "/home/farsana.ka/Documents/Bus Buddy/source_code/web/env/lib/python3.10/site-packages/rest_framework/response.py", line 70, in rendered_content
    ret = renderer.render(self.data, accepted_media_type, context)
  File "/home/farsana.ka/Documents/Bus Buddy/source_code/web/env/lib/python3.10/site-packages/rest_framework/renderers.py", line 99, in render
    ret = json.dumps(
  File "/home/farsana.ka/Documents/Bus Buddy/source_code/web/env/lib/python3.10/site-packages/rest_framework/utils/json.py", line 25, in dumps
    return json.dumps(*args, **kwargs)
  File "/usr/lib/python3.10/json/__init__.py", line 238, in dumps
    **kw).encode(obj)
  File "/usr/lib/python3.10/json/encoder.py", line 199, in encode
    chunks = self.iterencode(o, _one_shot=True)
  File "/usr/lib/python3.10/json/encoder.py", line 257, in iterencode
    return _iterencode(o, 0)
  File "/home/farsana.ka/Documents/Bus Buddy/source_code/web/env/lib/python3.10/site-packages/rest_framework/utils/encoders.py", line 67, in default
    return super().default(obj)
  File "/usr/lib/python3.10/json/encoder.py", line 179, in default
    raise TypeError(f'Object of type {o.__class__.__name__} '
TypeError: Object of type ListSerializer is not JSON serializable
django.request ERROR 2023-10-20 12:24:51,872 log 53114 140135549101632 Internal Server Error: /user/update-profile/31
Traceback (most recent call last):
  File "/home/farsana.ka/Documents/Bus Buddy/source_code/web/env/lib/python3.10/site-packages/django/core/handlers/exception.py", line 55, in inner
    response = get_response(request)
  File "/home/farsana.ka/Documents/Bus Buddy/source_code/web/env/lib/python3.10/site-packages/django/core/handlers/base.py", line 220, in _get_response
    response = response.render()
  File "/home/farsana.ka/Documents/Bus Buddy/source_code/web/env/lib/python3.10/site-packages/django/template/response.py", line 114, in render
    self.content = self.rendered_content
  File "/home/farsana.ka/Documents/Bus Buddy/source_code/web/env/lib/python3.10/site-packages/rest_framework/response.py", line 70, in rendered_content
    ret = renderer.render(self.data, accepted_media_type, context)
  File "/home/farsana.ka/Documents/Bus Buddy/source_code/web/env/lib/python3.10/site-packages/rest_framework/renderers.py", line 99, in render
    ret = json.dumps(
  File "/home/farsana.ka/Documents/Bus Buddy/source_code/web/env/lib/python3.10/site-packages/rest_framework/utils/json.py", line 25, in dumps
    return json.dumps(*args, **kwargs)
  File "/usr/lib/python3.10/json/__init__.py", line 238, in dumps
    **kw).encode(obj)
  File "/usr/lib/python3.10/json/encoder.py", line 199, in encode
    chunks = self.iterencode(o, _one_shot=True)
  File "/usr/lib/python3.10/json/encoder.py", line 257, in iterencode
    return _iterencode(o, 0)
  File "/home/farsana.ka/Documents/Bus Buddy/source_code/web/env/lib/python3.10/site-packages/rest_framework/utils/encoders.py", line 67, in default
    return super().default(obj)
  File "/usr/lib/python3.10/json/encoder.py", line 179, in default
    raise TypeError(f'Object of type {o.__class__.__name__} '
TypeError: Object of type User is not JSON serializable
django.request ERROR 2023-10-20 12:29:43,777 log 53386 140388583073344 Internal Server Error: /user/update-profile/31
Traceback (most recent call last):
  File "/home/farsana.ka/Documents/Bus Buddy/source_code/web/env/lib/python3.10/site-packages/django/core/handlers/exception.py", line 55, in inner
    response = get_response(request)
  File "/home/farsana.ka/Documents/Bus Buddy/source_code/web/env/lib/python3.10/site-packages/django/core/handlers/base.py", line 197, in _get_response
    response = wrapped_callback(request, *callback_args, **callback_kwargs)
  File "/home/farsana.ka/Documents/Bus Buddy/source_code/web/env/lib/python3.10/site-packages/django/views/decorators/csrf.py", line 56, in wrapper_view
    return view_func(*args, **kwargs)
  File "/home/farsana.ka/Documents/Bus Buddy/source_code/web/env/lib/python3.10/site-packages/django/views/generic/base.py", line 104, in view
    return self.dispatch(request, *args, **kwargs)
  File "/home/farsana.ka/Documents/Bus Buddy/source_code/web/env/lib/python3.10/site-packages/rest_framework/views.py", line 509, in dispatch
    response = self.handle_exception(exc)
  File "/home/farsana.ka/Documents/Bus Buddy/source_code/web/env/lib/python3.10/site-packages/rest_framework/views.py", line 469, in handle_exception
    self.raise_uncaught_exception(exc)
  File "/home/farsana.ka/Documents/Bus Buddy/source_code/web/env/lib/python3.10/site-packages/rest_framework/views.py", line 480, in raise_uncaught_exception
    raise exc
  File "/home/farsana.ka/Documents/Bus Buddy/source_code/web/env/lib/python3.10/site-packages/rest_framework/views.py", line 506, in dispatch
    response = handler(request, *args, **kwargs)
  File "/home/farsana.ka/Documents/Bus Buddy/source_code/web/bus_buddy_back_end/normal_user/views.py", line 92, in get
    return Response(serialized_data)
  File "/home/farsana.ka/Documents/Bus Buddy/source_code/web/env/lib/python3.10/site-packages/rest_framework/response.py", line 38, in __init__
    raise AssertionError(msg)
AssertionError: You passed a Serializer instance as data, but probably meant to pass serialized `.data` or `.error`. representation.
django.request ERROR 2023-10-20 12:32:46,140 log 53490 139655534077504 Internal Server Error: /user/update-profile/31
Traceback (most recent call last):
  File "/home/farsana.ka/Documents/Bus Buddy/source_code/web/env/lib/python3.10/site-packages/django/core/handlers/exception.py", line 55, in inner
    response = get_response(request)
  File "/home/farsana.ka/Documents/Bus Buddy/source_code/web/env/lib/python3.10/site-packages/django/core/handlers/base.py", line 197, in _get_response
    response = wrapped_callback(request, *callback_args, **callback_kwargs)
  File "/home/farsana.ka/Documents/Bus Buddy/source_code/web/env/lib/python3.10/site-packages/django/views/decorators/csrf.py", line 56, in wrapper_view
    return view_func(*args, **kwargs)
  File "/home/farsana.ka/Documents/Bus Buddy/source_code/web/env/lib/python3.10/site-packages/django/views/generic/base.py", line 104, in view
    return self.dispatch(request, *args, **kwargs)
  File "/home/farsana.ka/Documents/Bus Buddy/source_code/web/env/lib/python3.10/site-packages/rest_framework/views.py", line 509, in dispatch
    response = self.handle_exception(exc)
  File "/home/farsana.ka/Documents/Bus Buddy/source_code/web/env/lib/python3.10/site-packages/rest_framework/views.py", line 469, in handle_exception
    self.raise_uncaught_exception(exc)
  File "/home/farsana.ka/Documents/Bus Buddy/source_code/web/env/lib/python3.10/site-packages/rest_framework/views.py", line 480, in raise_uncaught_exception
    raise exc
  File "/home/farsana.ka/Documents/Bus Buddy/source_code/web/env/lib/python3.10/site-packages/rest_framework/views.py", line 506, in dispatch
    response = handler(request, *args, **kwargs)
  File "/home/farsana.ka/Documents/Bus Buddy/source_code/web/bus_buddy_back_end/normal_user/views.py", line 92, in get
    return Response(serialized_data)
  File "/home/farsana.ka/Documents/Bus Buddy/source_code/web/env/lib/python3.10/site-packages/rest_framework/response.py", line 38, in __init__
    raise AssertionError(msg)
AssertionError: You passed a Serializer instance as data, but probably meant to pass serialized `.data` or `.error`. representation.
django.request ERROR 2023-10-24 04:08:41,715 log 13829 140281999517248 Internal Server Error: /user/registration/
Traceback (most recent call last):
  File "/home/farsana.ka/Documents/Bus Buddy/source_code/web/env/lib/python3.10/site-packages/django/core/handlers/exception.py", line 55, in inner
    response = get_response(request)
  File "/home/farsana.ka/Documents/Bus Buddy/source_code/web/env/lib/python3.10/site-packages/django/core/handlers/base.py", line 197, in _get_response
    response = wrapped_callback(request, *callback_args, **callback_kwargs)
  File "/home/farsana.ka/Documents/Bus Buddy/source_code/web/env/lib/python3.10/site-packages/django/views/decorators/csrf.py", line 56, in wrapper_view
    return view_func(*args, **kwargs)
  File "/home/farsana.ka/Documents/Bus Buddy/source_code/web/env/lib/python3.10/site-packages/django/views/generic/base.py", line 104, in view
    return self.dispatch(request, *args, **kwargs)
  File "/home/farsana.ka/Documents/Bus Buddy/source_code/web/env/lib/python3.10/site-packages/rest_framework/views.py", line 509, in dispatch
    response = self.handle_exception(exc)
  File "/home/farsana.ka/Documents/Bus Buddy/source_code/web/env/lib/python3.10/site-packages/rest_framework/views.py", line 469, in handle_exception
    self.raise_uncaught_exception(exc)
  File "/home/farsana.ka/Documents/Bus Buddy/source_code/web/env/lib/python3.10/site-packages/rest_framework/views.py", line 480, in raise_uncaught_exception
    raise exc
  File "/home/farsana.ka/Documents/Bus Buddy/source_code/web/env/lib/python3.10/site-packages/rest_framework/views.py", line 506, in dispatch
    response = handler(request, *args, **kwargs)
  File "/home/farsana.ka/Documents/Bus Buddy/source_code/web/bus_buddy_back_end/normal_user/views.py", line 76, in post
    serialized_data.save()
  File "/home/farsana.ka/Documents/Bus Buddy/source_code/web/env/lib/python3.10/site-packages/rest_framework/serializers.py", line 212, in save
    self.instance = self.create(validated_data)
  File "/home/farsana.ka/Documents/Bus Buddy/source_code/web/bus_buddy_back_end/normal_user/serializer.py", line 84, in create
    return User.create_user(**validated_data)
AttributeError: type object 'User' has no attribute 'create_user'
django.request ERROR 2023-10-24 04:15:37,711 log 14880 139624796120640 Internal Server Error: /user/update-profile/31
Traceback (most recent call last):
  File "/home/farsana.ka/Documents/Bus Buddy/source_code/web/env/lib/python3.10/site-packages/rest_framework/fields.py", line 446, in get_attribute
    return get_attribute(instance, self.source_attrs)
  File "/home/farsana.ka/Documents/Bus Buddy/source_code/web/env/lib/python3.10/site-packages/rest_framework/fields.py", line 96, in get_attribute
    instance = getattr(instance, attr)
AttributeError: 'UserUpdateSerializer' object has no attribute 'first_name'

During handling of the above exception, another exception occurred:

Traceback (most recent call last):
  File "/home/farsana.ka/Documents/Bus Buddy/source_code/web/env/lib/python3.10/site-packages/django/core/handlers/exception.py", line 55, in inner
    response = get_response(request)
  File "/home/farsana.ka/Documents/Bus Buddy/source_code/web/env/lib/python3.10/site-packages/django/core/handlers/base.py", line 197, in _get_response
    response = wrapped_callback(request, *callback_args, **callback_kwargs)
  File "/home/farsana.ka/Documents/Bus Buddy/source_code/web/env/lib/python3.10/site-packages/django/views/decorators/csrf.py", line 56, in wrapper_view
    return view_func(*args, **kwargs)
  File "/home/farsana.ka/Documents/Bus Buddy/source_code/web/env/lib/python3.10/site-packages/django/views/generic/base.py", line 104, in view
    return self.dispatch(request, *args, **kwargs)
  File "/home/farsana.ka/Documents/Bus Buddy/source_code/web/env/lib/python3.10/site-packages/rest_framework/views.py", line 509, in dispatch
    response = self.handle_exception(exc)
  File "/home/farsana.ka/Documents/Bus Buddy/source_code/web/env/lib/python3.10/site-packages/rest_framework/views.py", line 469, in handle_exception
    self.raise_uncaught_exception(exc)
  File "/home/farsana.ka/Documents/Bus Buddy/source_code/web/env/lib/python3.10/site-packages/rest_framework/views.py", line 480, in raise_uncaught_exception
    raise exc
  File "/home/farsana.ka/Documents/Bus Buddy/source_code/web/env/lib/python3.10/site-packages/rest_framework/views.py", line 506, in dispatch
    response = handler(request, *args, **kwargs)
  File "/home/farsana.ka/Documents/Bus Buddy/source_code/web/bus_buddy_back_end/normal_user/views.py", line 92, in get
    return Response(serialized_data.data)
  File "/home/farsana.ka/Documents/Bus Buddy/source_code/web/env/lib/python3.10/site-packages/rest_framework/serializers.py", line 555, in data
    ret = super().data
  File "/home/farsana.ka/Documents/Bus Buddy/source_code/web/env/lib/python3.10/site-packages/rest_framework/serializers.py", line 253, in data
    self._data = self.to_representation(self.instance)
  File "/home/farsana.ka/Documents/Bus Buddy/source_code/web/env/lib/python3.10/site-packages/rest_framework/serializers.py", line 509, in to_representation
    attribute = field.get_attribute(instance)
  File "/home/farsana.ka/Documents/Bus Buddy/source_code/web/env/lib/python3.10/site-packages/rest_framework/fields.py", line 479, in get_attribute
    raise type(exc)(msg)
AttributeError: Got AttributeError when attempting to get a value for field `first_name` on serializer `UserModelSerializer`.
The serializer field might be named incorrectly and not match any attribute or key on the `UserUpdateSerializer` instance.
Original exception text was: 'UserUpdateSerializer' object has no attribute 'first_name'.
django.request ERROR 2023-10-25 13:15:24,947 log 58442 140501231593024 Internal Server Error: /bus-owner/update-profile/32
Traceback (most recent call last):
  File "/home/farsana.ka/Documents/Bus Buddy/source_code/web/env/lib/python3.10/site-packages/django/core/handlers/exception.py", line 55, in inner
    response = get_response(request)
  File "/home/farsana.ka/Documents/Bus Buddy/source_code/web/env/lib/python3.10/site-packages/django/core/handlers/base.py", line 197, in _get_response
    response = wrapped_callback(request, *callback_args, **callback_kwargs)
  File "/home/farsana.ka/Documents/Bus Buddy/source_code/web/env/lib/python3.10/site-packages/django/views/decorators/csrf.py", line 56, in wrapper_view
    return view_func(*args, **kwargs)
  File "/home/farsana.ka/Documents/Bus Buddy/source_code/web/env/lib/python3.10/site-packages/django/views/generic/base.py", line 104, in view
    return self.dispatch(request, *args, **kwargs)
  File "/home/farsana.ka/Documents/Bus Buddy/source_code/web/env/lib/python3.10/site-packages/rest_framework/views.py", line 509, in dispatch
    response = self.handle_exception(exc)
  File "/home/farsana.ka/Documents/Bus Buddy/source_code/web/env/lib/python3.10/site-packages/rest_framework/views.py", line 469, in handle_exception
    self.raise_uncaught_exception(exc)
  File "/home/farsana.ka/Documents/Bus Buddy/source_code/web/env/lib/python3.10/site-packages/rest_framework/views.py", line 480, in raise_uncaught_exception
    raise exc
  File "/home/farsana.ka/Documents/Bus Buddy/source_code/web/env/lib/python3.10/site-packages/rest_framework/views.py", line 506, in dispatch
    response = handler(request, *args, **kwargs)
  File "/home/farsana.ka/Documents/Bus Buddy/source_code/web/bus_buddy_back_end/bus_owner/views.py", line 44, in put
    return self.update(request, id)
  File "/home/farsana.ka/Documents/Bus Buddy/source_code/web/bus_buddy_back_end/bus_owner/views.py", line 38, in update
    self.perform_update(serializer)
AttributeError: 'UpdateBusOwner' object has no attribute 'perform_update'
django.request ERROR 2023-10-25 13:20:58,597 log 60673 140289063777856 Internal Server Error: /bus-owner/update-profile/32
Traceback (most recent call last):
  File "/home/farsana.ka/Documents/Bus Buddy/source_code/web/bus_buddy_back_end/bus_owner/views.py", line 29, in update
    instance = self.get_object(User.objects.get(id=id))
TypeError: GenericAPIView.get_object() takes 1 positional argument but 2 were given

During handling of the above exception, another exception occurred:

Traceback (most recent call last):
  File "/home/farsana.ka/Documents/Bus Buddy/source_code/web/env/lib/python3.10/site-packages/django/core/handlers/exception.py", line 55, in inner
    response = get_response(request)
  File "/home/farsana.ka/Documents/Bus Buddy/source_code/web/env/lib/python3.10/site-packages/django/core/handlers/base.py", line 197, in _get_response
    response = wrapped_callback(request, *callback_args, **callback_kwargs)
  File "/home/farsana.ka/Documents/Bus Buddy/source_code/web/env/lib/python3.10/site-packages/django/views/decorators/csrf.py", line 56, in wrapper_view
    return view_func(*args, **kwargs)
  File "/home/farsana.ka/Documents/Bus Buddy/source_code/web/env/lib/python3.10/site-packages/django/views/generic/base.py", line 104, in view
    return self.dispatch(request, *args, **kwargs)
  File "/home/farsana.ka/Documents/Bus Buddy/source_code/web/env/lib/python3.10/site-packages/rest_framework/views.py", line 509, in dispatch
    response = self.handle_exception(exc)
  File "/home/farsana.ka/Documents/Bus Buddy/source_code/web/env/lib/python3.10/site-packages/rest_framework/views.py", line 469, in handle_exception
    self.raise_uncaught_exception(exc)
  File "/home/farsana.ka/Documents/Bus Buddy/source_code/web/env/lib/python3.10/site-packages/rest_framework/views.py", line 480, in raise_uncaught_exception
    raise exc
  File "/home/farsana.ka/Documents/Bus Buddy/source_code/web/env/lib/python3.10/site-packages/rest_framework/views.py", line 506, in dispatch
    response = handler(request, *args, **kwargs)
  File "/home/farsana.ka/Documents/Bus Buddy/source_code/web/bus_buddy_back_end/bus_owner/views.py", line 40, in put
    return self.update(request, id)
  File "/home/farsana.ka/Documents/Bus Buddy/source_code/web/bus_buddy_back_end/bus_owner/views.py", line 37, in update
    return Response(serializer.errors,status=400)
UnboundLocalError: local variable 'serializer' referenced before assignment
django.request ERROR 2023-10-25 13:25:40,963 log 60948 139671814268480 Internal Server Error: /bus-owner/update-profile/32
Traceback (most recent call last):
  File "/home/farsana.ka/Documents/Bus Buddy/source_code/web/env/lib/python3.10/site-packages/django/core/handlers/exception.py", line 55, in inner
    response = get_response(request)
  File "/home/farsana.ka/Documents/Bus Buddy/source_code/web/env/lib/python3.10/site-packages/django/core/handlers/base.py", line 197, in _get_response
    response = wrapped_callback(request, *callback_args, **callback_kwargs)
  File "/home/farsana.ka/Documents/Bus Buddy/source_code/web/env/lib/python3.10/site-packages/django/views/decorators/csrf.py", line 56, in wrapper_view
    return view_func(*args, **kwargs)
  File "/home/farsana.ka/Documents/Bus Buddy/source_code/web/env/lib/python3.10/site-packages/django/views/generic/base.py", line 104, in view
    return self.dispatch(request, *args, **kwargs)
  File "/home/farsana.ka/Documents/Bus Buddy/source_code/web/env/lib/python3.10/site-packages/rest_framework/views.py", line 509, in dispatch
    response = self.handle_exception(exc)
  File "/home/farsana.ka/Documents/Bus Buddy/source_code/web/env/lib/python3.10/site-packages/rest_framework/views.py", line 469, in handle_exception
    self.raise_uncaught_exception(exc)
  File "/home/farsana.ka/Documents/Bus Buddy/source_code/web/env/lib/python3.10/site-packages/rest_framework/views.py", line 480, in raise_uncaught_exception
    raise exc
  File "/home/farsana.ka/Documents/Bus Buddy/source_code/web/env/lib/python3.10/site-packages/rest_framework/views.py", line 506, in dispatch
    response = handler(request, *args, **kwargs)
  File "/home/farsana.ka/Documents/Bus Buddy/source_code/web/bus_buddy_back_end/bus_owner/views.py", line 41, in put
    return self.update(request, id)
  File "/home/farsana.ka/Documents/Bus Buddy/source_code/web/bus_buddy_back_end/bus_owner/views.py", line 30, in update
    instance = self.get_object()
  File "/home/farsana.ka/Documents/Bus Buddy/source_code/web/env/lib/python3.10/site-packages/rest_framework/generics.py", line 83, in get_object
    queryset = self.filter_queryset(self.get_queryset())
  File "/home/farsana.ka/Documents/Bus Buddy/source_code/web/env/lib/python3.10/site-packages/rest_framework/generics.py", line 63, in get_queryset
    assert self.queryset is not None, (
AssertionError: 'UpdateBusOwner' should either include a `queryset` attribute, or override the `get_queryset()` method.
