django.request ERROR 2023-10-13 12:35:28,585 log 57254 140509898073664 Internal Server Error: /deletebus/6/
Traceback (most recent call last):
  File "/home/antony.jose/Bus_buddy_new/Bus-Buddy/env/lib/python3.10/site-packages/django/core/handlers/exception.py", line 55, in inner
    response = get_response(request)
  File "/home/antony.jose/Bus_buddy_new/Bus-Buddy/env/lib/python3.10/site-packages/django/core/handlers/base.py", line 197, in _get_response
    response = wrapped_callback(request, *callback_args, **callback_kwargs)
  File "/home/antony.jose/Bus_buddy_new/Bus-Buddy/env/lib/python3.10/site-packages/django/views/decorators/csrf.py", line 56, in wrapper_view
    return view_func(*args, **kwargs)
  File "/home/antony.jose/Bus_buddy_new/Bus-Buddy/env/lib/python3.10/site-packages/django/views/generic/base.py", line 104, in view
    return self.dispatch(request, *args, **kwargs)
  File "/home/antony.jose/Bus_buddy_new/Bus-Buddy/env/lib/python3.10/site-packages/rest_framework/views.py", line 509, in dispatch
    response = self.handle_exception(exc)
  File "/home/antony.jose/Bus_buddy_new/Bus-Buddy/env/lib/python3.10/site-packages/rest_framework/views.py", line 469, in handle_exception
    self.raise_uncaught_exception(exc)
  File "/home/antony.jose/Bus_buddy_new/Bus-Buddy/env/lib/python3.10/site-packages/rest_framework/views.py", line 480, in raise_uncaught_exception
    raise exc
  File "/home/antony.jose/Bus_buddy_new/Bus-Buddy/env/lib/python3.10/site-packages/rest_framework/views.py", line 506, in dispatch
    response = handler(request, *args, **kwargs)
TypeError: Deletebus.put() got an unexpected keyword argument 'bus_name'
django.request ERROR 2023-10-13 12:36:14,108 log 57254 140509502756416 Internal Server Error: /deletebus/6/
Traceback (most recent call last):
  File "/home/antony.jose/Bus_buddy_new/Bus-Buddy/env/lib/python3.10/site-packages/django/core/handlers/exception.py", line 55, in inner
    response = get_response(request)
  File "/home/antony.jose/Bus_buddy_new/Bus-Buddy/env/lib/python3.10/site-packages/django/core/handlers/base.py", line 197, in _get_response
    response = wrapped_callback(request, *callback_args, **callback_kwargs)
  File "/home/antony.jose/Bus_buddy_new/Bus-Buddy/env/lib/python3.10/site-packages/django/views/decorators/csrf.py", line 56, in wrapper_view
    return view_func(*args, **kwargs)
  File "/home/antony.jose/Bus_buddy_new/Bus-Buddy/env/lib/python3.10/site-packages/django/views/generic/base.py", line 104, in view
    return self.dispatch(request, *args, **kwargs)
  File "/home/antony.jose/Bus_buddy_new/Bus-Buddy/env/lib/python3.10/site-packages/rest_framework/views.py", line 509, in dispatch
    response = self.handle_exception(exc)
  File "/home/antony.jose/Bus_buddy_new/Bus-Buddy/env/lib/python3.10/site-packages/rest_framework/views.py", line 469, in handle_exception
    self.raise_uncaught_exception(exc)
  File "/home/antony.jose/Bus_buddy_new/Bus-Buddy/env/lib/python3.10/site-packages/rest_framework/views.py", line 480, in raise_uncaught_exception
    raise exc
  File "/home/antony.jose/Bus_buddy_new/Bus-Buddy/env/lib/python3.10/site-packages/rest_framework/views.py", line 506, in dispatch
    response = handler(request, *args, **kwargs)
TypeError: Deletebus.put() got an unexpected keyword argument 'bus_name'
django.request ERROR 2023-10-13 12:42:10,543 log 58298 140269135590976 Internal Server Error: /updatebus/1/
Traceback (most recent call last):
  File "/home/antony.jose/Bus_buddy_new/Bus-Buddy/env/lib/python3.10/site-packages/django/core/handlers/exception.py", line 55, in inner
    response = get_response(request)
  File "/home/antony.jose/Bus_buddy_new/Bus-Buddy/env/lib/python3.10/site-packages/django/core/handlers/base.py", line 197, in _get_response
    response = wrapped_callback(request, *callback_args, **callback_kwargs)
  File "/home/antony.jose/Bus_buddy_new/Bus-Buddy/env/lib/python3.10/site-packages/django/views/decorators/csrf.py", line 56, in wrapper_view
    return view_func(*args, **kwargs)
  File "/home/antony.jose/Bus_buddy_new/Bus-Buddy/env/lib/python3.10/site-packages/django/views/generic/base.py", line 104, in view
    return self.dispatch(request, *args, **kwargs)
  File "/home/antony.jose/Bus_buddy_new/Bus-Buddy/env/lib/python3.10/site-packages/rest_framework/views.py", line 509, in dispatch
    response = self.handle_exception(exc)
  File "/home/antony.jose/Bus_buddy_new/Bus-Buddy/env/lib/python3.10/site-packages/rest_framework/views.py", line 469, in handle_exception
    self.raise_uncaught_exception(exc)
  File "/home/antony.jose/Bus_buddy_new/Bus-Buddy/env/lib/python3.10/site-packages/rest_framework/views.py", line 480, in raise_uncaught_exception
    raise exc
  File "/home/antony.jose/Bus_buddy_new/Bus-Buddy/env/lib/python3.10/site-packages/rest_framework/views.py", line 506, in dispatch
    response = handler(request, *args, **kwargs)
TypeError: Updatebus.put() got an unexpected keyword argument 'id'
django.request ERROR 2023-10-13 12:47:28,315 log 59140 140643773965888 Internal Server Error: /updatebus/1/
Traceback (most recent call last):
  File "/home/antony.jose/Bus_buddy_new/Bus-Buddy/env/lib/python3.10/site-packages/django/core/handlers/exception.py", line 55, in inner
    response = get_response(request)
  File "/home/antony.jose/Bus_buddy_new/Bus-Buddy/env/lib/python3.10/site-packages/django/core/handlers/base.py", line 197, in _get_response
    response = wrapped_callback(request, *callback_args, **callback_kwargs)
  File "/home/antony.jose/Bus_buddy_new/Bus-Buddy/env/lib/python3.10/site-packages/django/views/decorators/csrf.py", line 56, in wrapper_view
    return view_func(*args, **kwargs)
  File "/home/antony.jose/Bus_buddy_new/Bus-Buddy/env/lib/python3.10/site-packages/django/views/generic/base.py", line 104, in view
    return self.dispatch(request, *args, **kwargs)
  File "/home/antony.jose/Bus_buddy_new/Bus-Buddy/env/lib/python3.10/site-packages/rest_framework/views.py", line 509, in dispatch
    response = self.handle_exception(exc)
  File "/home/antony.jose/Bus_buddy_new/Bus-Buddy/env/lib/python3.10/site-packages/rest_framework/views.py", line 469, in handle_exception
    self.raise_uncaught_exception(exc)
  File "/home/antony.jose/Bus_buddy_new/Bus-Buddy/env/lib/python3.10/site-packages/rest_framework/views.py", line 480, in raise_uncaught_exception
    raise exc
  File "/home/antony.jose/Bus_buddy_new/Bus-Buddy/env/lib/python3.10/site-packages/rest_framework/views.py", line 506, in dispatch
    response = handler(request, *args, **kwargs)
  File "/home/antony.jose/Bus_buddy_new/Bus-Buddy/source_code/web/bus_buddy_back_end/bus_owner/views.py", line 55, in put
    data.user=serializer.validated_data['user']
KeyError: 'user'
django.request ERROR 2023-10-13 12:48:14,041 log 59140 140643773965888 Internal Server Error: /updatebus/1/
Traceback (most recent call last):
  File "/home/antony.jose/Bus_buddy_new/Bus-Buddy/env/lib/python3.10/site-packages/django/core/handlers/exception.py", line 55, in inner
    response = get_response(request)
  File "/home/antony.jose/Bus_buddy_new/Bus-Buddy/env/lib/python3.10/site-packages/django/core/handlers/base.py", line 197, in _get_response
    response = wrapped_callback(request, *callback_args, **callback_kwargs)
  File "/home/antony.jose/Bus_buddy_new/Bus-Buddy/env/lib/python3.10/site-packages/django/views/decorators/csrf.py", line 56, in wrapper_view
    return view_func(*args, **kwargs)
  File "/home/antony.jose/Bus_buddy_new/Bus-Buddy/env/lib/python3.10/site-packages/django/views/generic/base.py", line 104, in view
    return self.dispatch(request, *args, **kwargs)
  File "/home/antony.jose/Bus_buddy_new/Bus-Buddy/env/lib/python3.10/site-packages/rest_framework/views.py", line 509, in dispatch
    response = self.handle_exception(exc)
  File "/home/antony.jose/Bus_buddy_new/Bus-Buddy/env/lib/python3.10/site-packages/rest_framework/views.py", line 469, in handle_exception
    self.raise_uncaught_exception(exc)
  File "/home/antony.jose/Bus_buddy_new/Bus-Buddy/env/lib/python3.10/site-packages/rest_framework/views.py", line 480, in raise_uncaught_exception
    raise exc
  File "/home/antony.jose/Bus_buddy_new/Bus-Buddy/env/lib/python3.10/site-packages/rest_framework/views.py", line 506, in dispatch
    response = handler(request, *args, **kwargs)
  File "/home/antony.jose/Bus_buddy_new/Bus-Buddy/source_code/web/bus_buddy_back_end/bus_owner/views.py", line 55, in put
    data.user=serializer.validated_data['user']
  File "/home/antony.jose/Bus_buddy_new/Bus-Buddy/env/lib/python3.10/site-packages/django/db/models/fields/related_descriptors.py", line 266, in __set__
    raise ValueError(
ValueError: Cannot assign "'1'": "Bus.user" must be a "User" instance.
django.request ERROR 2023-10-13 12:49:06,734 log 59489 140635190322752 Internal Server Error: /updatebus/1/
Traceback (most recent call last):
  File "/home/antony.jose/Bus_buddy_new/Bus-Buddy/env/lib/python3.10/site-packages/django/core/handlers/exception.py", line 55, in inner
    response = get_response(request)
  File "/home/antony.jose/Bus_buddy_new/Bus-Buddy/env/lib/python3.10/site-packages/django/core/handlers/base.py", line 197, in _get_response
    response = wrapped_callback(request, *callback_args, **callback_kwargs)
  File "/home/antony.jose/Bus_buddy_new/Bus-Buddy/env/lib/python3.10/site-packages/django/views/decorators/csrf.py", line 56, in wrapper_view
    return view_func(*args, **kwargs)
  File "/home/antony.jose/Bus_buddy_new/Bus-Buddy/env/lib/python3.10/site-packages/django/views/generic/base.py", line 104, in view
    return self.dispatch(request, *args, **kwargs)
  File "/home/antony.jose/Bus_buddy_new/Bus-Buddy/env/lib/python3.10/site-packages/rest_framework/views.py", line 509, in dispatch
    response = self.handle_exception(exc)
  File "/home/antony.jose/Bus_buddy_new/Bus-Buddy/env/lib/python3.10/site-packages/rest_framework/views.py", line 469, in handle_exception
    self.raise_uncaught_exception(exc)
  File "/home/antony.jose/Bus_buddy_new/Bus-Buddy/env/lib/python3.10/site-packages/rest_framework/views.py", line 480, in raise_uncaught_exception
    raise exc
  File "/home/antony.jose/Bus_buddy_new/Bus-Buddy/env/lib/python3.10/site-packages/rest_framework/views.py", line 506, in dispatch
    response = handler(request, *args, **kwargs)
  File "/home/antony.jose/Bus_buddy_new/Bus-Buddy/source_code/web/bus_buddy_back_end/bus_owner/views.py", line 55, in put
    data.user=1
  File "/home/antony.jose/Bus_buddy_new/Bus-Buddy/env/lib/python3.10/site-packages/django/db/models/fields/related_descriptors.py", line 266, in __set__
    raise ValueError(
ValueError: Cannot assign "1": "Bus.user" must be a "User" instance.
