django.request WARNING 2023-11-13 07:48:37,361 log 33423 140344633062976 Bad Request: /user/book-seat/
django.request WARNING 2023-11-13 07:48:46,592 log 33423 140344633062976 Bad Request: /user/book-seat/
django.request WARNING 2023-11-13 08:00:24,175 log 35751 139686445049408 Bad Request: /user/book-seat/
django.request WARNING 2023-11-13 15:11:23,299 log 78671 140556274492992 Unauthorized: /user/book-seat/
django.request WARNING 2023-11-14 03:47:03,233 log 7634 140690993440320 Unauthorized: /user/book-seat/
django.request WARNING 2023-11-14 04:37:39,117 log 7634 140690993440320 Unauthorized: /user/update-profile
django.request WARNING 2023-11-14 07:36:19,454 log 7634 140690993440320 Unauthorized: /user/book-seat/
django.request WARNING 2023-11-14 09:14:33,161 log 43831 140641844586048 Not Found: /user/cancel-booking/9
django.request ERROR 2023-11-14 09:15:01,437 log 43831 140641844586048 Internal Server Error: /user/cancel-booking/
Traceback (most recent call last):
  File "/home/farsana.ka/Documents/Bus Buddy/source_code/web/env/lib/python3.10/site-packages/django/core/handlers/exception.py", line 55, in inner
    response = get_response(request)
  File "/home/farsana.ka/Documents/Bus Buddy/source_code/web/env/lib/python3.10/site-packages/django/core/handlers/base.py", line 197, in _get_response
    response = wrapped_callback(request, *callback_args, **callback_kwargs)
  File "/home/farsana.ka/Documents/Bus Buddy/source_code/web/env/lib/python3.10/site-packages/django/views/decorators/csrf.py", line 56, in wrapper_view
    return view_func(*args, **kwargs)
  File "/home/farsana.ka/Documents/Bus Buddy/source_code/web/env/lib/python3.10/site-packages/django/views/generic/base.py", line 104, in view
    return self.dispatch(request, *args, **kwargs)
  File "/home/farsana.ka/Documents/Bus Buddy/source_code/web/env/lib/python3.10/site-packages/rest_framework/views.py", line 509, in dispatch
    response = self.handle_exception(exc)
  File "/home/farsana.ka/Documents/Bus Buddy/source_code/web/env/lib/python3.10/site-packages/rest_framework/views.py", line 469, in handle_exception
    self.raise_uncaught_exception(exc)
  File "/home/farsana.ka/Documents/Bus Buddy/source_code/web/env/lib/python3.10/site-packages/rest_framework/views.py", line 480, in raise_uncaught_exception
    raise exc
  File "/home/farsana.ka/Documents/Bus Buddy/source_code/web/env/lib/python3.10/site-packages/rest_framework/views.py", line 497, in dispatch
    self.initial(request, *args, **kwargs)
  File "/home/farsana.ka/Documents/Bus Buddy/source_code/web/env/lib/python3.10/site-packages/rest_framework/views.py", line 415, in initial
    self.check_permissions(request)
  File "/home/farsana.ka/Documents/Bus Buddy/source_code/web/env/lib/python3.10/site-packages/rest_framework/views.py", line 331, in check_permissions
    for permission in self.get_permissions():
  File "/home/farsana.ka/Documents/Bus Buddy/source_code/web/env/lib/python3.10/site-packages/rest_framework/views.py", line 278, in get_permissions
    return [permission() for permission in self.permission_classes]
TypeError: 'BasePermissionMetaclass' object is not iterable
django.request ERROR 2023-11-14 09:15:01,437 log 43831 140641844586048 Internal Server Error: /user/cancel-booking/
Traceback (most recent call last):
  File "/home/farsana.ka/Documents/Bus Buddy/source_code/web/env/lib/python3.10/site-packages/django/core/handlers/exception.py", line 55, in inner
    response = get_response(request)
  File "/home/farsana.ka/Documents/Bus Buddy/source_code/web/env/lib/python3.10/site-packages/django/core/handlers/base.py", line 197, in _get_response
    response = wrapped_callback(request, *callback_args, **callback_kwargs)
  File "/home/farsana.ka/Documents/Bus Buddy/source_code/web/env/lib/python3.10/site-packages/django/views/decorators/csrf.py", line 56, in wrapper_view
    return view_func(*args, **kwargs)
  File "/home/farsana.ka/Documents/Bus Buddy/source_code/web/env/lib/python3.10/site-packages/django/views/generic/base.py", line 104, in view
    return self.dispatch(request, *args, **kwargs)
  File "/home/farsana.ka/Documents/Bus Buddy/source_code/web/env/lib/python3.10/site-packages/rest_framework/views.py", line 509, in dispatch
    response = self.handle_exception(exc)
  File "/home/farsana.ka/Documents/Bus Buddy/source_code/web/env/lib/python3.10/site-packages/rest_framework/views.py", line 469, in handle_exception
    self.raise_uncaught_exception(exc)
  File "/home/farsana.ka/Documents/Bus Buddy/source_code/web/env/lib/python3.10/site-packages/rest_framework/views.py", line 480, in raise_uncaught_exception
    raise exc
  File "/home/farsana.ka/Documents/Bus Buddy/source_code/web/env/lib/python3.10/site-packages/rest_framework/views.py", line 497, in dispatch
    self.initial(request, *args, **kwargs)
  File "/home/farsana.ka/Documents/Bus Buddy/source_code/web/env/lib/python3.10/site-packages/rest_framework/views.py", line 415, in initial
    self.check_permissions(request)
  File "/home/farsana.ka/Documents/Bus Buddy/source_code/web/env/lib/python3.10/site-packages/rest_framework/views.py", line 331, in check_permissions
    for permission in self.get_permissions():
  File "/home/farsana.ka/Documents/Bus Buddy/source_code/web/env/lib/python3.10/site-packages/rest_framework/views.py", line 278, in get_permissions
    return [permission() for permission in self.permission_classes]
TypeError: 'BasePermissionMetaclass' object is not iterable
django.request ERROR 2023-11-14 09:26:15,073 log 43976 140588890449472 Internal Server Error: /user/cancel-booking
Traceback (most recent call last):
  File "/home/farsana.ka/Documents/Bus Buddy/source_code/web/env/lib/python3.10/site-packages/django/core/handlers/exception.py", line 55, in inner
    response = get_response(request)
  File "/home/farsana.ka/Documents/Bus Buddy/source_code/web/env/lib/python3.10/site-packages/django/utils/deprecation.py", line 136, in __call__
    response = self.process_response(request, response)
  File "/home/farsana.ka/Documents/Bus Buddy/source_code/web/env/lib/python3.10/site-packages/django/middleware/common.py", line 108, in process_response
    return self.response_redirect_class(self.get_full_path_with_slash(request))
  File "/home/farsana.ka/Documents/Bus Buddy/source_code/web/env/lib/python3.10/site-packages/django/middleware/common.py", line 87, in get_full_path_with_slash
    raise RuntimeError(
RuntimeError: You called this URL via PUT, but the URL doesn't end in a slash and you have APPEND_SLASH set. Django can't redirect to the slash URL while maintaining PUT data. Change your form to point to 127.0.0.1:8000/user/cancel-booking/?booking_id=BK25Y202335 (note the trailing slash), or set APPEND_SLASH=False in your Django settings.
django.request ERROR 2023-11-14 09:26:15,073 log 43976 140588890449472 Internal Server Error: /user/cancel-booking
Traceback (most recent call last):
  File "/home/farsana.ka/Documents/Bus Buddy/source_code/web/env/lib/python3.10/site-packages/django/core/handlers/exception.py", line 55, in inner
    response = get_response(request)
  File "/home/farsana.ka/Documents/Bus Buddy/source_code/web/env/lib/python3.10/site-packages/django/utils/deprecation.py", line 136, in __call__
    response = self.process_response(request, response)
  File "/home/farsana.ka/Documents/Bus Buddy/source_code/web/env/lib/python3.10/site-packages/django/middleware/common.py", line 108, in process_response
    return self.response_redirect_class(self.get_full_path_with_slash(request))
  File "/home/farsana.ka/Documents/Bus Buddy/source_code/web/env/lib/python3.10/site-packages/django/middleware/common.py", line 87, in get_full_path_with_slash
    raise RuntimeError(
RuntimeError: You called this URL via PUT, but the URL doesn't end in a slash and you have APPEND_SLASH set. Django can't redirect to the slash URL while maintaining PUT data. Change your form to point to 127.0.0.1:8000/user/cancel-booking/?booking_id=BK25Y202335 (note the trailing slash), or set APPEND_SLASH=False in your Django settings.
django.request ERROR 2023-11-14 09:26:40,267 log 43976 140588890449472 Internal Server Error: /user/cancel-booking
Traceback (most recent call last):
  File "/home/farsana.ka/Documents/Bus Buddy/source_code/web/env/lib/python3.10/site-packages/django/core/handlers/exception.py", line 55, in inner
    response = get_response(request)
  File "/home/farsana.ka/Documents/Bus Buddy/source_code/web/env/lib/python3.10/site-packages/django/utils/deprecation.py", line 136, in __call__
    response = self.process_response(request, response)
  File "/home/farsana.ka/Documents/Bus Buddy/source_code/web/env/lib/python3.10/site-packages/django/middleware/common.py", line 108, in process_response
    return self.response_redirect_class(self.get_full_path_with_slash(request))
  File "/home/farsana.ka/Documents/Bus Buddy/source_code/web/env/lib/python3.10/site-packages/django/middleware/common.py", line 87, in get_full_path_with_slash
    raise RuntimeError(
RuntimeError: You called this URL via PUT, but the URL doesn't end in a slash and you have APPEND_SLASH set. Django can't redirect to the slash URL while maintaining PUT data. Change your form to point to 127.0.0.1:8000/user/cancel-booking/?booking_id=BK25Y202335 (note the trailing slash), or set APPEND_SLASH=False in your Django settings.
django.request ERROR 2023-11-14 09:26:40,267 log 43976 140588890449472 Internal Server Error: /user/cancel-booking
Traceback (most recent call last):
  File "/home/farsana.ka/Documents/Bus Buddy/source_code/web/env/lib/python3.10/site-packages/django/core/handlers/exception.py", line 55, in inner
    response = get_response(request)
  File "/home/farsana.ka/Documents/Bus Buddy/source_code/web/env/lib/python3.10/site-packages/django/utils/deprecation.py", line 136, in __call__
    response = self.process_response(request, response)
  File "/home/farsana.ka/Documents/Bus Buddy/source_code/web/env/lib/python3.10/site-packages/django/middleware/common.py", line 108, in process_response
    return self.response_redirect_class(self.get_full_path_with_slash(request))
  File "/home/farsana.ka/Documents/Bus Buddy/source_code/web/env/lib/python3.10/site-packages/django/middleware/common.py", line 87, in get_full_path_with_slash
    raise RuntimeError(
RuntimeError: You called this URL via PUT, but the URL doesn't end in a slash and you have APPEND_SLASH set. Django can't redirect to the slash URL while maintaining PUT data. Change your form to point to 127.0.0.1:8000/user/cancel-booking/?booking_id=BK25Y202335 (note the trailing slash), or set APPEND_SLASH=False in your Django settings.
django.request ERROR 2023-11-14 09:27:10,276 log 43976 140588890449472 Internal Server Error: /user/cancel-booking
Traceback (most recent call last):
  File "/home/farsana.ka/Documents/Bus Buddy/source_code/web/env/lib/python3.10/site-packages/django/core/handlers/exception.py", line 55, in inner
    response = get_response(request)
  File "/home/farsana.ka/Documents/Bus Buddy/source_code/web/env/lib/python3.10/site-packages/django/utils/deprecation.py", line 136, in __call__
    response = self.process_response(request, response)
  File "/home/farsana.ka/Documents/Bus Buddy/source_code/web/env/lib/python3.10/site-packages/django/middleware/common.py", line 108, in process_response
    return self.response_redirect_class(self.get_full_path_with_slash(request))
  File "/home/farsana.ka/Documents/Bus Buddy/source_code/web/env/lib/python3.10/site-packages/django/middleware/common.py", line 87, in get_full_path_with_slash
    raise RuntimeError(
RuntimeError: You called this URL via PUT, but the URL doesn't end in a slash and you have APPEND_SLASH set. Django can't redirect to the slash URL while maintaining PUT data. Change your form to point to 127.0.0.1:8000/user/cancel-booking/?booking_id=6 (note the trailing slash), or set APPEND_SLASH=False in your Django settings.
django.request ERROR 2023-11-14 09:27:10,276 log 43976 140588890449472 Internal Server Error: /user/cancel-booking
Traceback (most recent call last):
  File "/home/farsana.ka/Documents/Bus Buddy/source_code/web/env/lib/python3.10/site-packages/django/core/handlers/exception.py", line 55, in inner
    response = get_response(request)
  File "/home/farsana.ka/Documents/Bus Buddy/source_code/web/env/lib/python3.10/site-packages/django/utils/deprecation.py", line 136, in __call__
    response = self.process_response(request, response)
  File "/home/farsana.ka/Documents/Bus Buddy/source_code/web/env/lib/python3.10/site-packages/django/middleware/common.py", line 108, in process_response
    return self.response_redirect_class(self.get_full_path_with_slash(request))
  File "/home/farsana.ka/Documents/Bus Buddy/source_code/web/env/lib/python3.10/site-packages/django/middleware/common.py", line 87, in get_full_path_with_slash
    raise RuntimeError(
RuntimeError: You called this URL via PUT, but the URL doesn't end in a slash and you have APPEND_SLASH set. Django can't redirect to the slash URL while maintaining PUT data. Change your form to point to 127.0.0.1:8000/user/cancel-booking/?booking_id=6 (note the trailing slash), or set APPEND_SLASH=False in your Django settings.
django.request WARNING 2023-11-14 09:40:21,662 log 46881 139781182846528 Unauthorized: /user/booking-history
django.request ERROR 2023-11-14 09:43:06,827 log 46881 139781170259520 Internal Server Error: /user/booking-history
Traceback (most recent call last):
  File "/home/farsana.ka/Documents/Bus Buddy/source_code/web/env/lib/python3.10/site-packages/django/db/models/fields/__init__.py", line 2053, in get_prep_value
    return int(value)
ValueError: invalid literal for int() with base 10: ''

The above exception was the direct cause of the following exception:

Traceback (most recent call last):
  File "/home/farsana.ka/Documents/Bus Buddy/source_code/web/bus_buddy_back_end/normal_user/views.py", line 160, in list
    queryset = Bookings.objects.filter(user=user_id,status=status)
  File "/home/farsana.ka/Documents/Bus Buddy/source_code/web/env/lib/python3.10/site-packages/django/db/models/manager.py", line 87, in manager_method
    return getattr(self.get_queryset(), name)(*args, **kwargs)
  File "/home/farsana.ka/Documents/Bus Buddy/source_code/web/env/lib/python3.10/site-packages/django/db/models/query.py", line 1436, in filter
    return self._filter_or_exclude(False, args, kwargs)
  File "/home/farsana.ka/Documents/Bus Buddy/source_code/web/env/lib/python3.10/site-packages/django/db/models/query.py", line 1454, in _filter_or_exclude
    clone._filter_or_exclude_inplace(negate, args, kwargs)
  File "/home/farsana.ka/Documents/Bus Buddy/source_code/web/env/lib/python3.10/site-packages/django/db/models/query.py", line 1461, in _filter_or_exclude_inplace
    self._query.add_q(Q(*args, **kwargs))
  File "/home/farsana.ka/Documents/Bus Buddy/source_code/web/env/lib/python3.10/site-packages/django/db/models/sql/query.py", line 1545, in add_q
    clause, _ = self._add_q(q_object, self.used_aliases)
  File "/home/farsana.ka/Documents/Bus Buddy/source_code/web/env/lib/python3.10/site-packages/django/db/models/sql/query.py", line 1576, in _add_q
    child_clause, needed_inner = self.build_filter(
  File "/home/farsana.ka/Documents/Bus Buddy/source_code/web/env/lib/python3.10/site-packages/django/db/models/sql/query.py", line 1491, in build_filter
    condition = self.build_lookup(lookups, col, value)
  File "/home/farsana.ka/Documents/Bus Buddy/source_code/web/env/lib/python3.10/site-packages/django/db/models/sql/query.py", line 1318, in build_lookup
    lookup = lookup_class(lhs, rhs)
  File "/home/farsana.ka/Documents/Bus Buddy/source_code/web/env/lib/python3.10/site-packages/django/db/models/lookups.py", line 27, in __init__
    self.rhs = self.get_prep_lookup()
  File "/home/farsana.ka/Documents/Bus Buddy/source_code/web/env/lib/python3.10/site-packages/django/db/models/lookups.py", line 341, in get_prep_lookup
    return super().get_prep_lookup()
  File "/home/farsana.ka/Documents/Bus Buddy/source_code/web/env/lib/python3.10/site-packages/django/db/models/lookups.py", line 85, in get_prep_lookup
    return self.lhs.output_field.get_prep_value(self.rhs)
  File "/home/farsana.ka/Documents/Bus Buddy/source_code/web/env/lib/python3.10/site-packages/django/db/models/fields/__init__.py", line 2055, in get_prep_value
    raise e.__class__(
ValueError: Field 'status' expected a number but got ''.

During handling of the above exception, another exception occurred:

Traceback (most recent call last):
  File "/home/farsana.ka/Documents/Bus Buddy/source_code/web/env/lib/python3.10/site-packages/django/core/handlers/exception.py", line 55, in inner
    response = get_response(request)
  File "/home/farsana.ka/Documents/Bus Buddy/source_code/web/env/lib/python3.10/site-packages/django/core/handlers/base.py", line 197, in _get_response
    response = wrapped_callback(request, *callback_args, **callback_kwargs)
  File "/home/farsana.ka/Documents/Bus Buddy/source_code/web/env/lib/python3.10/site-packages/django/views/decorators/csrf.py", line 56, in wrapper_view
    return view_func(*args, **kwargs)
  File "/home/farsana.ka/Documents/Bus Buddy/source_code/web/env/lib/python3.10/site-packages/django/views/generic/base.py", line 104, in view
    return self.dispatch(request, *args, **kwargs)
  File "/home/farsana.ka/Documents/Bus Buddy/source_code/web/env/lib/python3.10/site-packages/rest_framework/views.py", line 509, in dispatch
    response = self.handle_exception(exc)
  File "/home/farsana.ka/Documents/Bus Buddy/source_code/web/env/lib/python3.10/site-packages/rest_framework/views.py", line 469, in handle_exception
    self.raise_uncaught_exception(exc)
  File "/home/farsana.ka/Documents/Bus Buddy/source_code/web/env/lib/python3.10/site-packages/rest_framework/views.py", line 480, in raise_uncaught_exception
    raise exc
  File "/home/farsana.ka/Documents/Bus Buddy/source_code/web/env/lib/python3.10/site-packages/rest_framework/views.py", line 506, in dispatch
    response = handler(request, *args, **kwargs)
  File "/home/farsana.ka/Documents/Bus Buddy/source_code/web/env/lib/python3.10/site-packages/rest_framework/generics.py", line 199, in get
    return self.list(request, *args, **kwargs)
  File "/home/farsana.ka/Documents/Bus Buddy/source_code/web/bus_buddy_back_end/normal_user/views.py", line 172, in list
    return Response(serializer._errors)
UnboundLocalError: local variable 'serializer' referenced before assignment
django.request ERROR 2023-11-14 09:43:06,827 log 46881 139781170259520 Internal Server Error: /user/booking-history
Traceback (most recent call last):
  File "/home/farsana.ka/Documents/Bus Buddy/source_code/web/env/lib/python3.10/site-packages/django/db/models/fields/__init__.py", line 2053, in get_prep_value
    return int(value)
ValueError: invalid literal for int() with base 10: ''

The above exception was the direct cause of the following exception:

Traceback (most recent call last):
  File "/home/farsana.ka/Documents/Bus Buddy/source_code/web/bus_buddy_back_end/normal_user/views.py", line 160, in list
    queryset = Bookings.objects.filter(user=user_id,status=status)
  File "/home/farsana.ka/Documents/Bus Buddy/source_code/web/env/lib/python3.10/site-packages/django/db/models/manager.py", line 87, in manager_method
    return getattr(self.get_queryset(), name)(*args, **kwargs)
  File "/home/farsana.ka/Documents/Bus Buddy/source_code/web/env/lib/python3.10/site-packages/django/db/models/query.py", line 1436, in filter
    return self._filter_or_exclude(False, args, kwargs)
  File "/home/farsana.ka/Documents/Bus Buddy/source_code/web/env/lib/python3.10/site-packages/django/db/models/query.py", line 1454, in _filter_or_exclude
    clone._filter_or_exclude_inplace(negate, args, kwargs)
  File "/home/farsana.ka/Documents/Bus Buddy/source_code/web/env/lib/python3.10/site-packages/django/db/models/query.py", line 1461, in _filter_or_exclude_inplace
    self._query.add_q(Q(*args, **kwargs))
  File "/home/farsana.ka/Documents/Bus Buddy/source_code/web/env/lib/python3.10/site-packages/django/db/models/sql/query.py", line 1545, in add_q
    clause, _ = self._add_q(q_object, self.used_aliases)
  File "/home/farsana.ka/Documents/Bus Buddy/source_code/web/env/lib/python3.10/site-packages/django/db/models/sql/query.py", line 1576, in _add_q
    child_clause, needed_inner = self.build_filter(
  File "/home/farsana.ka/Documents/Bus Buddy/source_code/web/env/lib/python3.10/site-packages/django/db/models/sql/query.py", line 1491, in build_filter
    condition = self.build_lookup(lookups, col, value)
  File "/home/farsana.ka/Documents/Bus Buddy/source_code/web/env/lib/python3.10/site-packages/django/db/models/sql/query.py", line 1318, in build_lookup
    lookup = lookup_class(lhs, rhs)
  File "/home/farsana.ka/Documents/Bus Buddy/source_code/web/env/lib/python3.10/site-packages/django/db/models/lookups.py", line 27, in __init__
    self.rhs = self.get_prep_lookup()
  File "/home/farsana.ka/Documents/Bus Buddy/source_code/web/env/lib/python3.10/site-packages/django/db/models/lookups.py", line 341, in get_prep_lookup
    return super().get_prep_lookup()
  File "/home/farsana.ka/Documents/Bus Buddy/source_code/web/env/lib/python3.10/site-packages/django/db/models/lookups.py", line 85, in get_prep_lookup
    return self.lhs.output_field.get_prep_value(self.rhs)
  File "/home/farsana.ka/Documents/Bus Buddy/source_code/web/env/lib/python3.10/site-packages/django/db/models/fields/__init__.py", line 2055, in get_prep_value
    raise e.__class__(
ValueError: Field 'status' expected a number but got ''.

During handling of the above exception, another exception occurred:

Traceback (most recent call last):
  File "/home/farsana.ka/Documents/Bus Buddy/source_code/web/env/lib/python3.10/site-packages/django/core/handlers/exception.py", line 55, in inner
    response = get_response(request)
  File "/home/farsana.ka/Documents/Bus Buddy/source_code/web/env/lib/python3.10/site-packages/django/core/handlers/base.py", line 197, in _get_response
    response = wrapped_callback(request, *callback_args, **callback_kwargs)
  File "/home/farsana.ka/Documents/Bus Buddy/source_code/web/env/lib/python3.10/site-packages/django/views/decorators/csrf.py", line 56, in wrapper_view
    return view_func(*args, **kwargs)
  File "/home/farsana.ka/Documents/Bus Buddy/source_code/web/env/lib/python3.10/site-packages/django/views/generic/base.py", line 104, in view
    return self.dispatch(request, *args, **kwargs)
  File "/home/farsana.ka/Documents/Bus Buddy/source_code/web/env/lib/python3.10/site-packages/rest_framework/views.py", line 509, in dispatch
    response = self.handle_exception(exc)
  File "/home/farsana.ka/Documents/Bus Buddy/source_code/web/env/lib/python3.10/site-packages/rest_framework/views.py", line 469, in handle_exception
    self.raise_uncaught_exception(exc)
  File "/home/farsana.ka/Documents/Bus Buddy/source_code/web/env/lib/python3.10/site-packages/rest_framework/views.py", line 480, in raise_uncaught_exception
    raise exc
  File "/home/farsana.ka/Documents/Bus Buddy/source_code/web/env/lib/python3.10/site-packages/rest_framework/views.py", line 506, in dispatch
    response = handler(request, *args, **kwargs)
  File "/home/farsana.ka/Documents/Bus Buddy/source_code/web/env/lib/python3.10/site-packages/rest_framework/generics.py", line 199, in get
    return self.list(request, *args, **kwargs)
  File "/home/farsana.ka/Documents/Bus Buddy/source_code/web/bus_buddy_back_end/normal_user/views.py", line 172, in list
    return Response(serializer._errors)
UnboundLocalError: local variable 'serializer' referenced before assignment
django.request ERROR 2023-11-14 09:43:07,123 log 46881 139781170259520 Internal Server Error: /user/booking-history
Traceback (most recent call last):
  File "/home/farsana.ka/Documents/Bus Buddy/source_code/web/env/lib/python3.10/site-packages/django/db/models/fields/__init__.py", line 2053, in get_prep_value
    return int(value)
ValueError: invalid literal for int() with base 10: ''

The above exception was the direct cause of the following exception:

Traceback (most recent call last):
  File "/home/farsana.ka/Documents/Bus Buddy/source_code/web/bus_buddy_back_end/normal_user/views.py", line 160, in list
    queryset = Bookings.objects.filter(user=user_id,status=status)
  File "/home/farsana.ka/Documents/Bus Buddy/source_code/web/env/lib/python3.10/site-packages/django/db/models/manager.py", line 87, in manager_method
    return getattr(self.get_queryset(), name)(*args, **kwargs)
  File "/home/farsana.ka/Documents/Bus Buddy/source_code/web/env/lib/python3.10/site-packages/django/db/models/query.py", line 1436, in filter
    return self._filter_or_exclude(False, args, kwargs)
  File "/home/farsana.ka/Documents/Bus Buddy/source_code/web/env/lib/python3.10/site-packages/django/db/models/query.py", line 1454, in _filter_or_exclude
    clone._filter_or_exclude_inplace(negate, args, kwargs)
  File "/home/farsana.ka/Documents/Bus Buddy/source_code/web/env/lib/python3.10/site-packages/django/db/models/query.py", line 1461, in _filter_or_exclude_inplace
    self._query.add_q(Q(*args, **kwargs))
  File "/home/farsana.ka/Documents/Bus Buddy/source_code/web/env/lib/python3.10/site-packages/django/db/models/sql/query.py", line 1545, in add_q
    clause, _ = self._add_q(q_object, self.used_aliases)
  File "/home/farsana.ka/Documents/Bus Buddy/source_code/web/env/lib/python3.10/site-packages/django/db/models/sql/query.py", line 1576, in _add_q
    child_clause, needed_inner = self.build_filter(
  File "/home/farsana.ka/Documents/Bus Buddy/source_code/web/env/lib/python3.10/site-packages/django/db/models/sql/query.py", line 1491, in build_filter
    condition = self.build_lookup(lookups, col, value)
  File "/home/farsana.ka/Documents/Bus Buddy/source_code/web/env/lib/python3.10/site-packages/django/db/models/sql/query.py", line 1318, in build_lookup
    lookup = lookup_class(lhs, rhs)
  File "/home/farsana.ka/Documents/Bus Buddy/source_code/web/env/lib/python3.10/site-packages/django/db/models/lookups.py", line 27, in __init__
    self.rhs = self.get_prep_lookup()
  File "/home/farsana.ka/Documents/Bus Buddy/source_code/web/env/lib/python3.10/site-packages/django/db/models/lookups.py", line 341, in get_prep_lookup
    return super().get_prep_lookup()
  File "/home/farsana.ka/Documents/Bus Buddy/source_code/web/env/lib/python3.10/site-packages/django/db/models/lookups.py", line 85, in get_prep_lookup
    return self.lhs.output_field.get_prep_value(self.rhs)
  File "/home/farsana.ka/Documents/Bus Buddy/source_code/web/env/lib/python3.10/site-packages/django/db/models/fields/__init__.py", line 2055, in get_prep_value
    raise e.__class__(
ValueError: Field 'status' expected a number but got ''.

During handling of the above exception, another exception occurred:

Traceback (most recent call last):
  File "/home/farsana.ka/Documents/Bus Buddy/source_code/web/env/lib/python3.10/site-packages/django/core/handlers/exception.py", line 55, in inner
    response = get_response(request)
  File "/home/farsana.ka/Documents/Bus Buddy/source_code/web/env/lib/python3.10/site-packages/django/core/handlers/base.py", line 197, in _get_response
    response = wrapped_callback(request, *callback_args, **callback_kwargs)
  File "/home/farsana.ka/Documents/Bus Buddy/source_code/web/env/lib/python3.10/site-packages/django/views/decorators/csrf.py", line 56, in wrapper_view
    return view_func(*args, **kwargs)
  File "/home/farsana.ka/Documents/Bus Buddy/source_code/web/env/lib/python3.10/site-packages/django/views/generic/base.py", line 104, in view
    return self.dispatch(request, *args, **kwargs)
  File "/home/farsana.ka/Documents/Bus Buddy/source_code/web/env/lib/python3.10/site-packages/rest_framework/views.py", line 509, in dispatch
    response = self.handle_exception(exc)
  File "/home/farsana.ka/Documents/Bus Buddy/source_code/web/env/lib/python3.10/site-packages/rest_framework/views.py", line 469, in handle_exception
    self.raise_uncaught_exception(exc)
  File "/home/farsana.ka/Documents/Bus Buddy/source_code/web/env/lib/python3.10/site-packages/rest_framework/views.py", line 480, in raise_uncaught_exception
    raise exc
  File "/home/farsana.ka/Documents/Bus Buddy/source_code/web/env/lib/python3.10/site-packages/rest_framework/views.py", line 506, in dispatch
    response = handler(request, *args, **kwargs)
  File "/home/farsana.ka/Documents/Bus Buddy/source_code/web/env/lib/python3.10/site-packages/rest_framework/generics.py", line 199, in get
    return self.list(request, *args, **kwargs)
  File "/home/farsana.ka/Documents/Bus Buddy/source_code/web/bus_buddy_back_end/normal_user/views.py", line 172, in list
    return Response(serializer._errors)
UnboundLocalError: local variable 'serializer' referenced before assignment
django.request ERROR 2023-11-14 09:43:07,123 log 46881 139781170259520 Internal Server Error: /user/booking-history
Traceback (most recent call last):
  File "/home/farsana.ka/Documents/Bus Buddy/source_code/web/env/lib/python3.10/site-packages/django/db/models/fields/__init__.py", line 2053, in get_prep_value
    return int(value)
ValueError: invalid literal for int() with base 10: ''

The above exception was the direct cause of the following exception:

Traceback (most recent call last):
  File "/home/farsana.ka/Documents/Bus Buddy/source_code/web/bus_buddy_back_end/normal_user/views.py", line 160, in list
    queryset = Bookings.objects.filter(user=user_id,status=status)
  File "/home/farsana.ka/Documents/Bus Buddy/source_code/web/env/lib/python3.10/site-packages/django/db/models/manager.py", line 87, in manager_method
    return getattr(self.get_queryset(), name)(*args, **kwargs)
  File "/home/farsana.ka/Documents/Bus Buddy/source_code/web/env/lib/python3.10/site-packages/django/db/models/query.py", line 1436, in filter
    return self._filter_or_exclude(False, args, kwargs)
  File "/home/farsana.ka/Documents/Bus Buddy/source_code/web/env/lib/python3.10/site-packages/django/db/models/query.py", line 1454, in _filter_or_exclude
    clone._filter_or_exclude_inplace(negate, args, kwargs)
  File "/home/farsana.ka/Documents/Bus Buddy/source_code/web/env/lib/python3.10/site-packages/django/db/models/query.py", line 1461, in _filter_or_exclude_inplace
    self._query.add_q(Q(*args, **kwargs))
  File "/home/farsana.ka/Documents/Bus Buddy/source_code/web/env/lib/python3.10/site-packages/django/db/models/sql/query.py", line 1545, in add_q
    clause, _ = self._add_q(q_object, self.used_aliases)
  File "/home/farsana.ka/Documents/Bus Buddy/source_code/web/env/lib/python3.10/site-packages/django/db/models/sql/query.py", line 1576, in _add_q
    child_clause, needed_inner = self.build_filter(
  File "/home/farsana.ka/Documents/Bus Buddy/source_code/web/env/lib/python3.10/site-packages/django/db/models/sql/query.py", line 1491, in build_filter
    condition = self.build_lookup(lookups, col, value)
  File "/home/farsana.ka/Documents/Bus Buddy/source_code/web/env/lib/python3.10/site-packages/django/db/models/sql/query.py", line 1318, in build_lookup
    lookup = lookup_class(lhs, rhs)
  File "/home/farsana.ka/Documents/Bus Buddy/source_code/web/env/lib/python3.10/site-packages/django/db/models/lookups.py", line 27, in __init__
    self.rhs = self.get_prep_lookup()
  File "/home/farsana.ka/Documents/Bus Buddy/source_code/web/env/lib/python3.10/site-packages/django/db/models/lookups.py", line 341, in get_prep_lookup
    return super().get_prep_lookup()
  File "/home/farsana.ka/Documents/Bus Buddy/source_code/web/env/lib/python3.10/site-packages/django/db/models/lookups.py", line 85, in get_prep_lookup
    return self.lhs.output_field.get_prep_value(self.rhs)
  File "/home/farsana.ka/Documents/Bus Buddy/source_code/web/env/lib/python3.10/site-packages/django/db/models/fields/__init__.py", line 2055, in get_prep_value
    raise e.__class__(
ValueError: Field 'status' expected a number but got ''.

During handling of the above exception, another exception occurred:

Traceback (most recent call last):
  File "/home/farsana.ka/Documents/Bus Buddy/source_code/web/env/lib/python3.10/site-packages/django/core/handlers/exception.py", line 55, in inner
    response = get_response(request)
  File "/home/farsana.ka/Documents/Bus Buddy/source_code/web/env/lib/python3.10/site-packages/django/core/handlers/base.py", line 197, in _get_response
    response = wrapped_callback(request, *callback_args, **callback_kwargs)
  File "/home/farsana.ka/Documents/Bus Buddy/source_code/web/env/lib/python3.10/site-packages/django/views/decorators/csrf.py", line 56, in wrapper_view
    return view_func(*args, **kwargs)
  File "/home/farsana.ka/Documents/Bus Buddy/source_code/web/env/lib/python3.10/site-packages/django/views/generic/base.py", line 104, in view
    return self.dispatch(request, *args, **kwargs)
  File "/home/farsana.ka/Documents/Bus Buddy/source_code/web/env/lib/python3.10/site-packages/rest_framework/views.py", line 509, in dispatch
    response = self.handle_exception(exc)
  File "/home/farsana.ka/Documents/Bus Buddy/source_code/web/env/lib/python3.10/site-packages/rest_framework/views.py", line 469, in handle_exception
    self.raise_uncaught_exception(exc)
  File "/home/farsana.ka/Documents/Bus Buddy/source_code/web/env/lib/python3.10/site-packages/rest_framework/views.py", line 480, in raise_uncaught_exception
    raise exc
  File "/home/farsana.ka/Documents/Bus Buddy/source_code/web/env/lib/python3.10/site-packages/rest_framework/views.py", line 506, in dispatch
    response = handler(request, *args, **kwargs)
  File "/home/farsana.ka/Documents/Bus Buddy/source_code/web/env/lib/python3.10/site-packages/rest_framework/generics.py", line 199, in get
    return self.list(request, *args, **kwargs)
  File "/home/farsana.ka/Documents/Bus Buddy/source_code/web/bus_buddy_back_end/normal_user/views.py", line 172, in list
    return Response(serializer._errors)
UnboundLocalError: local variable 'serializer' referenced before assignment
django.request ERROR 2023-11-14 09:43:13,087 log 46881 139781170259520 Internal Server Error: /user/booking-history
Traceback (most recent call last):
  File "/home/farsana.ka/Documents/Bus Buddy/source_code/web/env/lib/python3.10/site-packages/django/db/models/fields/__init__.py", line 2053, in get_prep_value
    return int(value)
ValueError: invalid literal for int() with base 10: ''

The above exception was the direct cause of the following exception:

Traceback (most recent call last):
  File "/home/farsana.ka/Documents/Bus Buddy/source_code/web/bus_buddy_back_end/normal_user/views.py", line 160, in list
    queryset = Bookings.objects.filter(user=user_id,status=status)
  File "/home/farsana.ka/Documents/Bus Buddy/source_code/web/env/lib/python3.10/site-packages/django/db/models/manager.py", line 87, in manager_method
    return getattr(self.get_queryset(), name)(*args, **kwargs)
  File "/home/farsana.ka/Documents/Bus Buddy/source_code/web/env/lib/python3.10/site-packages/django/db/models/query.py", line 1436, in filter
    return self._filter_or_exclude(False, args, kwargs)
  File "/home/farsana.ka/Documents/Bus Buddy/source_code/web/env/lib/python3.10/site-packages/django/db/models/query.py", line 1454, in _filter_or_exclude
    clone._filter_or_exclude_inplace(negate, args, kwargs)
  File "/home/farsana.ka/Documents/Bus Buddy/source_code/web/env/lib/python3.10/site-packages/django/db/models/query.py", line 1461, in _filter_or_exclude_inplace
    self._query.add_q(Q(*args, **kwargs))
  File "/home/farsana.ka/Documents/Bus Buddy/source_code/web/env/lib/python3.10/site-packages/django/db/models/sql/query.py", line 1545, in add_q
    clause, _ = self._add_q(q_object, self.used_aliases)
  File "/home/farsana.ka/Documents/Bus Buddy/source_code/web/env/lib/python3.10/site-packages/django/db/models/sql/query.py", line 1576, in _add_q
    child_clause, needed_inner = self.build_filter(
  File "/home/farsana.ka/Documents/Bus Buddy/source_code/web/env/lib/python3.10/site-packages/django/db/models/sql/query.py", line 1491, in build_filter
    condition = self.build_lookup(lookups, col, value)
  File "/home/farsana.ka/Documents/Bus Buddy/source_code/web/env/lib/python3.10/site-packages/django/db/models/sql/query.py", line 1318, in build_lookup
    lookup = lookup_class(lhs, rhs)
  File "/home/farsana.ka/Documents/Bus Buddy/source_code/web/env/lib/python3.10/site-packages/django/db/models/lookups.py", line 27, in __init__
    self.rhs = self.get_prep_lookup()
  File "/home/farsana.ka/Documents/Bus Buddy/source_code/web/env/lib/python3.10/site-packages/django/db/models/lookups.py", line 341, in get_prep_lookup
    return super().get_prep_lookup()
  File "/home/farsana.ka/Documents/Bus Buddy/source_code/web/env/lib/python3.10/site-packages/django/db/models/lookups.py", line 85, in get_prep_lookup
    return self.lhs.output_field.get_prep_value(self.rhs)
  File "/home/farsana.ka/Documents/Bus Buddy/source_code/web/env/lib/python3.10/site-packages/django/db/models/fields/__init__.py", line 2055, in get_prep_value
    raise e.__class__(
ValueError: Field 'status' expected a number but got ''.

During handling of the above exception, another exception occurred:

Traceback (most recent call last):
  File "/home/farsana.ka/Documents/Bus Buddy/source_code/web/env/lib/python3.10/site-packages/django/core/handlers/exception.py", line 55, in inner
    response = get_response(request)
  File "/home/farsana.ka/Documents/Bus Buddy/source_code/web/env/lib/python3.10/site-packages/django/core/handlers/base.py", line 197, in _get_response
    response = wrapped_callback(request, *callback_args, **callback_kwargs)
  File "/home/farsana.ka/Documents/Bus Buddy/source_code/web/env/lib/python3.10/site-packages/django/views/decorators/csrf.py", line 56, in wrapper_view
    return view_func(*args, **kwargs)
  File "/home/farsana.ka/Documents/Bus Buddy/source_code/web/env/lib/python3.10/site-packages/django/views/generic/base.py", line 104, in view
    return self.dispatch(request, *args, **kwargs)
  File "/home/farsana.ka/Documents/Bus Buddy/source_code/web/env/lib/python3.10/site-packages/rest_framework/views.py", line 509, in dispatch
    response = self.handle_exception(exc)
  File "/home/farsana.ka/Documents/Bus Buddy/source_code/web/env/lib/python3.10/site-packages/rest_framework/views.py", line 469, in handle_exception
    self.raise_uncaught_exception(exc)
  File "/home/farsana.ka/Documents/Bus Buddy/source_code/web/env/lib/python3.10/site-packages/rest_framework/views.py", line 480, in raise_uncaught_exception
    raise exc
  File "/home/farsana.ka/Documents/Bus Buddy/source_code/web/env/lib/python3.10/site-packages/rest_framework/views.py", line 506, in dispatch
    response = handler(request, *args, **kwargs)
  File "/home/farsana.ka/Documents/Bus Buddy/source_code/web/env/lib/python3.10/site-packages/rest_framework/generics.py", line 199, in get
    return self.list(request, *args, **kwargs)
  File "/home/farsana.ka/Documents/Bus Buddy/source_code/web/bus_buddy_back_end/normal_user/views.py", line 172, in list
    return Response(serializer._errors)
UnboundLocalError: local variable 'serializer' referenced before assignment
django.request ERROR 2023-11-14 09:43:13,087 log 46881 139781170259520 Internal Server Error: /user/booking-history
Traceback (most recent call last):
  File "/home/farsana.ka/Documents/Bus Buddy/source_code/web/env/lib/python3.10/site-packages/django/db/models/fields/__init__.py", line 2053, in get_prep_value
    return int(value)
ValueError: invalid literal for int() with base 10: ''

The above exception was the direct cause of the following exception:

Traceback (most recent call last):
  File "/home/farsana.ka/Documents/Bus Buddy/source_code/web/bus_buddy_back_end/normal_user/views.py", line 160, in list
    queryset = Bookings.objects.filter(user=user_id,status=status)
  File "/home/farsana.ka/Documents/Bus Buddy/source_code/web/env/lib/python3.10/site-packages/django/db/models/manager.py", line 87, in manager_method
    return getattr(self.get_queryset(), name)(*args, **kwargs)
  File "/home/farsana.ka/Documents/Bus Buddy/source_code/web/env/lib/python3.10/site-packages/django/db/models/query.py", line 1436, in filter
    return self._filter_or_exclude(False, args, kwargs)
  File "/home/farsana.ka/Documents/Bus Buddy/source_code/web/env/lib/python3.10/site-packages/django/db/models/query.py", line 1454, in _filter_or_exclude
    clone._filter_or_exclude_inplace(negate, args, kwargs)
  File "/home/farsana.ka/Documents/Bus Buddy/source_code/web/env/lib/python3.10/site-packages/django/db/models/query.py", line 1461, in _filter_or_exclude_inplace
    self._query.add_q(Q(*args, **kwargs))
  File "/home/farsana.ka/Documents/Bus Buddy/source_code/web/env/lib/python3.10/site-packages/django/db/models/sql/query.py", line 1545, in add_q
    clause, _ = self._add_q(q_object, self.used_aliases)
  File "/home/farsana.ka/Documents/Bus Buddy/source_code/web/env/lib/python3.10/site-packages/django/db/models/sql/query.py", line 1576, in _add_q
    child_clause, needed_inner = self.build_filter(
  File "/home/farsana.ka/Documents/Bus Buddy/source_code/web/env/lib/python3.10/site-packages/django/db/models/sql/query.py", line 1491, in build_filter
    condition = self.build_lookup(lookups, col, value)
  File "/home/farsana.ka/Documents/Bus Buddy/source_code/web/env/lib/python3.10/site-packages/django/db/models/sql/query.py", line 1318, in build_lookup
    lookup = lookup_class(lhs, rhs)
  File "/home/farsana.ka/Documents/Bus Buddy/source_code/web/env/lib/python3.10/site-packages/django/db/models/lookups.py", line 27, in __init__
    self.rhs = self.get_prep_lookup()
  File "/home/farsana.ka/Documents/Bus Buddy/source_code/web/env/lib/python3.10/site-packages/django/db/models/lookups.py", line 341, in get_prep_lookup
    return super().get_prep_lookup()
  File "/home/farsana.ka/Documents/Bus Buddy/source_code/web/env/lib/python3.10/site-packages/django/db/models/lookups.py", line 85, in get_prep_lookup
    return self.lhs.output_field.get_prep_value(self.rhs)
  File "/home/farsana.ka/Documents/Bus Buddy/source_code/web/env/lib/python3.10/site-packages/django/db/models/fields/__init__.py", line 2055, in get_prep_value
    raise e.__class__(
ValueError: Field 'status' expected a number but got ''.

During handling of the above exception, another exception occurred:

Traceback (most recent call last):
  File "/home/farsana.ka/Documents/Bus Buddy/source_code/web/env/lib/python3.10/site-packages/django/core/handlers/exception.py", line 55, in inner
    response = get_response(request)
  File "/home/farsana.ka/Documents/Bus Buddy/source_code/web/env/lib/python3.10/site-packages/django/core/handlers/base.py", line 197, in _get_response
    response = wrapped_callback(request, *callback_args, **callback_kwargs)
  File "/home/farsana.ka/Documents/Bus Buddy/source_code/web/env/lib/python3.10/site-packages/django/views/decorators/csrf.py", line 56, in wrapper_view
    return view_func(*args, **kwargs)
  File "/home/farsana.ka/Documents/Bus Buddy/source_code/web/env/lib/python3.10/site-packages/django/views/generic/base.py", line 104, in view
    return self.dispatch(request, *args, **kwargs)
  File "/home/farsana.ka/Documents/Bus Buddy/source_code/web/env/lib/python3.10/site-packages/rest_framework/views.py", line 509, in dispatch
    response = self.handle_exception(exc)
  File "/home/farsana.ka/Documents/Bus Buddy/source_code/web/env/lib/python3.10/site-packages/rest_framework/views.py", line 469, in handle_exception
    self.raise_uncaught_exception(exc)
  File "/home/farsana.ka/Documents/Bus Buddy/source_code/web/env/lib/python3.10/site-packages/rest_framework/views.py", line 480, in raise_uncaught_exception
    raise exc
  File "/home/farsana.ka/Documents/Bus Buddy/source_code/web/env/lib/python3.10/site-packages/rest_framework/views.py", line 506, in dispatch
    response = handler(request, *args, **kwargs)
  File "/home/farsana.ka/Documents/Bus Buddy/source_code/web/env/lib/python3.10/site-packages/rest_framework/generics.py", line 199, in get
    return self.list(request, *args, **kwargs)
  File "/home/farsana.ka/Documents/Bus Buddy/source_code/web/bus_buddy_back_end/normal_user/views.py", line 172, in list
    return Response(serializer._errors)
UnboundLocalError: local variable 'serializer' referenced before assignment
django.request ERROR 2023-11-14 09:43:33,402 log 46881 139781170259520 Internal Server Error: /user/booking-history
Traceback (most recent call last):
  File "/home/farsana.ka/Documents/Bus Buddy/source_code/web/env/lib/python3.10/site-packages/django/db/models/fields/__init__.py", line 2053, in get_prep_value
    return int(value)
ValueError: invalid literal for int() with base 10: ''

The above exception was the direct cause of the following exception:

Traceback (most recent call last):
  File "/home/farsana.ka/Documents/Bus Buddy/source_code/web/bus_buddy_back_end/normal_user/views.py", line 160, in list
    queryset = Bookings.objects.filter(user=user_id,status=status)
  File "/home/farsana.ka/Documents/Bus Buddy/source_code/web/env/lib/python3.10/site-packages/django/db/models/manager.py", line 87, in manager_method
    return getattr(self.get_queryset(), name)(*args, **kwargs)
  File "/home/farsana.ka/Documents/Bus Buddy/source_code/web/env/lib/python3.10/site-packages/django/db/models/query.py", line 1436, in filter
    return self._filter_or_exclude(False, args, kwargs)
  File "/home/farsana.ka/Documents/Bus Buddy/source_code/web/env/lib/python3.10/site-packages/django/db/models/query.py", line 1454, in _filter_or_exclude
    clone._filter_or_exclude_inplace(negate, args, kwargs)
  File "/home/farsana.ka/Documents/Bus Buddy/source_code/web/env/lib/python3.10/site-packages/django/db/models/query.py", line 1461, in _filter_or_exclude_inplace
    self._query.add_q(Q(*args, **kwargs))
  File "/home/farsana.ka/Documents/Bus Buddy/source_code/web/env/lib/python3.10/site-packages/django/db/models/sql/query.py", line 1545, in add_q
    clause, _ = self._add_q(q_object, self.used_aliases)
  File "/home/farsana.ka/Documents/Bus Buddy/source_code/web/env/lib/python3.10/site-packages/django/db/models/sql/query.py", line 1576, in _add_q
    child_clause, needed_inner = self.build_filter(
  File "/home/farsana.ka/Documents/Bus Buddy/source_code/web/env/lib/python3.10/site-packages/django/db/models/sql/query.py", line 1491, in build_filter
    condition = self.build_lookup(lookups, col, value)
  File "/home/farsana.ka/Documents/Bus Buddy/source_code/web/env/lib/python3.10/site-packages/django/db/models/sql/query.py", line 1318, in build_lookup
    lookup = lookup_class(lhs, rhs)
  File "/home/farsana.ka/Documents/Bus Buddy/source_code/web/env/lib/python3.10/site-packages/django/db/models/lookups.py", line 27, in __init__
    self.rhs = self.get_prep_lookup()
  File "/home/farsana.ka/Documents/Bus Buddy/source_code/web/env/lib/python3.10/site-packages/django/db/models/lookups.py", line 341, in get_prep_lookup
    return super().get_prep_lookup()
  File "/home/farsana.ka/Documents/Bus Buddy/source_code/web/env/lib/python3.10/site-packages/django/db/models/lookups.py", line 85, in get_prep_lookup
    return self.lhs.output_field.get_prep_value(self.rhs)
  File "/home/farsana.ka/Documents/Bus Buddy/source_code/web/env/lib/python3.10/site-packages/django/db/models/fields/__init__.py", line 2055, in get_prep_value
    raise e.__class__(
ValueError: Field 'status' expected a number but got ''.

During handling of the above exception, another exception occurred:

Traceback (most recent call last):
  File "/home/farsana.ka/Documents/Bus Buddy/source_code/web/env/lib/python3.10/site-packages/django/core/handlers/exception.py", line 55, in inner
    response = get_response(request)
  File "/home/farsana.ka/Documents/Bus Buddy/source_code/web/env/lib/python3.10/site-packages/django/core/handlers/base.py", line 197, in _get_response
    response = wrapped_callback(request, *callback_args, **callback_kwargs)
  File "/home/farsana.ka/Documents/Bus Buddy/source_code/web/env/lib/python3.10/site-packages/django/views/decorators/csrf.py", line 56, in wrapper_view
    return view_func(*args, **kwargs)
  File "/home/farsana.ka/Documents/Bus Buddy/source_code/web/env/lib/python3.10/site-packages/django/views/generic/base.py", line 104, in view
    return self.dispatch(request, *args, **kwargs)
  File "/home/farsana.ka/Documents/Bus Buddy/source_code/web/env/lib/python3.10/site-packages/rest_framework/views.py", line 509, in dispatch
    response = self.handle_exception(exc)
  File "/home/farsana.ka/Documents/Bus Buddy/source_code/web/env/lib/python3.10/site-packages/rest_framework/views.py", line 469, in handle_exception
    self.raise_uncaught_exception(exc)
  File "/home/farsana.ka/Documents/Bus Buddy/source_code/web/env/lib/python3.10/site-packages/rest_framework/views.py", line 480, in raise_uncaught_exception
    raise exc
  File "/home/farsana.ka/Documents/Bus Buddy/source_code/web/env/lib/python3.10/site-packages/rest_framework/views.py", line 506, in dispatch
    response = handler(request, *args, **kwargs)
  File "/home/farsana.ka/Documents/Bus Buddy/source_code/web/env/lib/python3.10/site-packages/rest_framework/generics.py", line 199, in get
    return self.list(request, *args, **kwargs)
  File "/home/farsana.ka/Documents/Bus Buddy/source_code/web/bus_buddy_back_end/normal_user/views.py", line 172, in list
    return Response(serializer._errors)
UnboundLocalError: local variable 'serializer' referenced before assignment
django.request ERROR 2023-11-14 09:43:33,402 log 46881 139781170259520 Internal Server Error: /user/booking-history
Traceback (most recent call last):
  File "/home/farsana.ka/Documents/Bus Buddy/source_code/web/env/lib/python3.10/site-packages/django/db/models/fields/__init__.py", line 2053, in get_prep_value
    return int(value)
ValueError: invalid literal for int() with base 10: ''

The above exception was the direct cause of the following exception:

Traceback (most recent call last):
  File "/home/farsana.ka/Documents/Bus Buddy/source_code/web/bus_buddy_back_end/normal_user/views.py", line 160, in list
    queryset = Bookings.objects.filter(user=user_id,status=status)
  File "/home/farsana.ka/Documents/Bus Buddy/source_code/web/env/lib/python3.10/site-packages/django/db/models/manager.py", line 87, in manager_method
    return getattr(self.get_queryset(), name)(*args, **kwargs)
  File "/home/farsana.ka/Documents/Bus Buddy/source_code/web/env/lib/python3.10/site-packages/django/db/models/query.py", line 1436, in filter
    return self._filter_or_exclude(False, args, kwargs)
  File "/home/farsana.ka/Documents/Bus Buddy/source_code/web/env/lib/python3.10/site-packages/django/db/models/query.py", line 1454, in _filter_or_exclude
    clone._filter_or_exclude_inplace(negate, args, kwargs)
  File "/home/farsana.ka/Documents/Bus Buddy/source_code/web/env/lib/python3.10/site-packages/django/db/models/query.py", line 1461, in _filter_or_exclude_inplace
    self._query.add_q(Q(*args, **kwargs))
  File "/home/farsana.ka/Documents/Bus Buddy/source_code/web/env/lib/python3.10/site-packages/django/db/models/sql/query.py", line 1545, in add_q
    clause, _ = self._add_q(q_object, self.used_aliases)
  File "/home/farsana.ka/Documents/Bus Buddy/source_code/web/env/lib/python3.10/site-packages/django/db/models/sql/query.py", line 1576, in _add_q
    child_clause, needed_inner = self.build_filter(
  File "/home/farsana.ka/Documents/Bus Buddy/source_code/web/env/lib/python3.10/site-packages/django/db/models/sql/query.py", line 1491, in build_filter
    condition = self.build_lookup(lookups, col, value)
  File "/home/farsana.ka/Documents/Bus Buddy/source_code/web/env/lib/python3.10/site-packages/django/db/models/sql/query.py", line 1318, in build_lookup
    lookup = lookup_class(lhs, rhs)
  File "/home/farsana.ka/Documents/Bus Buddy/source_code/web/env/lib/python3.10/site-packages/django/db/models/lookups.py", line 27, in __init__
    self.rhs = self.get_prep_lookup()
  File "/home/farsana.ka/Documents/Bus Buddy/source_code/web/env/lib/python3.10/site-packages/django/db/models/lookups.py", line 341, in get_prep_lookup
    return super().get_prep_lookup()
  File "/home/farsana.ka/Documents/Bus Buddy/source_code/web/env/lib/python3.10/site-packages/django/db/models/lookups.py", line 85, in get_prep_lookup
    return self.lhs.output_field.get_prep_value(self.rhs)
  File "/home/farsana.ka/Documents/Bus Buddy/source_code/web/env/lib/python3.10/site-packages/django/db/models/fields/__init__.py", line 2055, in get_prep_value
    raise e.__class__(
ValueError: Field 'status' expected a number but got ''.

During handling of the above exception, another exception occurred:

Traceback (most recent call last):
  File "/home/farsana.ka/Documents/Bus Buddy/source_code/web/env/lib/python3.10/site-packages/django/core/handlers/exception.py", line 55, in inner
    response = get_response(request)
  File "/home/farsana.ka/Documents/Bus Buddy/source_code/web/env/lib/python3.10/site-packages/django/core/handlers/base.py", line 197, in _get_response
    response = wrapped_callback(request, *callback_args, **callback_kwargs)
  File "/home/farsana.ka/Documents/Bus Buddy/source_code/web/env/lib/python3.10/site-packages/django/views/decorators/csrf.py", line 56, in wrapper_view
    return view_func(*args, **kwargs)
  File "/home/farsana.ka/Documents/Bus Buddy/source_code/web/env/lib/python3.10/site-packages/django/views/generic/base.py", line 104, in view
    return self.dispatch(request, *args, **kwargs)
  File "/home/farsana.ka/Documents/Bus Buddy/source_code/web/env/lib/python3.10/site-packages/rest_framework/views.py", line 509, in dispatch
    response = self.handle_exception(exc)
  File "/home/farsana.ka/Documents/Bus Buddy/source_code/web/env/lib/python3.10/site-packages/rest_framework/views.py", line 469, in handle_exception
    self.raise_uncaught_exception(exc)
  File "/home/farsana.ka/Documents/Bus Buddy/source_code/web/env/lib/python3.10/site-packages/rest_framework/views.py", line 480, in raise_uncaught_exception
    raise exc
  File "/home/farsana.ka/Documents/Bus Buddy/source_code/web/env/lib/python3.10/site-packages/rest_framework/views.py", line 506, in dispatch
    response = handler(request, *args, **kwargs)
  File "/home/farsana.ka/Documents/Bus Buddy/source_code/web/env/lib/python3.10/site-packages/rest_framework/generics.py", line 199, in get
    return self.list(request, *args, **kwargs)
  File "/home/farsana.ka/Documents/Bus Buddy/source_code/web/bus_buddy_back_end/normal_user/views.py", line 172, in list
    return Response(serializer._errors)
UnboundLocalError: local variable 'serializer' referenced before assignment
django.request ERROR 2023-11-14 09:43:34,086 log 46881 139781170259520 Internal Server Error: /user/booking-history
Traceback (most recent call last):
  File "/home/farsana.ka/Documents/Bus Buddy/source_code/web/env/lib/python3.10/site-packages/django/db/models/fields/__init__.py", line 2053, in get_prep_value
    return int(value)
ValueError: invalid literal for int() with base 10: ''

The above exception was the direct cause of the following exception:

Traceback (most recent call last):
  File "/home/farsana.ka/Documents/Bus Buddy/source_code/web/bus_buddy_back_end/normal_user/views.py", line 160, in list
    queryset = Bookings.objects.filter(user=user_id,status=status)
  File "/home/farsana.ka/Documents/Bus Buddy/source_code/web/env/lib/python3.10/site-packages/django/db/models/manager.py", line 87, in manager_method
    return getattr(self.get_queryset(), name)(*args, **kwargs)
  File "/home/farsana.ka/Documents/Bus Buddy/source_code/web/env/lib/python3.10/site-packages/django/db/models/query.py", line 1436, in filter
    return self._filter_or_exclude(False, args, kwargs)
  File "/home/farsana.ka/Documents/Bus Buddy/source_code/web/env/lib/python3.10/site-packages/django/db/models/query.py", line 1454, in _filter_or_exclude
    clone._filter_or_exclude_inplace(negate, args, kwargs)
  File "/home/farsana.ka/Documents/Bus Buddy/source_code/web/env/lib/python3.10/site-packages/django/db/models/query.py", line 1461, in _filter_or_exclude_inplace
    self._query.add_q(Q(*args, **kwargs))
  File "/home/farsana.ka/Documents/Bus Buddy/source_code/web/env/lib/python3.10/site-packages/django/db/models/sql/query.py", line 1545, in add_q
    clause, _ = self._add_q(q_object, self.used_aliases)
  File "/home/farsana.ka/Documents/Bus Buddy/source_code/web/env/lib/python3.10/site-packages/django/db/models/sql/query.py", line 1576, in _add_q
    child_clause, needed_inner = self.build_filter(
  File "/home/farsana.ka/Documents/Bus Buddy/source_code/web/env/lib/python3.10/site-packages/django/db/models/sql/query.py", line 1491, in build_filter
    condition = self.build_lookup(lookups, col, value)
  File "/home/farsana.ka/Documents/Bus Buddy/source_code/web/env/lib/python3.10/site-packages/django/db/models/sql/query.py", line 1318, in build_lookup
    lookup = lookup_class(lhs, rhs)
  File "/home/farsana.ka/Documents/Bus Buddy/source_code/web/env/lib/python3.10/site-packages/django/db/models/lookups.py", line 27, in __init__
    self.rhs = self.get_prep_lookup()
  File "/home/farsana.ka/Documents/Bus Buddy/source_code/web/env/lib/python3.10/site-packages/django/db/models/lookups.py", line 341, in get_prep_lookup
    return super().get_prep_lookup()
  File "/home/farsana.ka/Documents/Bus Buddy/source_code/web/env/lib/python3.10/site-packages/django/db/models/lookups.py", line 85, in get_prep_lookup
    return self.lhs.output_field.get_prep_value(self.rhs)
  File "/home/farsana.ka/Documents/Bus Buddy/source_code/web/env/lib/python3.10/site-packages/django/db/models/fields/__init__.py", line 2055, in get_prep_value
    raise e.__class__(
ValueError: Field 'status' expected a number but got ''.

During handling of the above exception, another exception occurred:

Traceback (most recent call last):
  File "/home/farsana.ka/Documents/Bus Buddy/source_code/web/env/lib/python3.10/site-packages/django/core/handlers/exception.py", line 55, in inner
    response = get_response(request)
  File "/home/farsana.ka/Documents/Bus Buddy/source_code/web/env/lib/python3.10/site-packages/django/core/handlers/base.py", line 197, in _get_response
    response = wrapped_callback(request, *callback_args, **callback_kwargs)
  File "/home/farsana.ka/Documents/Bus Buddy/source_code/web/env/lib/python3.10/site-packages/django/views/decorators/csrf.py", line 56, in wrapper_view
    return view_func(*args, **kwargs)
  File "/home/farsana.ka/Documents/Bus Buddy/source_code/web/env/lib/python3.10/site-packages/django/views/generic/base.py", line 104, in view
    return self.dispatch(request, *args, **kwargs)
  File "/home/farsana.ka/Documents/Bus Buddy/source_code/web/env/lib/python3.10/site-packages/rest_framework/views.py", line 509, in dispatch
    response = self.handle_exception(exc)
  File "/home/farsana.ka/Documents/Bus Buddy/source_code/web/env/lib/python3.10/site-packages/rest_framework/views.py", line 469, in handle_exception
    self.raise_uncaught_exception(exc)
  File "/home/farsana.ka/Documents/Bus Buddy/source_code/web/env/lib/python3.10/site-packages/rest_framework/views.py", line 480, in raise_uncaught_exception
    raise exc
  File "/home/farsana.ka/Documents/Bus Buddy/source_code/web/env/lib/python3.10/site-packages/rest_framework/views.py", line 506, in dispatch
    response = handler(request, *args, **kwargs)
  File "/home/farsana.ka/Documents/Bus Buddy/source_code/web/env/lib/python3.10/site-packages/rest_framework/generics.py", line 199, in get
    return self.list(request, *args, **kwargs)
  File "/home/farsana.ka/Documents/Bus Buddy/source_code/web/bus_buddy_back_end/normal_user/views.py", line 172, in list
    return Response(serializer._errors)
UnboundLocalError: local variable 'serializer' referenced before assignment
django.request ERROR 2023-11-14 09:43:34,086 log 46881 139781170259520 Internal Server Error: /user/booking-history
Traceback (most recent call last):
  File "/home/farsana.ka/Documents/Bus Buddy/source_code/web/env/lib/python3.10/site-packages/django/db/models/fields/__init__.py", line 2053, in get_prep_value
    return int(value)
ValueError: invalid literal for int() with base 10: ''

The above exception was the direct cause of the following exception:

Traceback (most recent call last):
  File "/home/farsana.ka/Documents/Bus Buddy/source_code/web/bus_buddy_back_end/normal_user/views.py", line 160, in list
    queryset = Bookings.objects.filter(user=user_id,status=status)
  File "/home/farsana.ka/Documents/Bus Buddy/source_code/web/env/lib/python3.10/site-packages/django/db/models/manager.py", line 87, in manager_method
    return getattr(self.get_queryset(), name)(*args, **kwargs)
  File "/home/farsana.ka/Documents/Bus Buddy/source_code/web/env/lib/python3.10/site-packages/django/db/models/query.py", line 1436, in filter
    return self._filter_or_exclude(False, args, kwargs)
  File "/home/farsana.ka/Documents/Bus Buddy/source_code/web/env/lib/python3.10/site-packages/django/db/models/query.py", line 1454, in _filter_or_exclude
    clone._filter_or_exclude_inplace(negate, args, kwargs)
  File "/home/farsana.ka/Documents/Bus Buddy/source_code/web/env/lib/python3.10/site-packages/django/db/models/query.py", line 1461, in _filter_or_exclude_inplace
    self._query.add_q(Q(*args, **kwargs))
  File "/home/farsana.ka/Documents/Bus Buddy/source_code/web/env/lib/python3.10/site-packages/django/db/models/sql/query.py", line 1545, in add_q
    clause, _ = self._add_q(q_object, self.used_aliases)
  File "/home/farsana.ka/Documents/Bus Buddy/source_code/web/env/lib/python3.10/site-packages/django/db/models/sql/query.py", line 1576, in _add_q
    child_clause, needed_inner = self.build_filter(
  File "/home/farsana.ka/Documents/Bus Buddy/source_code/web/env/lib/python3.10/site-packages/django/db/models/sql/query.py", line 1491, in build_filter
    condition = self.build_lookup(lookups, col, value)
  File "/home/farsana.ka/Documents/Bus Buddy/source_code/web/env/lib/python3.10/site-packages/django/db/models/sql/query.py", line 1318, in build_lookup
    lookup = lookup_class(lhs, rhs)
  File "/home/farsana.ka/Documents/Bus Buddy/source_code/web/env/lib/python3.10/site-packages/django/db/models/lookups.py", line 27, in __init__
    self.rhs = self.get_prep_lookup()
  File "/home/farsana.ka/Documents/Bus Buddy/source_code/web/env/lib/python3.10/site-packages/django/db/models/lookups.py", line 341, in get_prep_lookup
    return super().get_prep_lookup()
  File "/home/farsana.ka/Documents/Bus Buddy/source_code/web/env/lib/python3.10/site-packages/django/db/models/lookups.py", line 85, in get_prep_lookup
    return self.lhs.output_field.get_prep_value(self.rhs)
  File "/home/farsana.ka/Documents/Bus Buddy/source_code/web/env/lib/python3.10/site-packages/django/db/models/fields/__init__.py", line 2055, in get_prep_value
    raise e.__class__(
ValueError: Field 'status' expected a number but got ''.

During handling of the above exception, another exception occurred:

Traceback (most recent call last):
  File "/home/farsana.ka/Documents/Bus Buddy/source_code/web/env/lib/python3.10/site-packages/django/core/handlers/exception.py", line 55, in inner
    response = get_response(request)
  File "/home/farsana.ka/Documents/Bus Buddy/source_code/web/env/lib/python3.10/site-packages/django/core/handlers/base.py", line 197, in _get_response
    response = wrapped_callback(request, *callback_args, **callback_kwargs)
  File "/home/farsana.ka/Documents/Bus Buddy/source_code/web/env/lib/python3.10/site-packages/django/views/decorators/csrf.py", line 56, in wrapper_view
    return view_func(*args, **kwargs)
  File "/home/farsana.ka/Documents/Bus Buddy/source_code/web/env/lib/python3.10/site-packages/django/views/generic/base.py", line 104, in view
    return self.dispatch(request, *args, **kwargs)
  File "/home/farsana.ka/Documents/Bus Buddy/source_code/web/env/lib/python3.10/site-packages/rest_framework/views.py", line 509, in dispatch
    response = self.handle_exception(exc)
  File "/home/farsana.ka/Documents/Bus Buddy/source_code/web/env/lib/python3.10/site-packages/rest_framework/views.py", line 469, in handle_exception
    self.raise_uncaught_exception(exc)
  File "/home/farsana.ka/Documents/Bus Buddy/source_code/web/env/lib/python3.10/site-packages/rest_framework/views.py", line 480, in raise_uncaught_exception
    raise exc
  File "/home/farsana.ka/Documents/Bus Buddy/source_code/web/env/lib/python3.10/site-packages/rest_framework/views.py", line 506, in dispatch
    response = handler(request, *args, **kwargs)
  File "/home/farsana.ka/Documents/Bus Buddy/source_code/web/env/lib/python3.10/site-packages/rest_framework/generics.py", line 199, in get
    return self.list(request, *args, **kwargs)
  File "/home/farsana.ka/Documents/Bus Buddy/source_code/web/bus_buddy_back_end/normal_user/views.py", line 172, in list
    return Response(serializer._errors)
UnboundLocalError: local variable 'serializer' referenced before assignment
django.request ERROR 2023-11-14 09:43:38,486 log 46881 139781170259520 Internal Server Error: /user/booking-history
Traceback (most recent call last):
  File "/home/farsana.ka/Documents/Bus Buddy/source_code/web/env/lib/python3.10/site-packages/django/db/models/fields/__init__.py", line 2053, in get_prep_value
    return int(value)
ValueError: invalid literal for int() with base 10: ''

The above exception was the direct cause of the following exception:

Traceback (most recent call last):
  File "/home/farsana.ka/Documents/Bus Buddy/source_code/web/bus_buddy_back_end/normal_user/views.py", line 160, in list
    queryset = Bookings.objects.filter(user=user_id,status=status)
  File "/home/farsana.ka/Documents/Bus Buddy/source_code/web/env/lib/python3.10/site-packages/django/db/models/manager.py", line 87, in manager_method
    return getattr(self.get_queryset(), name)(*args, **kwargs)
  File "/home/farsana.ka/Documents/Bus Buddy/source_code/web/env/lib/python3.10/site-packages/django/db/models/query.py", line 1436, in filter
    return self._filter_or_exclude(False, args, kwargs)
  File "/home/farsana.ka/Documents/Bus Buddy/source_code/web/env/lib/python3.10/site-packages/django/db/models/query.py", line 1454, in _filter_or_exclude
    clone._filter_or_exclude_inplace(negate, args, kwargs)
  File "/home/farsana.ka/Documents/Bus Buddy/source_code/web/env/lib/python3.10/site-packages/django/db/models/query.py", line 1461, in _filter_or_exclude_inplace
    self._query.add_q(Q(*args, **kwargs))
  File "/home/farsana.ka/Documents/Bus Buddy/source_code/web/env/lib/python3.10/site-packages/django/db/models/sql/query.py", line 1545, in add_q
    clause, _ = self._add_q(q_object, self.used_aliases)
  File "/home/farsana.ka/Documents/Bus Buddy/source_code/web/env/lib/python3.10/site-packages/django/db/models/sql/query.py", line 1576, in _add_q
    child_clause, needed_inner = self.build_filter(
  File "/home/farsana.ka/Documents/Bus Buddy/source_code/web/env/lib/python3.10/site-packages/django/db/models/sql/query.py", line 1491, in build_filter
    condition = self.build_lookup(lookups, col, value)
  File "/home/farsana.ka/Documents/Bus Buddy/source_code/web/env/lib/python3.10/site-packages/django/db/models/sql/query.py", line 1318, in build_lookup
    lookup = lookup_class(lhs, rhs)
  File "/home/farsana.ka/Documents/Bus Buddy/source_code/web/env/lib/python3.10/site-packages/django/db/models/lookups.py", line 27, in __init__
    self.rhs = self.get_prep_lookup()
  File "/home/farsana.ka/Documents/Bus Buddy/source_code/web/env/lib/python3.10/site-packages/django/db/models/lookups.py", line 341, in get_prep_lookup
    return super().get_prep_lookup()
  File "/home/farsana.ka/Documents/Bus Buddy/source_code/web/env/lib/python3.10/site-packages/django/db/models/lookups.py", line 85, in get_prep_lookup
    return self.lhs.output_field.get_prep_value(self.rhs)
  File "/home/farsana.ka/Documents/Bus Buddy/source_code/web/env/lib/python3.10/site-packages/django/db/models/fields/__init__.py", line 2055, in get_prep_value
    raise e.__class__(
ValueError: Field 'status' expected a number but got ''.

During handling of the above exception, another exception occurred:

Traceback (most recent call last):
  File "/home/farsana.ka/Documents/Bus Buddy/source_code/web/env/lib/python3.10/site-packages/django/core/handlers/exception.py", line 55, in inner
    response = get_response(request)
  File "/home/farsana.ka/Documents/Bus Buddy/source_code/web/env/lib/python3.10/site-packages/django/core/handlers/base.py", line 197, in _get_response
    response = wrapped_callback(request, *callback_args, **callback_kwargs)
  File "/home/farsana.ka/Documents/Bus Buddy/source_code/web/env/lib/python3.10/site-packages/django/views/decorators/csrf.py", line 56, in wrapper_view
    return view_func(*args, **kwargs)
  File "/home/farsana.ka/Documents/Bus Buddy/source_code/web/env/lib/python3.10/site-packages/django/views/generic/base.py", line 104, in view
    return self.dispatch(request, *args, **kwargs)
  File "/home/farsana.ka/Documents/Bus Buddy/source_code/web/env/lib/python3.10/site-packages/rest_framework/views.py", line 509, in dispatch
    response = self.handle_exception(exc)
  File "/home/farsana.ka/Documents/Bus Buddy/source_code/web/env/lib/python3.10/site-packages/rest_framework/views.py", line 469, in handle_exception
    self.raise_uncaught_exception(exc)
  File "/home/farsana.ka/Documents/Bus Buddy/source_code/web/env/lib/python3.10/site-packages/rest_framework/views.py", line 480, in raise_uncaught_exception
    raise exc
  File "/home/farsana.ka/Documents/Bus Buddy/source_code/web/env/lib/python3.10/site-packages/rest_framework/views.py", line 506, in dispatch
    response = handler(request, *args, **kwargs)
  File "/home/farsana.ka/Documents/Bus Buddy/source_code/web/env/lib/python3.10/site-packages/rest_framework/generics.py", line 199, in get
    return self.list(request, *args, **kwargs)
  File "/home/farsana.ka/Documents/Bus Buddy/source_code/web/bus_buddy_back_end/normal_user/views.py", line 172, in list
    return Response(serializer._errors)
UnboundLocalError: local variable 'serializer' referenced before assignment
django.request ERROR 2023-11-14 09:43:38,486 log 46881 139781170259520 Internal Server Error: /user/booking-history
Traceback (most recent call last):
  File "/home/farsana.ka/Documents/Bus Buddy/source_code/web/env/lib/python3.10/site-packages/django/db/models/fields/__init__.py", line 2053, in get_prep_value
    return int(value)
ValueError: invalid literal for int() with base 10: ''

The above exception was the direct cause of the following exception:

Traceback (most recent call last):
  File "/home/farsana.ka/Documents/Bus Buddy/source_code/web/bus_buddy_back_end/normal_user/views.py", line 160, in list
    queryset = Bookings.objects.filter(user=user_id,status=status)
  File "/home/farsana.ka/Documents/Bus Buddy/source_code/web/env/lib/python3.10/site-packages/django/db/models/manager.py", line 87, in manager_method
    return getattr(self.get_queryset(), name)(*args, **kwargs)
  File "/home/farsana.ka/Documents/Bus Buddy/source_code/web/env/lib/python3.10/site-packages/django/db/models/query.py", line 1436, in filter
    return self._filter_or_exclude(False, args, kwargs)
  File "/home/farsana.ka/Documents/Bus Buddy/source_code/web/env/lib/python3.10/site-packages/django/db/models/query.py", line 1454, in _filter_or_exclude
    clone._filter_or_exclude_inplace(negate, args, kwargs)
  File "/home/farsana.ka/Documents/Bus Buddy/source_code/web/env/lib/python3.10/site-packages/django/db/models/query.py", line 1461, in _filter_or_exclude_inplace
    self._query.add_q(Q(*args, **kwargs))
  File "/home/farsana.ka/Documents/Bus Buddy/source_code/web/env/lib/python3.10/site-packages/django/db/models/sql/query.py", line 1545, in add_q
    clause, _ = self._add_q(q_object, self.used_aliases)
  File "/home/farsana.ka/Documents/Bus Buddy/source_code/web/env/lib/python3.10/site-packages/django/db/models/sql/query.py", line 1576, in _add_q
    child_clause, needed_inner = self.build_filter(
  File "/home/farsana.ka/Documents/Bus Buddy/source_code/web/env/lib/python3.10/site-packages/django/db/models/sql/query.py", line 1491, in build_filter
    condition = self.build_lookup(lookups, col, value)
  File "/home/farsana.ka/Documents/Bus Buddy/source_code/web/env/lib/python3.10/site-packages/django/db/models/sql/query.py", line 1318, in build_lookup
    lookup = lookup_class(lhs, rhs)
  File "/home/farsana.ka/Documents/Bus Buddy/source_code/web/env/lib/python3.10/site-packages/django/db/models/lookups.py", line 27, in __init__
    self.rhs = self.get_prep_lookup()
  File "/home/farsana.ka/Documents/Bus Buddy/source_code/web/env/lib/python3.10/site-packages/django/db/models/lookups.py", line 341, in get_prep_lookup
    return super().get_prep_lookup()
  File "/home/farsana.ka/Documents/Bus Buddy/source_code/web/env/lib/python3.10/site-packages/django/db/models/lookups.py", line 85, in get_prep_lookup
    return self.lhs.output_field.get_prep_value(self.rhs)
  File "/home/farsana.ka/Documents/Bus Buddy/source_code/web/env/lib/python3.10/site-packages/django/db/models/fields/__init__.py", line 2055, in get_prep_value
    raise e.__class__(
ValueError: Field 'status' expected a number but got ''.

During handling of the above exception, another exception occurred:

Traceback (most recent call last):
  File "/home/farsana.ka/Documents/Bus Buddy/source_code/web/env/lib/python3.10/site-packages/django/core/handlers/exception.py", line 55, in inner
    response = get_response(request)
  File "/home/farsana.ka/Documents/Bus Buddy/source_code/web/env/lib/python3.10/site-packages/django/core/handlers/base.py", line 197, in _get_response
    response = wrapped_callback(request, *callback_args, **callback_kwargs)
  File "/home/farsana.ka/Documents/Bus Buddy/source_code/web/env/lib/python3.10/site-packages/django/views/decorators/csrf.py", line 56, in wrapper_view
    return view_func(*args, **kwargs)
  File "/home/farsana.ka/Documents/Bus Buddy/source_code/web/env/lib/python3.10/site-packages/django/views/generic/base.py", line 104, in view
    return self.dispatch(request, *args, **kwargs)
  File "/home/farsana.ka/Documents/Bus Buddy/source_code/web/env/lib/python3.10/site-packages/rest_framework/views.py", line 509, in dispatch
    response = self.handle_exception(exc)
  File "/home/farsana.ka/Documents/Bus Buddy/source_code/web/env/lib/python3.10/site-packages/rest_framework/views.py", line 469, in handle_exception
    self.raise_uncaught_exception(exc)
  File "/home/farsana.ka/Documents/Bus Buddy/source_code/web/env/lib/python3.10/site-packages/rest_framework/views.py", line 480, in raise_uncaught_exception
    raise exc
  File "/home/farsana.ka/Documents/Bus Buddy/source_code/web/env/lib/python3.10/site-packages/rest_framework/views.py", line 506, in dispatch
    response = handler(request, *args, **kwargs)
  File "/home/farsana.ka/Documents/Bus Buddy/source_code/web/env/lib/python3.10/site-packages/rest_framework/generics.py", line 199, in get
    return self.list(request, *args, **kwargs)
  File "/home/farsana.ka/Documents/Bus Buddy/source_code/web/bus_buddy_back_end/normal_user/views.py", line 172, in list
    return Response(serializer._errors)
UnboundLocalError: local variable 'serializer' referenced before assignment
django.request ERROR 2023-11-14 09:43:57,616 log 46881 139781170259520 Internal Server Error: /user/booking-history
Traceback (most recent call last):
  File "/home/farsana.ka/Documents/Bus Buddy/source_code/web/env/lib/python3.10/site-packages/django/db/models/fields/__init__.py", line 2053, in get_prep_value
    return int(value)
ValueError: invalid literal for int() with base 10: 'undefined'

The above exception was the direct cause of the following exception:

Traceback (most recent call last):
  File "/home/farsana.ka/Documents/Bus Buddy/source_code/web/bus_buddy_back_end/normal_user/views.py", line 160, in list
    queryset = Bookings.objects.filter(user=user_id,status=status)
  File "/home/farsana.ka/Documents/Bus Buddy/source_code/web/env/lib/python3.10/site-packages/django/db/models/manager.py", line 87, in manager_method
    return getattr(self.get_queryset(), name)(*args, **kwargs)
  File "/home/farsana.ka/Documents/Bus Buddy/source_code/web/env/lib/python3.10/site-packages/django/db/models/query.py", line 1436, in filter
    return self._filter_or_exclude(False, args, kwargs)
  File "/home/farsana.ka/Documents/Bus Buddy/source_code/web/env/lib/python3.10/site-packages/django/db/models/query.py", line 1454, in _filter_or_exclude
    clone._filter_or_exclude_inplace(negate, args, kwargs)
  File "/home/farsana.ka/Documents/Bus Buddy/source_code/web/env/lib/python3.10/site-packages/django/db/models/query.py", line 1461, in _filter_or_exclude_inplace
    self._query.add_q(Q(*args, **kwargs))
  File "/home/farsana.ka/Documents/Bus Buddy/source_code/web/env/lib/python3.10/site-packages/django/db/models/sql/query.py", line 1545, in add_q
    clause, _ = self._add_q(q_object, self.used_aliases)
  File "/home/farsana.ka/Documents/Bus Buddy/source_code/web/env/lib/python3.10/site-packages/django/db/models/sql/query.py", line 1576, in _add_q
    child_clause, needed_inner = self.build_filter(
  File "/home/farsana.ka/Documents/Bus Buddy/source_code/web/env/lib/python3.10/site-packages/django/db/models/sql/query.py", line 1491, in build_filter
    condition = self.build_lookup(lookups, col, value)
  File "/home/farsana.ka/Documents/Bus Buddy/source_code/web/env/lib/python3.10/site-packages/django/db/models/sql/query.py", line 1318, in build_lookup
    lookup = lookup_class(lhs, rhs)
  File "/home/farsana.ka/Documents/Bus Buddy/source_code/web/env/lib/python3.10/site-packages/django/db/models/lookups.py", line 27, in __init__
    self.rhs = self.get_prep_lookup()
  File "/home/farsana.ka/Documents/Bus Buddy/source_code/web/env/lib/python3.10/site-packages/django/db/models/lookups.py", line 341, in get_prep_lookup
    return super().get_prep_lookup()
  File "/home/farsana.ka/Documents/Bus Buddy/source_code/web/env/lib/python3.10/site-packages/django/db/models/lookups.py", line 85, in get_prep_lookup
    return self.lhs.output_field.get_prep_value(self.rhs)
  File "/home/farsana.ka/Documents/Bus Buddy/source_code/web/env/lib/python3.10/site-packages/django/db/models/fields/__init__.py", line 2055, in get_prep_value
    raise e.__class__(
ValueError: Field 'status' expected a number but got 'undefined'.

During handling of the above exception, another exception occurred:

Traceback (most recent call last):
  File "/home/farsana.ka/Documents/Bus Buddy/source_code/web/env/lib/python3.10/site-packages/django/core/handlers/exception.py", line 55, in inner
    response = get_response(request)
  File "/home/farsana.ka/Documents/Bus Buddy/source_code/web/env/lib/python3.10/site-packages/django/core/handlers/base.py", line 197, in _get_response
    response = wrapped_callback(request, *callback_args, **callback_kwargs)
  File "/home/farsana.ka/Documents/Bus Buddy/source_code/web/env/lib/python3.10/site-packages/django/views/decorators/csrf.py", line 56, in wrapper_view
    return view_func(*args, **kwargs)
  File "/home/farsana.ka/Documents/Bus Buddy/source_code/web/env/lib/python3.10/site-packages/django/views/generic/base.py", line 104, in view
    return self.dispatch(request, *args, **kwargs)
  File "/home/farsana.ka/Documents/Bus Buddy/source_code/web/env/lib/python3.10/site-packages/rest_framework/views.py", line 509, in dispatch
    response = self.handle_exception(exc)
  File "/home/farsana.ka/Documents/Bus Buddy/source_code/web/env/lib/python3.10/site-packages/rest_framework/views.py", line 469, in handle_exception
    self.raise_uncaught_exception(exc)
  File "/home/farsana.ka/Documents/Bus Buddy/source_code/web/env/lib/python3.10/site-packages/rest_framework/views.py", line 480, in raise_uncaught_exception
    raise exc
  File "/home/farsana.ka/Documents/Bus Buddy/source_code/web/env/lib/python3.10/site-packages/rest_framework/views.py", line 506, in dispatch
    response = handler(request, *args, **kwargs)
  File "/home/farsana.ka/Documents/Bus Buddy/source_code/web/env/lib/python3.10/site-packages/rest_framework/generics.py", line 199, in get
    return self.list(request, *args, **kwargs)
  File "/home/farsana.ka/Documents/Bus Buddy/source_code/web/bus_buddy_back_end/normal_user/views.py", line 172, in list
    return Response(serializer._errors)
UnboundLocalError: local variable 'serializer' referenced before assignment
django.request ERROR 2023-11-14 09:43:57,616 log 46881 139781170259520 Internal Server Error: /user/booking-history
Traceback (most recent call last):
  File "/home/farsana.ka/Documents/Bus Buddy/source_code/web/env/lib/python3.10/site-packages/django/db/models/fields/__init__.py", line 2053, in get_prep_value
    return int(value)
ValueError: invalid literal for int() with base 10: 'undefined'

The above exception was the direct cause of the following exception:

Traceback (most recent call last):
  File "/home/farsana.ka/Documents/Bus Buddy/source_code/web/bus_buddy_back_end/normal_user/views.py", line 160, in list
    queryset = Bookings.objects.filter(user=user_id,status=status)
  File "/home/farsana.ka/Documents/Bus Buddy/source_code/web/env/lib/python3.10/site-packages/django/db/models/manager.py", line 87, in manager_method
    return getattr(self.get_queryset(), name)(*args, **kwargs)
  File "/home/farsana.ka/Documents/Bus Buddy/source_code/web/env/lib/python3.10/site-packages/django/db/models/query.py", line 1436, in filter
    return self._filter_or_exclude(False, args, kwargs)
  File "/home/farsana.ka/Documents/Bus Buddy/source_code/web/env/lib/python3.10/site-packages/django/db/models/query.py", line 1454, in _filter_or_exclude
    clone._filter_or_exclude_inplace(negate, args, kwargs)
  File "/home/farsana.ka/Documents/Bus Buddy/source_code/web/env/lib/python3.10/site-packages/django/db/models/query.py", line 1461, in _filter_or_exclude_inplace
    self._query.add_q(Q(*args, **kwargs))
  File "/home/farsana.ka/Documents/Bus Buddy/source_code/web/env/lib/python3.10/site-packages/django/db/models/sql/query.py", line 1545, in add_q
    clause, _ = self._add_q(q_object, self.used_aliases)
  File "/home/farsana.ka/Documents/Bus Buddy/source_code/web/env/lib/python3.10/site-packages/django/db/models/sql/query.py", line 1576, in _add_q
    child_clause, needed_inner = self.build_filter(
  File "/home/farsana.ka/Documents/Bus Buddy/source_code/web/env/lib/python3.10/site-packages/django/db/models/sql/query.py", line 1491, in build_filter
    condition = self.build_lookup(lookups, col, value)
  File "/home/farsana.ka/Documents/Bus Buddy/source_code/web/env/lib/python3.10/site-packages/django/db/models/sql/query.py", line 1318, in build_lookup
    lookup = lookup_class(lhs, rhs)
  File "/home/farsana.ka/Documents/Bus Buddy/source_code/web/env/lib/python3.10/site-packages/django/db/models/lookups.py", line 27, in __init__
    self.rhs = self.get_prep_lookup()
  File "/home/farsana.ka/Documents/Bus Buddy/source_code/web/env/lib/python3.10/site-packages/django/db/models/lookups.py", line 341, in get_prep_lookup
    return super().get_prep_lookup()
  File "/home/farsana.ka/Documents/Bus Buddy/source_code/web/env/lib/python3.10/site-packages/django/db/models/lookups.py", line 85, in get_prep_lookup
    return self.lhs.output_field.get_prep_value(self.rhs)
  File "/home/farsana.ka/Documents/Bus Buddy/source_code/web/env/lib/python3.10/site-packages/django/db/models/fields/__init__.py", line 2055, in get_prep_value
    raise e.__class__(
ValueError: Field 'status' expected a number but got 'undefined'.

During handling of the above exception, another exception occurred:

Traceback (most recent call last):
  File "/home/farsana.ka/Documents/Bus Buddy/source_code/web/env/lib/python3.10/site-packages/django/core/handlers/exception.py", line 55, in inner
    response = get_response(request)
  File "/home/farsana.ka/Documents/Bus Buddy/source_code/web/env/lib/python3.10/site-packages/django/core/handlers/base.py", line 197, in _get_response
    response = wrapped_callback(request, *callback_args, **callback_kwargs)
  File "/home/farsana.ka/Documents/Bus Buddy/source_code/web/env/lib/python3.10/site-packages/django/views/decorators/csrf.py", line 56, in wrapper_view
    return view_func(*args, **kwargs)
  File "/home/farsana.ka/Documents/Bus Buddy/source_code/web/env/lib/python3.10/site-packages/django/views/generic/base.py", line 104, in view
    return self.dispatch(request, *args, **kwargs)
  File "/home/farsana.ka/Documents/Bus Buddy/source_code/web/env/lib/python3.10/site-packages/rest_framework/views.py", line 509, in dispatch
    response = self.handle_exception(exc)
  File "/home/farsana.ka/Documents/Bus Buddy/source_code/web/env/lib/python3.10/site-packages/rest_framework/views.py", line 469, in handle_exception
    self.raise_uncaught_exception(exc)
  File "/home/farsana.ka/Documents/Bus Buddy/source_code/web/env/lib/python3.10/site-packages/rest_framework/views.py", line 480, in raise_uncaught_exception
    raise exc
  File "/home/farsana.ka/Documents/Bus Buddy/source_code/web/env/lib/python3.10/site-packages/rest_framework/views.py", line 506, in dispatch
    response = handler(request, *args, **kwargs)
  File "/home/farsana.ka/Documents/Bus Buddy/source_code/web/env/lib/python3.10/site-packages/rest_framework/generics.py", line 199, in get
    return self.list(request, *args, **kwargs)
  File "/home/farsana.ka/Documents/Bus Buddy/source_code/web/bus_buddy_back_end/normal_user/views.py", line 172, in list
    return Response(serializer._errors)
UnboundLocalError: local variable 'serializer' referenced before assignment
django.request ERROR 2023-11-14 09:43:58,089 log 46881 139781170259520 Internal Server Error: /user/booking-history
Traceback (most recent call last):
  File "/home/farsana.ka/Documents/Bus Buddy/source_code/web/env/lib/python3.10/site-packages/django/db/models/fields/__init__.py", line 2053, in get_prep_value
    return int(value)
ValueError: invalid literal for int() with base 10: 'undefined'

The above exception was the direct cause of the following exception:

Traceback (most recent call last):
  File "/home/farsana.ka/Documents/Bus Buddy/source_code/web/bus_buddy_back_end/normal_user/views.py", line 160, in list
    queryset = Bookings.objects.filter(user=user_id,status=status)
  File "/home/farsana.ka/Documents/Bus Buddy/source_code/web/env/lib/python3.10/site-packages/django/db/models/manager.py", line 87, in manager_method
    return getattr(self.get_queryset(), name)(*args, **kwargs)
  File "/home/farsana.ka/Documents/Bus Buddy/source_code/web/env/lib/python3.10/site-packages/django/db/models/query.py", line 1436, in filter
    return self._filter_or_exclude(False, args, kwargs)
  File "/home/farsana.ka/Documents/Bus Buddy/source_code/web/env/lib/python3.10/site-packages/django/db/models/query.py", line 1454, in _filter_or_exclude
    clone._filter_or_exclude_inplace(negate, args, kwargs)
  File "/home/farsana.ka/Documents/Bus Buddy/source_code/web/env/lib/python3.10/site-packages/django/db/models/query.py", line 1461, in _filter_or_exclude_inplace
    self._query.add_q(Q(*args, **kwargs))
  File "/home/farsana.ka/Documents/Bus Buddy/source_code/web/env/lib/python3.10/site-packages/django/db/models/sql/query.py", line 1545, in add_q
    clause, _ = self._add_q(q_object, self.used_aliases)
  File "/home/farsana.ka/Documents/Bus Buddy/source_code/web/env/lib/python3.10/site-packages/django/db/models/sql/query.py", line 1576, in _add_q
    child_clause, needed_inner = self.build_filter(
  File "/home/farsana.ka/Documents/Bus Buddy/source_code/web/env/lib/python3.10/site-packages/django/db/models/sql/query.py", line 1491, in build_filter
    condition = self.build_lookup(lookups, col, value)
  File "/home/farsana.ka/Documents/Bus Buddy/source_code/web/env/lib/python3.10/site-packages/django/db/models/sql/query.py", line 1318, in build_lookup
    lookup = lookup_class(lhs, rhs)
  File "/home/farsana.ka/Documents/Bus Buddy/source_code/web/env/lib/python3.10/site-packages/django/db/models/lookups.py", line 27, in __init__
    self.rhs = self.get_prep_lookup()
  File "/home/farsana.ka/Documents/Bus Buddy/source_code/web/env/lib/python3.10/site-packages/django/db/models/lookups.py", line 341, in get_prep_lookup
    return super().get_prep_lookup()
  File "/home/farsana.ka/Documents/Bus Buddy/source_code/web/env/lib/python3.10/site-packages/django/db/models/lookups.py", line 85, in get_prep_lookup
    return self.lhs.output_field.get_prep_value(self.rhs)
  File "/home/farsana.ka/Documents/Bus Buddy/source_code/web/env/lib/python3.10/site-packages/django/db/models/fields/__init__.py", line 2055, in get_prep_value
    raise e.__class__(
ValueError: Field 'status' expected a number but got 'undefined'.

During handling of the above exception, another exception occurred:

Traceback (most recent call last):
  File "/home/farsana.ka/Documents/Bus Buddy/source_code/web/env/lib/python3.10/site-packages/django/core/handlers/exception.py", line 55, in inner
    response = get_response(request)
  File "/home/farsana.ka/Documents/Bus Buddy/source_code/web/env/lib/python3.10/site-packages/django/core/handlers/base.py", line 197, in _get_response
    response = wrapped_callback(request, *callback_args, **callback_kwargs)
  File "/home/farsana.ka/Documents/Bus Buddy/source_code/web/env/lib/python3.10/site-packages/django/views/decorators/csrf.py", line 56, in wrapper_view
    return view_func(*args, **kwargs)
  File "/home/farsana.ka/Documents/Bus Buddy/source_code/web/env/lib/python3.10/site-packages/django/views/generic/base.py", line 104, in view
    return self.dispatch(request, *args, **kwargs)
  File "/home/farsana.ka/Documents/Bus Buddy/source_code/web/env/lib/python3.10/site-packages/rest_framework/views.py", line 509, in dispatch
    response = self.handle_exception(exc)
  File "/home/farsana.ka/Documents/Bus Buddy/source_code/web/env/lib/python3.10/site-packages/rest_framework/views.py", line 469, in handle_exception
    self.raise_uncaught_exception(exc)
  File "/home/farsana.ka/Documents/Bus Buddy/source_code/web/env/lib/python3.10/site-packages/rest_framework/views.py", line 480, in raise_uncaught_exception
    raise exc
  File "/home/farsana.ka/Documents/Bus Buddy/source_code/web/env/lib/python3.10/site-packages/rest_framework/views.py", line 506, in dispatch
    response = handler(request, *args, **kwargs)
  File "/home/farsana.ka/Documents/Bus Buddy/source_code/web/env/lib/python3.10/site-packages/rest_framework/generics.py", line 199, in get
    return self.list(request, *args, **kwargs)
  File "/home/farsana.ka/Documents/Bus Buddy/source_code/web/bus_buddy_back_end/normal_user/views.py", line 172, in list
    return Response(serializer._errors)
UnboundLocalError: local variable 'serializer' referenced before assignment
django.request ERROR 2023-11-14 09:43:58,089 log 46881 139781170259520 Internal Server Error: /user/booking-history
Traceback (most recent call last):
  File "/home/farsana.ka/Documents/Bus Buddy/source_code/web/env/lib/python3.10/site-packages/django/db/models/fields/__init__.py", line 2053, in get_prep_value
    return int(value)
ValueError: invalid literal for int() with base 10: 'undefined'

The above exception was the direct cause of the following exception:

Traceback (most recent call last):
  File "/home/farsana.ka/Documents/Bus Buddy/source_code/web/bus_buddy_back_end/normal_user/views.py", line 160, in list
    queryset = Bookings.objects.filter(user=user_id,status=status)
  File "/home/farsana.ka/Documents/Bus Buddy/source_code/web/env/lib/python3.10/site-packages/django/db/models/manager.py", line 87, in manager_method
    return getattr(self.get_queryset(), name)(*args, **kwargs)
  File "/home/farsana.ka/Documents/Bus Buddy/source_code/web/env/lib/python3.10/site-packages/django/db/models/query.py", line 1436, in filter
    return self._filter_or_exclude(False, args, kwargs)
  File "/home/farsana.ka/Documents/Bus Buddy/source_code/web/env/lib/python3.10/site-packages/django/db/models/query.py", line 1454, in _filter_or_exclude
    clone._filter_or_exclude_inplace(negate, args, kwargs)
  File "/home/farsana.ka/Documents/Bus Buddy/source_code/web/env/lib/python3.10/site-packages/django/db/models/query.py", line 1461, in _filter_or_exclude_inplace
    self._query.add_q(Q(*args, **kwargs))
  File "/home/farsana.ka/Documents/Bus Buddy/source_code/web/env/lib/python3.10/site-packages/django/db/models/sql/query.py", line 1545, in add_q
    clause, _ = self._add_q(q_object, self.used_aliases)
  File "/home/farsana.ka/Documents/Bus Buddy/source_code/web/env/lib/python3.10/site-packages/django/db/models/sql/query.py", line 1576, in _add_q
    child_clause, needed_inner = self.build_filter(
  File "/home/farsana.ka/Documents/Bus Buddy/source_code/web/env/lib/python3.10/site-packages/django/db/models/sql/query.py", line 1491, in build_filter
    condition = self.build_lookup(lookups, col, value)
  File "/home/farsana.ka/Documents/Bus Buddy/source_code/web/env/lib/python3.10/site-packages/django/db/models/sql/query.py", line 1318, in build_lookup
    lookup = lookup_class(lhs, rhs)
  File "/home/farsana.ka/Documents/Bus Buddy/source_code/web/env/lib/python3.10/site-packages/django/db/models/lookups.py", line 27, in __init__
    self.rhs = self.get_prep_lookup()
  File "/home/farsana.ka/Documents/Bus Buddy/source_code/web/env/lib/python3.10/site-packages/django/db/models/lookups.py", line 341, in get_prep_lookup
    return super().get_prep_lookup()
  File "/home/farsana.ka/Documents/Bus Buddy/source_code/web/env/lib/python3.10/site-packages/django/db/models/lookups.py", line 85, in get_prep_lookup
    return self.lhs.output_field.get_prep_value(self.rhs)
  File "/home/farsana.ka/Documents/Bus Buddy/source_code/web/env/lib/python3.10/site-packages/django/db/models/fields/__init__.py", line 2055, in get_prep_value
    raise e.__class__(
ValueError: Field 'status' expected a number but got 'undefined'.

During handling of the above exception, another exception occurred:

Traceback (most recent call last):
  File "/home/farsana.ka/Documents/Bus Buddy/source_code/web/env/lib/python3.10/site-packages/django/core/handlers/exception.py", line 55, in inner
    response = get_response(request)
  File "/home/farsana.ka/Documents/Bus Buddy/source_code/web/env/lib/python3.10/site-packages/django/core/handlers/base.py", line 197, in _get_response
    response = wrapped_callback(request, *callback_args, **callback_kwargs)
  File "/home/farsana.ka/Documents/Bus Buddy/source_code/web/env/lib/python3.10/site-packages/django/views/decorators/csrf.py", line 56, in wrapper_view
    return view_func(*args, **kwargs)
  File "/home/farsana.ka/Documents/Bus Buddy/source_code/web/env/lib/python3.10/site-packages/django/views/generic/base.py", line 104, in view
    return self.dispatch(request, *args, **kwargs)
  File "/home/farsana.ka/Documents/Bus Buddy/source_code/web/env/lib/python3.10/site-packages/rest_framework/views.py", line 509, in dispatch
    response = self.handle_exception(exc)
  File "/home/farsana.ka/Documents/Bus Buddy/source_code/web/env/lib/python3.10/site-packages/rest_framework/views.py", line 469, in handle_exception
    self.raise_uncaught_exception(exc)
  File "/home/farsana.ka/Documents/Bus Buddy/source_code/web/env/lib/python3.10/site-packages/rest_framework/views.py", line 480, in raise_uncaught_exception
    raise exc
  File "/home/farsana.ka/Documents/Bus Buddy/source_code/web/env/lib/python3.10/site-packages/rest_framework/views.py", line 506, in dispatch
    response = handler(request, *args, **kwargs)
  File "/home/farsana.ka/Documents/Bus Buddy/source_code/web/env/lib/python3.10/site-packages/rest_framework/generics.py", line 199, in get
    return self.list(request, *args, **kwargs)
  File "/home/farsana.ka/Documents/Bus Buddy/source_code/web/bus_buddy_back_end/normal_user/views.py", line 172, in list
    return Response(serializer._errors)
UnboundLocalError: local variable 'serializer' referenced before assignment
django.request ERROR 2023-11-14 09:44:24,624 log 46881 139781170259520 Internal Server Error: /user/booking-history
Traceback (most recent call last):
  File "/home/farsana.ka/Documents/Bus Buddy/source_code/web/env/lib/python3.10/site-packages/django/db/models/fields/__init__.py", line 2053, in get_prep_value
    return int(value)
ValueError: invalid literal for int() with base 10: 'undefined'

The above exception was the direct cause of the following exception:

Traceback (most recent call last):
  File "/home/farsana.ka/Documents/Bus Buddy/source_code/web/bus_buddy_back_end/normal_user/views.py", line 160, in list
    queryset = Bookings.objects.filter(user=user_id,status=status)
  File "/home/farsana.ka/Documents/Bus Buddy/source_code/web/env/lib/python3.10/site-packages/django/db/models/manager.py", line 87, in manager_method
    return getattr(self.get_queryset(), name)(*args, **kwargs)
  File "/home/farsana.ka/Documents/Bus Buddy/source_code/web/env/lib/python3.10/site-packages/django/db/models/query.py", line 1436, in filter
    return self._filter_or_exclude(False, args, kwargs)
  File "/home/farsana.ka/Documents/Bus Buddy/source_code/web/env/lib/python3.10/site-packages/django/db/models/query.py", line 1454, in _filter_or_exclude
    clone._filter_or_exclude_inplace(negate, args, kwargs)
  File "/home/farsana.ka/Documents/Bus Buddy/source_code/web/env/lib/python3.10/site-packages/django/db/models/query.py", line 1461, in _filter_or_exclude_inplace
    self._query.add_q(Q(*args, **kwargs))
  File "/home/farsana.ka/Documents/Bus Buddy/source_code/web/env/lib/python3.10/site-packages/django/db/models/sql/query.py", line 1545, in add_q
    clause, _ = self._add_q(q_object, self.used_aliases)
  File "/home/farsana.ka/Documents/Bus Buddy/source_code/web/env/lib/python3.10/site-packages/django/db/models/sql/query.py", line 1576, in _add_q
    child_clause, needed_inner = self.build_filter(
  File "/home/farsana.ka/Documents/Bus Buddy/source_code/web/env/lib/python3.10/site-packages/django/db/models/sql/query.py", line 1491, in build_filter
    condition = self.build_lookup(lookups, col, value)
  File "/home/farsana.ka/Documents/Bus Buddy/source_code/web/env/lib/python3.10/site-packages/django/db/models/sql/query.py", line 1318, in build_lookup
    lookup = lookup_class(lhs, rhs)
  File "/home/farsana.ka/Documents/Bus Buddy/source_code/web/env/lib/python3.10/site-packages/django/db/models/lookups.py", line 27, in __init__
    self.rhs = self.get_prep_lookup()
  File "/home/farsana.ka/Documents/Bus Buddy/source_code/web/env/lib/python3.10/site-packages/django/db/models/lookups.py", line 341, in get_prep_lookup
    return super().get_prep_lookup()
  File "/home/farsana.ka/Documents/Bus Buddy/source_code/web/env/lib/python3.10/site-packages/django/db/models/lookups.py", line 85, in get_prep_lookup
    return self.lhs.output_field.get_prep_value(self.rhs)
  File "/home/farsana.ka/Documents/Bus Buddy/source_code/web/env/lib/python3.10/site-packages/django/db/models/fields/__init__.py", line 2055, in get_prep_value
    raise e.__class__(
ValueError: Field 'status' expected a number but got 'undefined'.

During handling of the above exception, another exception occurred:

Traceback (most recent call last):
  File "/home/farsana.ka/Documents/Bus Buddy/source_code/web/env/lib/python3.10/site-packages/django/core/handlers/exception.py", line 55, in inner
    response = get_response(request)
  File "/home/farsana.ka/Documents/Bus Buddy/source_code/web/env/lib/python3.10/site-packages/django/core/handlers/base.py", line 197, in _get_response
    response = wrapped_callback(request, *callback_args, **callback_kwargs)
  File "/home/farsana.ka/Documents/Bus Buddy/source_code/web/env/lib/python3.10/site-packages/django/views/decorators/csrf.py", line 56, in wrapper_view
    return view_func(*args, **kwargs)
  File "/home/farsana.ka/Documents/Bus Buddy/source_code/web/env/lib/python3.10/site-packages/django/views/generic/base.py", line 104, in view
    return self.dispatch(request, *args, **kwargs)
  File "/home/farsana.ka/Documents/Bus Buddy/source_code/web/env/lib/python3.10/site-packages/rest_framework/views.py", line 509, in dispatch
    response = self.handle_exception(exc)
  File "/home/farsana.ka/Documents/Bus Buddy/source_code/web/env/lib/python3.10/site-packages/rest_framework/views.py", line 469, in handle_exception
    self.raise_uncaught_exception(exc)
  File "/home/farsana.ka/Documents/Bus Buddy/source_code/web/env/lib/python3.10/site-packages/rest_framework/views.py", line 480, in raise_uncaught_exception
    raise exc
  File "/home/farsana.ka/Documents/Bus Buddy/source_code/web/env/lib/python3.10/site-packages/rest_framework/views.py", line 506, in dispatch
    response = handler(request, *args, **kwargs)
  File "/home/farsana.ka/Documents/Bus Buddy/source_code/web/env/lib/python3.10/site-packages/rest_framework/generics.py", line 199, in get
    return self.list(request, *args, **kwargs)
  File "/home/farsana.ka/Documents/Bus Buddy/source_code/web/bus_buddy_back_end/normal_user/views.py", line 172, in list
    return Response(serializer._errors)
UnboundLocalError: local variable 'serializer' referenced before assignment
django.request ERROR 2023-11-14 09:44:24,624 log 46881 139781170259520 Internal Server Error: /user/booking-history
Traceback (most recent call last):
  File "/home/farsana.ka/Documents/Bus Buddy/source_code/web/env/lib/python3.10/site-packages/django/db/models/fields/__init__.py", line 2053, in get_prep_value
    return int(value)
ValueError: invalid literal for int() with base 10: 'undefined'

The above exception was the direct cause of the following exception:

Traceback (most recent call last):
  File "/home/farsana.ka/Documents/Bus Buddy/source_code/web/bus_buddy_back_end/normal_user/views.py", line 160, in list
    queryset = Bookings.objects.filter(user=user_id,status=status)
  File "/home/farsana.ka/Documents/Bus Buddy/source_code/web/env/lib/python3.10/site-packages/django/db/models/manager.py", line 87, in manager_method
    return getattr(self.get_queryset(), name)(*args, **kwargs)
  File "/home/farsana.ka/Documents/Bus Buddy/source_code/web/env/lib/python3.10/site-packages/django/db/models/query.py", line 1436, in filter
    return self._filter_or_exclude(False, args, kwargs)
  File "/home/farsana.ka/Documents/Bus Buddy/source_code/web/env/lib/python3.10/site-packages/django/db/models/query.py", line 1454, in _filter_or_exclude
    clone._filter_or_exclude_inplace(negate, args, kwargs)
  File "/home/farsana.ka/Documents/Bus Buddy/source_code/web/env/lib/python3.10/site-packages/django/db/models/query.py", line 1461, in _filter_or_exclude_inplace
    self._query.add_q(Q(*args, **kwargs))
  File "/home/farsana.ka/Documents/Bus Buddy/source_code/web/env/lib/python3.10/site-packages/django/db/models/sql/query.py", line 1545, in add_q
    clause, _ = self._add_q(q_object, self.used_aliases)
  File "/home/farsana.ka/Documents/Bus Buddy/source_code/web/env/lib/python3.10/site-packages/django/db/models/sql/query.py", line 1576, in _add_q
    child_clause, needed_inner = self.build_filter(
  File "/home/farsana.ka/Documents/Bus Buddy/source_code/web/env/lib/python3.10/site-packages/django/db/models/sql/query.py", line 1491, in build_filter
    condition = self.build_lookup(lookups, col, value)
  File "/home/farsana.ka/Documents/Bus Buddy/source_code/web/env/lib/python3.10/site-packages/django/db/models/sql/query.py", line 1318, in build_lookup
    lookup = lookup_class(lhs, rhs)
  File "/home/farsana.ka/Documents/Bus Buddy/source_code/web/env/lib/python3.10/site-packages/django/db/models/lookups.py", line 27, in __init__
    self.rhs = self.get_prep_lookup()
  File "/home/farsana.ka/Documents/Bus Buddy/source_code/web/env/lib/python3.10/site-packages/django/db/models/lookups.py", line 341, in get_prep_lookup
    return super().get_prep_lookup()
  File "/home/farsana.ka/Documents/Bus Buddy/source_code/web/env/lib/python3.10/site-packages/django/db/models/lookups.py", line 85, in get_prep_lookup
    return self.lhs.output_field.get_prep_value(self.rhs)
  File "/home/farsana.ka/Documents/Bus Buddy/source_code/web/env/lib/python3.10/site-packages/django/db/models/fields/__init__.py", line 2055, in get_prep_value
    raise e.__class__(
ValueError: Field 'status' expected a number but got 'undefined'.

During handling of the above exception, another exception occurred:

Traceback (most recent call last):
  File "/home/farsana.ka/Documents/Bus Buddy/source_code/web/env/lib/python3.10/site-packages/django/core/handlers/exception.py", line 55, in inner
    response = get_response(request)
  File "/home/farsana.ka/Documents/Bus Buddy/source_code/web/env/lib/python3.10/site-packages/django/core/handlers/base.py", line 197, in _get_response
    response = wrapped_callback(request, *callback_args, **callback_kwargs)
  File "/home/farsana.ka/Documents/Bus Buddy/source_code/web/env/lib/python3.10/site-packages/django/views/decorators/csrf.py", line 56, in wrapper_view
    return view_func(*args, **kwargs)
  File "/home/farsana.ka/Documents/Bus Buddy/source_code/web/env/lib/python3.10/site-packages/django/views/generic/base.py", line 104, in view
    return self.dispatch(request, *args, **kwargs)
  File "/home/farsana.ka/Documents/Bus Buddy/source_code/web/env/lib/python3.10/site-packages/rest_framework/views.py", line 509, in dispatch
    response = self.handle_exception(exc)
  File "/home/farsana.ka/Documents/Bus Buddy/source_code/web/env/lib/python3.10/site-packages/rest_framework/views.py", line 469, in handle_exception
    self.raise_uncaught_exception(exc)
  File "/home/farsana.ka/Documents/Bus Buddy/source_code/web/env/lib/python3.10/site-packages/rest_framework/views.py", line 480, in raise_uncaught_exception
    raise exc
  File "/home/farsana.ka/Documents/Bus Buddy/source_code/web/env/lib/python3.10/site-packages/rest_framework/views.py", line 506, in dispatch
    response = handler(request, *args, **kwargs)
  File "/home/farsana.ka/Documents/Bus Buddy/source_code/web/env/lib/python3.10/site-packages/rest_framework/generics.py", line 199, in get
    return self.list(request, *args, **kwargs)
  File "/home/farsana.ka/Documents/Bus Buddy/source_code/web/bus_buddy_back_end/normal_user/views.py", line 172, in list
    return Response(serializer._errors)
UnboundLocalError: local variable 'serializer' referenced before assignment
django.request ERROR 2023-11-14 09:44:25,121 log 46881 139781170259520 Internal Server Error: /user/booking-history
Traceback (most recent call last):
  File "/home/farsana.ka/Documents/Bus Buddy/source_code/web/env/lib/python3.10/site-packages/django/db/models/fields/__init__.py", line 2053, in get_prep_value
    return int(value)
ValueError: invalid literal for int() with base 10: 'undefined'

The above exception was the direct cause of the following exception:

Traceback (most recent call last):
  File "/home/farsana.ka/Documents/Bus Buddy/source_code/web/bus_buddy_back_end/normal_user/views.py", line 160, in list
    queryset = Bookings.objects.filter(user=user_id,status=status)
  File "/home/farsana.ka/Documents/Bus Buddy/source_code/web/env/lib/python3.10/site-packages/django/db/models/manager.py", line 87, in manager_method
    return getattr(self.get_queryset(), name)(*args, **kwargs)
  File "/home/farsana.ka/Documents/Bus Buddy/source_code/web/env/lib/python3.10/site-packages/django/db/models/query.py", line 1436, in filter
    return self._filter_or_exclude(False, args, kwargs)
  File "/home/farsana.ka/Documents/Bus Buddy/source_code/web/env/lib/python3.10/site-packages/django/db/models/query.py", line 1454, in _filter_or_exclude
    clone._filter_or_exclude_inplace(negate, args, kwargs)
  File "/home/farsana.ka/Documents/Bus Buddy/source_code/web/env/lib/python3.10/site-packages/django/db/models/query.py", line 1461, in _filter_or_exclude_inplace
    self._query.add_q(Q(*args, **kwargs))
  File "/home/farsana.ka/Documents/Bus Buddy/source_code/web/env/lib/python3.10/site-packages/django/db/models/sql/query.py", line 1545, in add_q
    clause, _ = self._add_q(q_object, self.used_aliases)
  File "/home/farsana.ka/Documents/Bus Buddy/source_code/web/env/lib/python3.10/site-packages/django/db/models/sql/query.py", line 1576, in _add_q
    child_clause, needed_inner = self.build_filter(
  File "/home/farsana.ka/Documents/Bus Buddy/source_code/web/env/lib/python3.10/site-packages/django/db/models/sql/query.py", line 1491, in build_filter
    condition = self.build_lookup(lookups, col, value)
  File "/home/farsana.ka/Documents/Bus Buddy/source_code/web/env/lib/python3.10/site-packages/django/db/models/sql/query.py", line 1318, in build_lookup
    lookup = lookup_class(lhs, rhs)
  File "/home/farsana.ka/Documents/Bus Buddy/source_code/web/env/lib/python3.10/site-packages/django/db/models/lookups.py", line 27, in __init__
    self.rhs = self.get_prep_lookup()
  File "/home/farsana.ka/Documents/Bus Buddy/source_code/web/env/lib/python3.10/site-packages/django/db/models/lookups.py", line 341, in get_prep_lookup
    return super().get_prep_lookup()
  File "/home/farsana.ka/Documents/Bus Buddy/source_code/web/env/lib/python3.10/site-packages/django/db/models/lookups.py", line 85, in get_prep_lookup
    return self.lhs.output_field.get_prep_value(self.rhs)
  File "/home/farsana.ka/Documents/Bus Buddy/source_code/web/env/lib/python3.10/site-packages/django/db/models/fields/__init__.py", line 2055, in get_prep_value
    raise e.__class__(
ValueError: Field 'status' expected a number but got 'undefined'.

During handling of the above exception, another exception occurred:

Traceback (most recent call last):
  File "/home/farsana.ka/Documents/Bus Buddy/source_code/web/env/lib/python3.10/site-packages/django/core/handlers/exception.py", line 55, in inner
    response = get_response(request)
  File "/home/farsana.ka/Documents/Bus Buddy/source_code/web/env/lib/python3.10/site-packages/django/core/handlers/base.py", line 197, in _get_response
    response = wrapped_callback(request, *callback_args, **callback_kwargs)
  File "/home/farsana.ka/Documents/Bus Buddy/source_code/web/env/lib/python3.10/site-packages/django/views/decorators/csrf.py", line 56, in wrapper_view
    return view_func(*args, **kwargs)
  File "/home/farsana.ka/Documents/Bus Buddy/source_code/web/env/lib/python3.10/site-packages/django/views/generic/base.py", line 104, in view
    return self.dispatch(request, *args, **kwargs)
  File "/home/farsana.ka/Documents/Bus Buddy/source_code/web/env/lib/python3.10/site-packages/rest_framework/views.py", line 509, in dispatch
    response = self.handle_exception(exc)
  File "/home/farsana.ka/Documents/Bus Buddy/source_code/web/env/lib/python3.10/site-packages/rest_framework/views.py", line 469, in handle_exception
    self.raise_uncaught_exception(exc)
  File "/home/farsana.ka/Documents/Bus Buddy/source_code/web/env/lib/python3.10/site-packages/rest_framework/views.py", line 480, in raise_uncaught_exception
    raise exc
  File "/home/farsana.ka/Documents/Bus Buddy/source_code/web/env/lib/python3.10/site-packages/rest_framework/views.py", line 506, in dispatch
    response = handler(request, *args, **kwargs)
  File "/home/farsana.ka/Documents/Bus Buddy/source_code/web/env/lib/python3.10/site-packages/rest_framework/generics.py", line 199, in get
    return self.list(request, *args, **kwargs)
  File "/home/farsana.ka/Documents/Bus Buddy/source_code/web/bus_buddy_back_end/normal_user/views.py", line 172, in list
    return Response(serializer._errors)
UnboundLocalError: local variable 'serializer' referenced before assignment
django.request ERROR 2023-11-14 09:44:25,121 log 46881 139781170259520 Internal Server Error: /user/booking-history
Traceback (most recent call last):
  File "/home/farsana.ka/Documents/Bus Buddy/source_code/web/env/lib/python3.10/site-packages/django/db/models/fields/__init__.py", line 2053, in get_prep_value
    return int(value)
ValueError: invalid literal for int() with base 10: 'undefined'

The above exception was the direct cause of the following exception:

Traceback (most recent call last):
  File "/home/farsana.ka/Documents/Bus Buddy/source_code/web/bus_buddy_back_end/normal_user/views.py", line 160, in list
    queryset = Bookings.objects.filter(user=user_id,status=status)
  File "/home/farsana.ka/Documents/Bus Buddy/source_code/web/env/lib/python3.10/site-packages/django/db/models/manager.py", line 87, in manager_method
    return getattr(self.get_queryset(), name)(*args, **kwargs)
  File "/home/farsana.ka/Documents/Bus Buddy/source_code/web/env/lib/python3.10/site-packages/django/db/models/query.py", line 1436, in filter
    return self._filter_or_exclude(False, args, kwargs)
  File "/home/farsana.ka/Documents/Bus Buddy/source_code/web/env/lib/python3.10/site-packages/django/db/models/query.py", line 1454, in _filter_or_exclude
    clone._filter_or_exclude_inplace(negate, args, kwargs)
  File "/home/farsana.ka/Documents/Bus Buddy/source_code/web/env/lib/python3.10/site-packages/django/db/models/query.py", line 1461, in _filter_or_exclude_inplace
    self._query.add_q(Q(*args, **kwargs))
  File "/home/farsana.ka/Documents/Bus Buddy/source_code/web/env/lib/python3.10/site-packages/django/db/models/sql/query.py", line 1545, in add_q
    clause, _ = self._add_q(q_object, self.used_aliases)
  File "/home/farsana.ka/Documents/Bus Buddy/source_code/web/env/lib/python3.10/site-packages/django/db/models/sql/query.py", line 1576, in _add_q
    child_clause, needed_inner = self.build_filter(
  File "/home/farsana.ka/Documents/Bus Buddy/source_code/web/env/lib/python3.10/site-packages/django/db/models/sql/query.py", line 1491, in build_filter
    condition = self.build_lookup(lookups, col, value)
  File "/home/farsana.ka/Documents/Bus Buddy/source_code/web/env/lib/python3.10/site-packages/django/db/models/sql/query.py", line 1318, in build_lookup
    lookup = lookup_class(lhs, rhs)
  File "/home/farsana.ka/Documents/Bus Buddy/source_code/web/env/lib/python3.10/site-packages/django/db/models/lookups.py", line 27, in __init__
    self.rhs = self.get_prep_lookup()
  File "/home/farsana.ka/Documents/Bus Buddy/source_code/web/env/lib/python3.10/site-packages/django/db/models/lookups.py", line 341, in get_prep_lookup
    return super().get_prep_lookup()
  File "/home/farsana.ka/Documents/Bus Buddy/source_code/web/env/lib/python3.10/site-packages/django/db/models/lookups.py", line 85, in get_prep_lookup
    return self.lhs.output_field.get_prep_value(self.rhs)
  File "/home/farsana.ka/Documents/Bus Buddy/source_code/web/env/lib/python3.10/site-packages/django/db/models/fields/__init__.py", line 2055, in get_prep_value
    raise e.__class__(
ValueError: Field 'status' expected a number but got 'undefined'.

During handling of the above exception, another exception occurred:

Traceback (most recent call last):
  File "/home/farsana.ka/Documents/Bus Buddy/source_code/web/env/lib/python3.10/site-packages/django/core/handlers/exception.py", line 55, in inner
    response = get_response(request)
  File "/home/farsana.ka/Documents/Bus Buddy/source_code/web/env/lib/python3.10/site-packages/django/core/handlers/base.py", line 197, in _get_response
    response = wrapped_callback(request, *callback_args, **callback_kwargs)
  File "/home/farsana.ka/Documents/Bus Buddy/source_code/web/env/lib/python3.10/site-packages/django/views/decorators/csrf.py", line 56, in wrapper_view
    return view_func(*args, **kwargs)
  File "/home/farsana.ka/Documents/Bus Buddy/source_code/web/env/lib/python3.10/site-packages/django/views/generic/base.py", line 104, in view
    return self.dispatch(request, *args, **kwargs)
  File "/home/farsana.ka/Documents/Bus Buddy/source_code/web/env/lib/python3.10/site-packages/rest_framework/views.py", line 509, in dispatch
    response = self.handle_exception(exc)
  File "/home/farsana.ka/Documents/Bus Buddy/source_code/web/env/lib/python3.10/site-packages/rest_framework/views.py", line 469, in handle_exception
    self.raise_uncaught_exception(exc)
  File "/home/farsana.ka/Documents/Bus Buddy/source_code/web/env/lib/python3.10/site-packages/rest_framework/views.py", line 480, in raise_uncaught_exception
    raise exc
  File "/home/farsana.ka/Documents/Bus Buddy/source_code/web/env/lib/python3.10/site-packages/rest_framework/views.py", line 506, in dispatch
    response = handler(request, *args, **kwargs)
  File "/home/farsana.ka/Documents/Bus Buddy/source_code/web/env/lib/python3.10/site-packages/rest_framework/generics.py", line 199, in get
    return self.list(request, *args, **kwargs)
  File "/home/farsana.ka/Documents/Bus Buddy/source_code/web/bus_buddy_back_end/normal_user/views.py", line 172, in list
    return Response(serializer._errors)
UnboundLocalError: local variable 'serializer' referenced before assignment
django.request ERROR 2023-11-14 09:44:32,394 log 46881 139781170259520 Internal Server Error: /user/booking-history
Traceback (most recent call last):
  File "/home/farsana.ka/Documents/Bus Buddy/source_code/web/env/lib/python3.10/site-packages/django/db/models/fields/__init__.py", line 2053, in get_prep_value
    return int(value)
ValueError: invalid literal for int() with base 10: 'undefined'

The above exception was the direct cause of the following exception:

Traceback (most recent call last):
  File "/home/farsana.ka/Documents/Bus Buddy/source_code/web/bus_buddy_back_end/normal_user/views.py", line 160, in list
    queryset = Bookings.objects.filter(user=user_id,status=status)
  File "/home/farsana.ka/Documents/Bus Buddy/source_code/web/env/lib/python3.10/site-packages/django/db/models/manager.py", line 87, in manager_method
    return getattr(self.get_queryset(), name)(*args, **kwargs)
  File "/home/farsana.ka/Documents/Bus Buddy/source_code/web/env/lib/python3.10/site-packages/django/db/models/query.py", line 1436, in filter
    return self._filter_or_exclude(False, args, kwargs)
  File "/home/farsana.ka/Documents/Bus Buddy/source_code/web/env/lib/python3.10/site-packages/django/db/models/query.py", line 1454, in _filter_or_exclude
    clone._filter_or_exclude_inplace(negate, args, kwargs)
  File "/home/farsana.ka/Documents/Bus Buddy/source_code/web/env/lib/python3.10/site-packages/django/db/models/query.py", line 1461, in _filter_or_exclude_inplace
    self._query.add_q(Q(*args, **kwargs))
  File "/home/farsana.ka/Documents/Bus Buddy/source_code/web/env/lib/python3.10/site-packages/django/db/models/sql/query.py", line 1545, in add_q
    clause, _ = self._add_q(q_object, self.used_aliases)
  File "/home/farsana.ka/Documents/Bus Buddy/source_code/web/env/lib/python3.10/site-packages/django/db/models/sql/query.py", line 1576, in _add_q
    child_clause, needed_inner = self.build_filter(
  File "/home/farsana.ka/Documents/Bus Buddy/source_code/web/env/lib/python3.10/site-packages/django/db/models/sql/query.py", line 1491, in build_filter
    condition = self.build_lookup(lookups, col, value)
  File "/home/farsana.ka/Documents/Bus Buddy/source_code/web/env/lib/python3.10/site-packages/django/db/models/sql/query.py", line 1318, in build_lookup
    lookup = lookup_class(lhs, rhs)
  File "/home/farsana.ka/Documents/Bus Buddy/source_code/web/env/lib/python3.10/site-packages/django/db/models/lookups.py", line 27, in __init__
    self.rhs = self.get_prep_lookup()
  File "/home/farsana.ka/Documents/Bus Buddy/source_code/web/env/lib/python3.10/site-packages/django/db/models/lookups.py", line 341, in get_prep_lookup
    return super().get_prep_lookup()
  File "/home/farsana.ka/Documents/Bus Buddy/source_code/web/env/lib/python3.10/site-packages/django/db/models/lookups.py", line 85, in get_prep_lookup
    return self.lhs.output_field.get_prep_value(self.rhs)
  File "/home/farsana.ka/Documents/Bus Buddy/source_code/web/env/lib/python3.10/site-packages/django/db/models/fields/__init__.py", line 2055, in get_prep_value
    raise e.__class__(
ValueError: Field 'status' expected a number but got 'undefined'.

During handling of the above exception, another exception occurred:

Traceback (most recent call last):
  File "/home/farsana.ka/Documents/Bus Buddy/source_code/web/env/lib/python3.10/site-packages/django/core/handlers/exception.py", line 55, in inner
    response = get_response(request)
  File "/home/farsana.ka/Documents/Bus Buddy/source_code/web/env/lib/python3.10/site-packages/django/core/handlers/base.py", line 197, in _get_response
    response = wrapped_callback(request, *callback_args, **callback_kwargs)
  File "/home/farsana.ka/Documents/Bus Buddy/source_code/web/env/lib/python3.10/site-packages/django/views/decorators/csrf.py", line 56, in wrapper_view
    return view_func(*args, **kwargs)
  File "/home/farsana.ka/Documents/Bus Buddy/source_code/web/env/lib/python3.10/site-packages/django/views/generic/base.py", line 104, in view
    return self.dispatch(request, *args, **kwargs)
  File "/home/farsana.ka/Documents/Bus Buddy/source_code/web/env/lib/python3.10/site-packages/rest_framework/views.py", line 509, in dispatch
    response = self.handle_exception(exc)
  File "/home/farsana.ka/Documents/Bus Buddy/source_code/web/env/lib/python3.10/site-packages/rest_framework/views.py", line 469, in handle_exception
    self.raise_uncaught_exception(exc)
  File "/home/farsana.ka/Documents/Bus Buddy/source_code/web/env/lib/python3.10/site-packages/rest_framework/views.py", line 480, in raise_uncaught_exception
    raise exc
  File "/home/farsana.ka/Documents/Bus Buddy/source_code/web/env/lib/python3.10/site-packages/rest_framework/views.py", line 506, in dispatch
    response = handler(request, *args, **kwargs)
  File "/home/farsana.ka/Documents/Bus Buddy/source_code/web/env/lib/python3.10/site-packages/rest_framework/generics.py", line 199, in get
    return self.list(request, *args, **kwargs)
  File "/home/farsana.ka/Documents/Bus Buddy/source_code/web/bus_buddy_back_end/normal_user/views.py", line 172, in list
    return Response(serializer._errors)
UnboundLocalError: local variable 'serializer' referenced before assignment
django.request ERROR 2023-11-14 09:44:32,394 log 46881 139781170259520 Internal Server Error: /user/booking-history
Traceback (most recent call last):
  File "/home/farsana.ka/Documents/Bus Buddy/source_code/web/env/lib/python3.10/site-packages/django/db/models/fields/__init__.py", line 2053, in get_prep_value
    return int(value)
ValueError: invalid literal for int() with base 10: 'undefined'

The above exception was the direct cause of the following exception:

Traceback (most recent call last):
  File "/home/farsana.ka/Documents/Bus Buddy/source_code/web/bus_buddy_back_end/normal_user/views.py", line 160, in list
    queryset = Bookings.objects.filter(user=user_id,status=status)
  File "/home/farsana.ka/Documents/Bus Buddy/source_code/web/env/lib/python3.10/site-packages/django/db/models/manager.py", line 87, in manager_method
    return getattr(self.get_queryset(), name)(*args, **kwargs)
  File "/home/farsana.ka/Documents/Bus Buddy/source_code/web/env/lib/python3.10/site-packages/django/db/models/query.py", line 1436, in filter
    return self._filter_or_exclude(False, args, kwargs)
  File "/home/farsana.ka/Documents/Bus Buddy/source_code/web/env/lib/python3.10/site-packages/django/db/models/query.py", line 1454, in _filter_or_exclude
    clone._filter_or_exclude_inplace(negate, args, kwargs)
  File "/home/farsana.ka/Documents/Bus Buddy/source_code/web/env/lib/python3.10/site-packages/django/db/models/query.py", line 1461, in _filter_or_exclude_inplace
    self._query.add_q(Q(*args, **kwargs))
  File "/home/farsana.ka/Documents/Bus Buddy/source_code/web/env/lib/python3.10/site-packages/django/db/models/sql/query.py", line 1545, in add_q
    clause, _ = self._add_q(q_object, self.used_aliases)
  File "/home/farsana.ka/Documents/Bus Buddy/source_code/web/env/lib/python3.10/site-packages/django/db/models/sql/query.py", line 1576, in _add_q
    child_clause, needed_inner = self.build_filter(
  File "/home/farsana.ka/Documents/Bus Buddy/source_code/web/env/lib/python3.10/site-packages/django/db/models/sql/query.py", line 1491, in build_filter
    condition = self.build_lookup(lookups, col, value)
  File "/home/farsana.ka/Documents/Bus Buddy/source_code/web/env/lib/python3.10/site-packages/django/db/models/sql/query.py", line 1318, in build_lookup
    lookup = lookup_class(lhs, rhs)
  File "/home/farsana.ka/Documents/Bus Buddy/source_code/web/env/lib/python3.10/site-packages/django/db/models/lookups.py", line 27, in __init__
    self.rhs = self.get_prep_lookup()
  File "/home/farsana.ka/Documents/Bus Buddy/source_code/web/env/lib/python3.10/site-packages/django/db/models/lookups.py", line 341, in get_prep_lookup
    return super().get_prep_lookup()
  File "/home/farsana.ka/Documents/Bus Buddy/source_code/web/env/lib/python3.10/site-packages/django/db/models/lookups.py", line 85, in get_prep_lookup
    return self.lhs.output_field.get_prep_value(self.rhs)
  File "/home/farsana.ka/Documents/Bus Buddy/source_code/web/env/lib/python3.10/site-packages/django/db/models/fields/__init__.py", line 2055, in get_prep_value
    raise e.__class__(
ValueError: Field 'status' expected a number but got 'undefined'.

During handling of the above exception, another exception occurred:

Traceback (most recent call last):
  File "/home/farsana.ka/Documents/Bus Buddy/source_code/web/env/lib/python3.10/site-packages/django/core/handlers/exception.py", line 55, in inner
    response = get_response(request)
  File "/home/farsana.ka/Documents/Bus Buddy/source_code/web/env/lib/python3.10/site-packages/django/core/handlers/base.py", line 197, in _get_response
    response = wrapped_callback(request, *callback_args, **callback_kwargs)
  File "/home/farsana.ka/Documents/Bus Buddy/source_code/web/env/lib/python3.10/site-packages/django/views/decorators/csrf.py", line 56, in wrapper_view
    return view_func(*args, **kwargs)
  File "/home/farsana.ka/Documents/Bus Buddy/source_code/web/env/lib/python3.10/site-packages/django/views/generic/base.py", line 104, in view
    return self.dispatch(request, *args, **kwargs)
  File "/home/farsana.ka/Documents/Bus Buddy/source_code/web/env/lib/python3.10/site-packages/rest_framework/views.py", line 509, in dispatch
    response = self.handle_exception(exc)
  File "/home/farsana.ka/Documents/Bus Buddy/source_code/web/env/lib/python3.10/site-packages/rest_framework/views.py", line 469, in handle_exception
    self.raise_uncaught_exception(exc)
  File "/home/farsana.ka/Documents/Bus Buddy/source_code/web/env/lib/python3.10/site-packages/rest_framework/views.py", line 480, in raise_uncaught_exception
    raise exc
  File "/home/farsana.ka/Documents/Bus Buddy/source_code/web/env/lib/python3.10/site-packages/rest_framework/views.py", line 506, in dispatch
    response = handler(request, *args, **kwargs)
  File "/home/farsana.ka/Documents/Bus Buddy/source_code/web/env/lib/python3.10/site-packages/rest_framework/generics.py", line 199, in get
    return self.list(request, *args, **kwargs)
  File "/home/farsana.ka/Documents/Bus Buddy/source_code/web/bus_buddy_back_end/normal_user/views.py", line 172, in list
    return Response(serializer._errors)
UnboundLocalError: local variable 'serializer' referenced before assignment
django.request ERROR 2023-11-14 09:44:33,086 log 46881 139781170259520 Internal Server Error: /user/booking-history
Traceback (most recent call last):
  File "/home/farsana.ka/Documents/Bus Buddy/source_code/web/env/lib/python3.10/site-packages/django/db/models/fields/__init__.py", line 2053, in get_prep_value
    return int(value)
ValueError: invalid literal for int() with base 10: 'undefined'

The above exception was the direct cause of the following exception:

Traceback (most recent call last):
  File "/home/farsana.ka/Documents/Bus Buddy/source_code/web/bus_buddy_back_end/normal_user/views.py", line 160, in list
    queryset = Bookings.objects.filter(user=user_id,status=status)
  File "/home/farsana.ka/Documents/Bus Buddy/source_code/web/env/lib/python3.10/site-packages/django/db/models/manager.py", line 87, in manager_method
    return getattr(self.get_queryset(), name)(*args, **kwargs)
  File "/home/farsana.ka/Documents/Bus Buddy/source_code/web/env/lib/python3.10/site-packages/django/db/models/query.py", line 1436, in filter
    return self._filter_or_exclude(False, args, kwargs)
  File "/home/farsana.ka/Documents/Bus Buddy/source_code/web/env/lib/python3.10/site-packages/django/db/models/query.py", line 1454, in _filter_or_exclude
    clone._filter_or_exclude_inplace(negate, args, kwargs)
  File "/home/farsana.ka/Documents/Bus Buddy/source_code/web/env/lib/python3.10/site-packages/django/db/models/query.py", line 1461, in _filter_or_exclude_inplace
    self._query.add_q(Q(*args, **kwargs))
  File "/home/farsana.ka/Documents/Bus Buddy/source_code/web/env/lib/python3.10/site-packages/django/db/models/sql/query.py", line 1545, in add_q
    clause, _ = self._add_q(q_object, self.used_aliases)
  File "/home/farsana.ka/Documents/Bus Buddy/source_code/web/env/lib/python3.10/site-packages/django/db/models/sql/query.py", line 1576, in _add_q
    child_clause, needed_inner = self.build_filter(
  File "/home/farsana.ka/Documents/Bus Buddy/source_code/web/env/lib/python3.10/site-packages/django/db/models/sql/query.py", line 1491, in build_filter
    condition = self.build_lookup(lookups, col, value)
  File "/home/farsana.ka/Documents/Bus Buddy/source_code/web/env/lib/python3.10/site-packages/django/db/models/sql/query.py", line 1318, in build_lookup
    lookup = lookup_class(lhs, rhs)
  File "/home/farsana.ka/Documents/Bus Buddy/source_code/web/env/lib/python3.10/site-packages/django/db/models/lookups.py", line 27, in __init__
    self.rhs = self.get_prep_lookup()
  File "/home/farsana.ka/Documents/Bus Buddy/source_code/web/env/lib/python3.10/site-packages/django/db/models/lookups.py", line 341, in get_prep_lookup
    return super().get_prep_lookup()
  File "/home/farsana.ka/Documents/Bus Buddy/source_code/web/env/lib/python3.10/site-packages/django/db/models/lookups.py", line 85, in get_prep_lookup
    return self.lhs.output_field.get_prep_value(self.rhs)
  File "/home/farsana.ka/Documents/Bus Buddy/source_code/web/env/lib/python3.10/site-packages/django/db/models/fields/__init__.py", line 2055, in get_prep_value
    raise e.__class__(
ValueError: Field 'status' expected a number but got 'undefined'.

During handling of the above exception, another exception occurred:

Traceback (most recent call last):
  File "/home/farsana.ka/Documents/Bus Buddy/source_code/web/env/lib/python3.10/site-packages/django/core/handlers/exception.py", line 55, in inner
    response = get_response(request)
  File "/home/farsana.ka/Documents/Bus Buddy/source_code/web/env/lib/python3.10/site-packages/django/core/handlers/base.py", line 197, in _get_response
    response = wrapped_callback(request, *callback_args, **callback_kwargs)
  File "/home/farsana.ka/Documents/Bus Buddy/source_code/web/env/lib/python3.10/site-packages/django/views/decorators/csrf.py", line 56, in wrapper_view
    return view_func(*args, **kwargs)
  File "/home/farsana.ka/Documents/Bus Buddy/source_code/web/env/lib/python3.10/site-packages/django/views/generic/base.py", line 104, in view
    return self.dispatch(request, *args, **kwargs)
  File "/home/farsana.ka/Documents/Bus Buddy/source_code/web/env/lib/python3.10/site-packages/rest_framework/views.py", line 509, in dispatch
    response = self.handle_exception(exc)
  File "/home/farsana.ka/Documents/Bus Buddy/source_code/web/env/lib/python3.10/site-packages/rest_framework/views.py", line 469, in handle_exception
    self.raise_uncaught_exception(exc)
  File "/home/farsana.ka/Documents/Bus Buddy/source_code/web/env/lib/python3.10/site-packages/rest_framework/views.py", line 480, in raise_uncaught_exception
    raise exc
  File "/home/farsana.ka/Documents/Bus Buddy/source_code/web/env/lib/python3.10/site-packages/rest_framework/views.py", line 506, in dispatch
    response = handler(request, *args, **kwargs)
  File "/home/farsana.ka/Documents/Bus Buddy/source_code/web/env/lib/python3.10/site-packages/rest_framework/generics.py", line 199, in get
    return self.list(request, *args, **kwargs)
  File "/home/farsana.ka/Documents/Bus Buddy/source_code/web/bus_buddy_back_end/normal_user/views.py", line 172, in list
    return Response(serializer._errors)
UnboundLocalError: local variable 'serializer' referenced before assignment
django.request ERROR 2023-11-14 09:44:33,086 log 46881 139781170259520 Internal Server Error: /user/booking-history
Traceback (most recent call last):
  File "/home/farsana.ka/Documents/Bus Buddy/source_code/web/env/lib/python3.10/site-packages/django/db/models/fields/__init__.py", line 2053, in get_prep_value
    return int(value)
ValueError: invalid literal for int() with base 10: 'undefined'

The above exception was the direct cause of the following exception:

Traceback (most recent call last):
  File "/home/farsana.ka/Documents/Bus Buddy/source_code/web/bus_buddy_back_end/normal_user/views.py", line 160, in list
    queryset = Bookings.objects.filter(user=user_id,status=status)
  File "/home/farsana.ka/Documents/Bus Buddy/source_code/web/env/lib/python3.10/site-packages/django/db/models/manager.py", line 87, in manager_method
    return getattr(self.get_queryset(), name)(*args, **kwargs)
  File "/home/farsana.ka/Documents/Bus Buddy/source_code/web/env/lib/python3.10/site-packages/django/db/models/query.py", line 1436, in filter
    return self._filter_or_exclude(False, args, kwargs)
  File "/home/farsana.ka/Documents/Bus Buddy/source_code/web/env/lib/python3.10/site-packages/django/db/models/query.py", line 1454, in _filter_or_exclude
    clone._filter_or_exclude_inplace(negate, args, kwargs)
  File "/home/farsana.ka/Documents/Bus Buddy/source_code/web/env/lib/python3.10/site-packages/django/db/models/query.py", line 1461, in _filter_or_exclude_inplace
    self._query.add_q(Q(*args, **kwargs))
  File "/home/farsana.ka/Documents/Bus Buddy/source_code/web/env/lib/python3.10/site-packages/django/db/models/sql/query.py", line 1545, in add_q
    clause, _ = self._add_q(q_object, self.used_aliases)
  File "/home/farsana.ka/Documents/Bus Buddy/source_code/web/env/lib/python3.10/site-packages/django/db/models/sql/query.py", line 1576, in _add_q
    child_clause, needed_inner = self.build_filter(
  File "/home/farsana.ka/Documents/Bus Buddy/source_code/web/env/lib/python3.10/site-packages/django/db/models/sql/query.py", line 1491, in build_filter
    condition = self.build_lookup(lookups, col, value)
  File "/home/farsana.ka/Documents/Bus Buddy/source_code/web/env/lib/python3.10/site-packages/django/db/models/sql/query.py", line 1318, in build_lookup
    lookup = lookup_class(lhs, rhs)
  File "/home/farsana.ka/Documents/Bus Buddy/source_code/web/env/lib/python3.10/site-packages/django/db/models/lookups.py", line 27, in __init__
    self.rhs = self.get_prep_lookup()
  File "/home/farsana.ka/Documents/Bus Buddy/source_code/web/env/lib/python3.10/site-packages/django/db/models/lookups.py", line 341, in get_prep_lookup
    return super().get_prep_lookup()
  File "/home/farsana.ka/Documents/Bus Buddy/source_code/web/env/lib/python3.10/site-packages/django/db/models/lookups.py", line 85, in get_prep_lookup
    return self.lhs.output_field.get_prep_value(self.rhs)
  File "/home/farsana.ka/Documents/Bus Buddy/source_code/web/env/lib/python3.10/site-packages/django/db/models/fields/__init__.py", line 2055, in get_prep_value
    raise e.__class__(
ValueError: Field 'status' expected a number but got 'undefined'.

During handling of the above exception, another exception occurred:

Traceback (most recent call last):
  File "/home/farsana.ka/Documents/Bus Buddy/source_code/web/env/lib/python3.10/site-packages/django/core/handlers/exception.py", line 55, in inner
    response = get_response(request)
  File "/home/farsana.ka/Documents/Bus Buddy/source_code/web/env/lib/python3.10/site-packages/django/core/handlers/base.py", line 197, in _get_response
    response = wrapped_callback(request, *callback_args, **callback_kwargs)
  File "/home/farsana.ka/Documents/Bus Buddy/source_code/web/env/lib/python3.10/site-packages/django/views/decorators/csrf.py", line 56, in wrapper_view
    return view_func(*args, **kwargs)
  File "/home/farsana.ka/Documents/Bus Buddy/source_code/web/env/lib/python3.10/site-packages/django/views/generic/base.py", line 104, in view
    return self.dispatch(request, *args, **kwargs)
  File "/home/farsana.ka/Documents/Bus Buddy/source_code/web/env/lib/python3.10/site-packages/rest_framework/views.py", line 509, in dispatch
    response = self.handle_exception(exc)
  File "/home/farsana.ka/Documents/Bus Buddy/source_code/web/env/lib/python3.10/site-packages/rest_framework/views.py", line 469, in handle_exception
    self.raise_uncaught_exception(exc)
  File "/home/farsana.ka/Documents/Bus Buddy/source_code/web/env/lib/python3.10/site-packages/rest_framework/views.py", line 480, in raise_uncaught_exception
    raise exc
  File "/home/farsana.ka/Documents/Bus Buddy/source_code/web/env/lib/python3.10/site-packages/rest_framework/views.py", line 506, in dispatch
    response = handler(request, *args, **kwargs)
  File "/home/farsana.ka/Documents/Bus Buddy/source_code/web/env/lib/python3.10/site-packages/rest_framework/generics.py", line 199, in get
    return self.list(request, *args, **kwargs)
  File "/home/farsana.ka/Documents/Bus Buddy/source_code/web/bus_buddy_back_end/normal_user/views.py", line 172, in list
    return Response(serializer._errors)
UnboundLocalError: local variable 'serializer' referenced before assignment
django.request ERROR 2023-11-14 09:46:09,204 log 46881 139781170259520 Internal Server Error: /user/booking-history
Traceback (most recent call last):
  File "/home/farsana.ka/Documents/Bus Buddy/source_code/web/env/lib/python3.10/site-packages/django/db/models/fields/__init__.py", line 2053, in get_prep_value
    return int(value)
ValueError: invalid literal for int() with base 10: 'undefined'

The above exception was the direct cause of the following exception:

Traceback (most recent call last):
  File "/home/farsana.ka/Documents/Bus Buddy/source_code/web/bus_buddy_back_end/normal_user/views.py", line 160, in list
    queryset = Bookings.objects.filter(user=user_id,status=status)
  File "/home/farsana.ka/Documents/Bus Buddy/source_code/web/env/lib/python3.10/site-packages/django/db/models/manager.py", line 87, in manager_method
    return getattr(self.get_queryset(), name)(*args, **kwargs)
  File "/home/farsana.ka/Documents/Bus Buddy/source_code/web/env/lib/python3.10/site-packages/django/db/models/query.py", line 1436, in filter
    return self._filter_or_exclude(False, args, kwargs)
  File "/home/farsana.ka/Documents/Bus Buddy/source_code/web/env/lib/python3.10/site-packages/django/db/models/query.py", line 1454, in _filter_or_exclude
    clone._filter_or_exclude_inplace(negate, args, kwargs)
  File "/home/farsana.ka/Documents/Bus Buddy/source_code/web/env/lib/python3.10/site-packages/django/db/models/query.py", line 1461, in _filter_or_exclude_inplace
    self._query.add_q(Q(*args, **kwargs))
  File "/home/farsana.ka/Documents/Bus Buddy/source_code/web/env/lib/python3.10/site-packages/django/db/models/sql/query.py", line 1545, in add_q
    clause, _ = self._add_q(q_object, self.used_aliases)
  File "/home/farsana.ka/Documents/Bus Buddy/source_code/web/env/lib/python3.10/site-packages/django/db/models/sql/query.py", line 1576, in _add_q
    child_clause, needed_inner = self.build_filter(
  File "/home/farsana.ka/Documents/Bus Buddy/source_code/web/env/lib/python3.10/site-packages/django/db/models/sql/query.py", line 1491, in build_filter
    condition = self.build_lookup(lookups, col, value)
  File "/home/farsana.ka/Documents/Bus Buddy/source_code/web/env/lib/python3.10/site-packages/django/db/models/sql/query.py", line 1318, in build_lookup
    lookup = lookup_class(lhs, rhs)
  File "/home/farsana.ka/Documents/Bus Buddy/source_code/web/env/lib/python3.10/site-packages/django/db/models/lookups.py", line 27, in __init__
    self.rhs = self.get_prep_lookup()
  File "/home/farsana.ka/Documents/Bus Buddy/source_code/web/env/lib/python3.10/site-packages/django/db/models/lookups.py", line 341, in get_prep_lookup
    return super().get_prep_lookup()
  File "/home/farsana.ka/Documents/Bus Buddy/source_code/web/env/lib/python3.10/site-packages/django/db/models/lookups.py", line 85, in get_prep_lookup
    return self.lhs.output_field.get_prep_value(self.rhs)
  File "/home/farsana.ka/Documents/Bus Buddy/source_code/web/env/lib/python3.10/site-packages/django/db/models/fields/__init__.py", line 2055, in get_prep_value
    raise e.__class__(
ValueError: Field 'status' expected a number but got 'undefined'.

During handling of the above exception, another exception occurred:

Traceback (most recent call last):
  File "/home/farsana.ka/Documents/Bus Buddy/source_code/web/env/lib/python3.10/site-packages/django/core/handlers/exception.py", line 55, in inner
    response = get_response(request)
  File "/home/farsana.ka/Documents/Bus Buddy/source_code/web/env/lib/python3.10/site-packages/django/core/handlers/base.py", line 197, in _get_response
    response = wrapped_callback(request, *callback_args, **callback_kwargs)
  File "/home/farsana.ka/Documents/Bus Buddy/source_code/web/env/lib/python3.10/site-packages/django/views/decorators/csrf.py", line 56, in wrapper_view
    return view_func(*args, **kwargs)
  File "/home/farsana.ka/Documents/Bus Buddy/source_code/web/env/lib/python3.10/site-packages/django/views/generic/base.py", line 104, in view
    return self.dispatch(request, *args, **kwargs)
  File "/home/farsana.ka/Documents/Bus Buddy/source_code/web/env/lib/python3.10/site-packages/rest_framework/views.py", line 509, in dispatch
    response = self.handle_exception(exc)
  File "/home/farsana.ka/Documents/Bus Buddy/source_code/web/env/lib/python3.10/site-packages/rest_framework/views.py", line 469, in handle_exception
    self.raise_uncaught_exception(exc)
  File "/home/farsana.ka/Documents/Bus Buddy/source_code/web/env/lib/python3.10/site-packages/rest_framework/views.py", line 480, in raise_uncaught_exception
    raise exc
  File "/home/farsana.ka/Documents/Bus Buddy/source_code/web/env/lib/python3.10/site-packages/rest_framework/views.py", line 506, in dispatch
    response = handler(request, *args, **kwargs)
  File "/home/farsana.ka/Documents/Bus Buddy/source_code/web/env/lib/python3.10/site-packages/rest_framework/generics.py", line 199, in get
    return self.list(request, *args, **kwargs)
  File "/home/farsana.ka/Documents/Bus Buddy/source_code/web/bus_buddy_back_end/normal_user/views.py", line 172, in list
    return Response(serializer._errors)
UnboundLocalError: local variable 'serializer' referenced before assignment
django.request ERROR 2023-11-14 09:46:09,204 log 46881 139781170259520 Internal Server Error: /user/booking-history
Traceback (most recent call last):
  File "/home/farsana.ka/Documents/Bus Buddy/source_code/web/env/lib/python3.10/site-packages/django/db/models/fields/__init__.py", line 2053, in get_prep_value
    return int(value)
ValueError: invalid literal for int() with base 10: 'undefined'

The above exception was the direct cause of the following exception:

Traceback (most recent call last):
  File "/home/farsana.ka/Documents/Bus Buddy/source_code/web/bus_buddy_back_end/normal_user/views.py", line 160, in list
    queryset = Bookings.objects.filter(user=user_id,status=status)
  File "/home/farsana.ka/Documents/Bus Buddy/source_code/web/env/lib/python3.10/site-packages/django/db/models/manager.py", line 87, in manager_method
    return getattr(self.get_queryset(), name)(*args, **kwargs)
  File "/home/farsana.ka/Documents/Bus Buddy/source_code/web/env/lib/python3.10/site-packages/django/db/models/query.py", line 1436, in filter
    return self._filter_or_exclude(False, args, kwargs)
  File "/home/farsana.ka/Documents/Bus Buddy/source_code/web/env/lib/python3.10/site-packages/django/db/models/query.py", line 1454, in _filter_or_exclude
    clone._filter_or_exclude_inplace(negate, args, kwargs)
  File "/home/farsana.ka/Documents/Bus Buddy/source_code/web/env/lib/python3.10/site-packages/django/db/models/query.py", line 1461, in _filter_or_exclude_inplace
    self._query.add_q(Q(*args, **kwargs))
  File "/home/farsana.ka/Documents/Bus Buddy/source_code/web/env/lib/python3.10/site-packages/django/db/models/sql/query.py", line 1545, in add_q
    clause, _ = self._add_q(q_object, self.used_aliases)
  File "/home/farsana.ka/Documents/Bus Buddy/source_code/web/env/lib/python3.10/site-packages/django/db/models/sql/query.py", line 1576, in _add_q
    child_clause, needed_inner = self.build_filter(
  File "/home/farsana.ka/Documents/Bus Buddy/source_code/web/env/lib/python3.10/site-packages/django/db/models/sql/query.py", line 1491, in build_filter
    condition = self.build_lookup(lookups, col, value)
  File "/home/farsana.ka/Documents/Bus Buddy/source_code/web/env/lib/python3.10/site-packages/django/db/models/sql/query.py", line 1318, in build_lookup
    lookup = lookup_class(lhs, rhs)
  File "/home/farsana.ka/Documents/Bus Buddy/source_code/web/env/lib/python3.10/site-packages/django/db/models/lookups.py", line 27, in __init__
    self.rhs = self.get_prep_lookup()
  File "/home/farsana.ka/Documents/Bus Buddy/source_code/web/env/lib/python3.10/site-packages/django/db/models/lookups.py", line 341, in get_prep_lookup
    return super().get_prep_lookup()
  File "/home/farsana.ka/Documents/Bus Buddy/source_code/web/env/lib/python3.10/site-packages/django/db/models/lookups.py", line 85, in get_prep_lookup
    return self.lhs.output_field.get_prep_value(self.rhs)
  File "/home/farsana.ka/Documents/Bus Buddy/source_code/web/env/lib/python3.10/site-packages/django/db/models/fields/__init__.py", line 2055, in get_prep_value
    raise e.__class__(
ValueError: Field 'status' expected a number but got 'undefined'.

During handling of the above exception, another exception occurred:

Traceback (most recent call last):
  File "/home/farsana.ka/Documents/Bus Buddy/source_code/web/env/lib/python3.10/site-packages/django/core/handlers/exception.py", line 55, in inner
    response = get_response(request)
  File "/home/farsana.ka/Documents/Bus Buddy/source_code/web/env/lib/python3.10/site-packages/django/core/handlers/base.py", line 197, in _get_response
    response = wrapped_callback(request, *callback_args, **callback_kwargs)
  File "/home/farsana.ka/Documents/Bus Buddy/source_code/web/env/lib/python3.10/site-packages/django/views/decorators/csrf.py", line 56, in wrapper_view
    return view_func(*args, **kwargs)
  File "/home/farsana.ka/Documents/Bus Buddy/source_code/web/env/lib/python3.10/site-packages/django/views/generic/base.py", line 104, in view
    return self.dispatch(request, *args, **kwargs)
  File "/home/farsana.ka/Documents/Bus Buddy/source_code/web/env/lib/python3.10/site-packages/rest_framework/views.py", line 509, in dispatch
    response = self.handle_exception(exc)
  File "/home/farsana.ka/Documents/Bus Buddy/source_code/web/env/lib/python3.10/site-packages/rest_framework/views.py", line 469, in handle_exception
    self.raise_uncaught_exception(exc)
  File "/home/farsana.ka/Documents/Bus Buddy/source_code/web/env/lib/python3.10/site-packages/rest_framework/views.py", line 480, in raise_uncaught_exception
    raise exc
  File "/home/farsana.ka/Documents/Bus Buddy/source_code/web/env/lib/python3.10/site-packages/rest_framework/views.py", line 506, in dispatch
    response = handler(request, *args, **kwargs)
  File "/home/farsana.ka/Documents/Bus Buddy/source_code/web/env/lib/python3.10/site-packages/rest_framework/generics.py", line 199, in get
    return self.list(request, *args, **kwargs)
  File "/home/farsana.ka/Documents/Bus Buddy/source_code/web/bus_buddy_back_end/normal_user/views.py", line 172, in list
    return Response(serializer._errors)
UnboundLocalError: local variable 'serializer' referenced before assignment
django.request ERROR 2023-11-14 09:46:10,093 log 46881 139781170259520 Internal Server Error: /user/booking-history
Traceback (most recent call last):
  File "/home/farsana.ka/Documents/Bus Buddy/source_code/web/env/lib/python3.10/site-packages/django/db/models/fields/__init__.py", line 2053, in get_prep_value
    return int(value)
ValueError: invalid literal for int() with base 10: 'undefined'

The above exception was the direct cause of the following exception:

Traceback (most recent call last):
  File "/home/farsana.ka/Documents/Bus Buddy/source_code/web/bus_buddy_back_end/normal_user/views.py", line 160, in list
    queryset = Bookings.objects.filter(user=user_id,status=status)
  File "/home/farsana.ka/Documents/Bus Buddy/source_code/web/env/lib/python3.10/site-packages/django/db/models/manager.py", line 87, in manager_method
    return getattr(self.get_queryset(), name)(*args, **kwargs)
  File "/home/farsana.ka/Documents/Bus Buddy/source_code/web/env/lib/python3.10/site-packages/django/db/models/query.py", line 1436, in filter
    return self._filter_or_exclude(False, args, kwargs)
  File "/home/farsana.ka/Documents/Bus Buddy/source_code/web/env/lib/python3.10/site-packages/django/db/models/query.py", line 1454, in _filter_or_exclude
    clone._filter_or_exclude_inplace(negate, args, kwargs)
  File "/home/farsana.ka/Documents/Bus Buddy/source_code/web/env/lib/python3.10/site-packages/django/db/models/query.py", line 1461, in _filter_or_exclude_inplace
    self._query.add_q(Q(*args, **kwargs))
  File "/home/farsana.ka/Documents/Bus Buddy/source_code/web/env/lib/python3.10/site-packages/django/db/models/sql/query.py", line 1545, in add_q
    clause, _ = self._add_q(q_object, self.used_aliases)
  File "/home/farsana.ka/Documents/Bus Buddy/source_code/web/env/lib/python3.10/site-packages/django/db/models/sql/query.py", line 1576, in _add_q
    child_clause, needed_inner = self.build_filter(
  File "/home/farsana.ka/Documents/Bus Buddy/source_code/web/env/lib/python3.10/site-packages/django/db/models/sql/query.py", line 1491, in build_filter
    condition = self.build_lookup(lookups, col, value)
  File "/home/farsana.ka/Documents/Bus Buddy/source_code/web/env/lib/python3.10/site-packages/django/db/models/sql/query.py", line 1318, in build_lookup
    lookup = lookup_class(lhs, rhs)
  File "/home/farsana.ka/Documents/Bus Buddy/source_code/web/env/lib/python3.10/site-packages/django/db/models/lookups.py", line 27, in __init__
    self.rhs = self.get_prep_lookup()
  File "/home/farsana.ka/Documents/Bus Buddy/source_code/web/env/lib/python3.10/site-packages/django/db/models/lookups.py", line 341, in get_prep_lookup
    return super().get_prep_lookup()
  File "/home/farsana.ka/Documents/Bus Buddy/source_code/web/env/lib/python3.10/site-packages/django/db/models/lookups.py", line 85, in get_prep_lookup
    return self.lhs.output_field.get_prep_value(self.rhs)
  File "/home/farsana.ka/Documents/Bus Buddy/source_code/web/env/lib/python3.10/site-packages/django/db/models/fields/__init__.py", line 2055, in get_prep_value
    raise e.__class__(
ValueError: Field 'status' expected a number but got 'undefined'.

During handling of the above exception, another exception occurred:

Traceback (most recent call last):
  File "/home/farsana.ka/Documents/Bus Buddy/source_code/web/env/lib/python3.10/site-packages/django/core/handlers/exception.py", line 55, in inner
    response = get_response(request)
  File "/home/farsana.ka/Documents/Bus Buddy/source_code/web/env/lib/python3.10/site-packages/django/core/handlers/base.py", line 197, in _get_response
    response = wrapped_callback(request, *callback_args, **callback_kwargs)
  File "/home/farsana.ka/Documents/Bus Buddy/source_code/web/env/lib/python3.10/site-packages/django/views/decorators/csrf.py", line 56, in wrapper_view
    return view_func(*args, **kwargs)
  File "/home/farsana.ka/Documents/Bus Buddy/source_code/web/env/lib/python3.10/site-packages/django/views/generic/base.py", line 104, in view
    return self.dispatch(request, *args, **kwargs)
  File "/home/farsana.ka/Documents/Bus Buddy/source_code/web/env/lib/python3.10/site-packages/rest_framework/views.py", line 509, in dispatch
    response = self.handle_exception(exc)
  File "/home/farsana.ka/Documents/Bus Buddy/source_code/web/env/lib/python3.10/site-packages/rest_framework/views.py", line 469, in handle_exception
    self.raise_uncaught_exception(exc)
  File "/home/farsana.ka/Documents/Bus Buddy/source_code/web/env/lib/python3.10/site-packages/rest_framework/views.py", line 480, in raise_uncaught_exception
    raise exc
  File "/home/farsana.ka/Documents/Bus Buddy/source_code/web/env/lib/python3.10/site-packages/rest_framework/views.py", line 506, in dispatch
    response = handler(request, *args, **kwargs)
  File "/home/farsana.ka/Documents/Bus Buddy/source_code/web/env/lib/python3.10/site-packages/rest_framework/generics.py", line 199, in get
    return self.list(request, *args, **kwargs)
  File "/home/farsana.ka/Documents/Bus Buddy/source_code/web/bus_buddy_back_end/normal_user/views.py", line 172, in list
    return Response(serializer._errors)
UnboundLocalError: local variable 'serializer' referenced before assignment
django.request ERROR 2023-11-14 09:46:10,093 log 46881 139781170259520 Internal Server Error: /user/booking-history
Traceback (most recent call last):
  File "/home/farsana.ka/Documents/Bus Buddy/source_code/web/env/lib/python3.10/site-packages/django/db/models/fields/__init__.py", line 2053, in get_prep_value
    return int(value)
ValueError: invalid literal for int() with base 10: 'undefined'

The above exception was the direct cause of the following exception:

Traceback (most recent call last):
  File "/home/farsana.ka/Documents/Bus Buddy/source_code/web/bus_buddy_back_end/normal_user/views.py", line 160, in list
    queryset = Bookings.objects.filter(user=user_id,status=status)
  File "/home/farsana.ka/Documents/Bus Buddy/source_code/web/env/lib/python3.10/site-packages/django/db/models/manager.py", line 87, in manager_method
    return getattr(self.get_queryset(), name)(*args, **kwargs)
  File "/home/farsana.ka/Documents/Bus Buddy/source_code/web/env/lib/python3.10/site-packages/django/db/models/query.py", line 1436, in filter
    return self._filter_or_exclude(False, args, kwargs)
  File "/home/farsana.ka/Documents/Bus Buddy/source_code/web/env/lib/python3.10/site-packages/django/db/models/query.py", line 1454, in _filter_or_exclude
    clone._filter_or_exclude_inplace(negate, args, kwargs)
  File "/home/farsana.ka/Documents/Bus Buddy/source_code/web/env/lib/python3.10/site-packages/django/db/models/query.py", line 1461, in _filter_or_exclude_inplace
    self._query.add_q(Q(*args, **kwargs))
  File "/home/farsana.ka/Documents/Bus Buddy/source_code/web/env/lib/python3.10/site-packages/django/db/models/sql/query.py", line 1545, in add_q
    clause, _ = self._add_q(q_object, self.used_aliases)
  File "/home/farsana.ka/Documents/Bus Buddy/source_code/web/env/lib/python3.10/site-packages/django/db/models/sql/query.py", line 1576, in _add_q
    child_clause, needed_inner = self.build_filter(
  File "/home/farsana.ka/Documents/Bus Buddy/source_code/web/env/lib/python3.10/site-packages/django/db/models/sql/query.py", line 1491, in build_filter
    condition = self.build_lookup(lookups, col, value)
  File "/home/farsana.ka/Documents/Bus Buddy/source_code/web/env/lib/python3.10/site-packages/django/db/models/sql/query.py", line 1318, in build_lookup
    lookup = lookup_class(lhs, rhs)
  File "/home/farsana.ka/Documents/Bus Buddy/source_code/web/env/lib/python3.10/site-packages/django/db/models/lookups.py", line 27, in __init__
    self.rhs = self.get_prep_lookup()
  File "/home/farsana.ka/Documents/Bus Buddy/source_code/web/env/lib/python3.10/site-packages/django/db/models/lookups.py", line 341, in get_prep_lookup
    return super().get_prep_lookup()
  File "/home/farsana.ka/Documents/Bus Buddy/source_code/web/env/lib/python3.10/site-packages/django/db/models/lookups.py", line 85, in get_prep_lookup
    return self.lhs.output_field.get_prep_value(self.rhs)
  File "/home/farsana.ka/Documents/Bus Buddy/source_code/web/env/lib/python3.10/site-packages/django/db/models/fields/__init__.py", line 2055, in get_prep_value
    raise e.__class__(
ValueError: Field 'status' expected a number but got 'undefined'.

During handling of the above exception, another exception occurred:

Traceback (most recent call last):
  File "/home/farsana.ka/Documents/Bus Buddy/source_code/web/env/lib/python3.10/site-packages/django/core/handlers/exception.py", line 55, in inner
    response = get_response(request)
  File "/home/farsana.ka/Documents/Bus Buddy/source_code/web/env/lib/python3.10/site-packages/django/core/handlers/base.py", line 197, in _get_response
    response = wrapped_callback(request, *callback_args, **callback_kwargs)
  File "/home/farsana.ka/Documents/Bus Buddy/source_code/web/env/lib/python3.10/site-packages/django/views/decorators/csrf.py", line 56, in wrapper_view
    return view_func(*args, **kwargs)
  File "/home/farsana.ka/Documents/Bus Buddy/source_code/web/env/lib/python3.10/site-packages/django/views/generic/base.py", line 104, in view
    return self.dispatch(request, *args, **kwargs)
  File "/home/farsana.ka/Documents/Bus Buddy/source_code/web/env/lib/python3.10/site-packages/rest_framework/views.py", line 509, in dispatch
    response = self.handle_exception(exc)
  File "/home/farsana.ka/Documents/Bus Buddy/source_code/web/env/lib/python3.10/site-packages/rest_framework/views.py", line 469, in handle_exception
    self.raise_uncaught_exception(exc)
  File "/home/farsana.ka/Documents/Bus Buddy/source_code/web/env/lib/python3.10/site-packages/rest_framework/views.py", line 480, in raise_uncaught_exception
    raise exc
  File "/home/farsana.ka/Documents/Bus Buddy/source_code/web/env/lib/python3.10/site-packages/rest_framework/views.py", line 506, in dispatch
    response = handler(request, *args, **kwargs)
  File "/home/farsana.ka/Documents/Bus Buddy/source_code/web/env/lib/python3.10/site-packages/rest_framework/generics.py", line 199, in get
    return self.list(request, *args, **kwargs)
  File "/home/farsana.ka/Documents/Bus Buddy/source_code/web/bus_buddy_back_end/normal_user/views.py", line 172, in list
    return Response(serializer._errors)
UnboundLocalError: local variable 'serializer' referenced before assignment
django.request WARNING 2023-11-14 10:33:34,021 log 55970 140111982356032 Unauthorized: /bus-owner/add-seat-details
django.request WARNING 2023-11-14 10:35:15,168 log 55970 140111982356032 Unauthorized: /bus-owner/add-seat-details
django.request WARNING 2023-11-14 10:36:04,713 log 56454 139736941323840 Unauthorized: /bus-owner/add-seat-details
