django.request ERROR 2023-10-11 07:27:06,322 log 62823 140488380249664 Internal Server Error: /user/registration/
Traceback (most recent call last):
  File "/home/farsana.ka/Documents/Bus Buddy/source_code/web/env/lib/python3.10/site-packages/django/core/handlers/exception.py", line 55, in inner
    response = get_response(request)
  File "/home/farsana.ka/Documents/Bus Buddy/source_code/web/env/lib/python3.10/site-packages/django/core/handlers/base.py", line 197, in _get_response
    response = wrapped_callback(request, *callback_args, **callback_kwargs)
  File "/home/farsana.ka/Documents/Bus Buddy/source_code/web/env/lib/python3.10/site-packages/django/views/decorators/csrf.py", line 56, in wrapper_view
    return view_func(*args, **kwargs)
  File "/home/farsana.ka/Documents/Bus Buddy/source_code/web/env/lib/python3.10/site-packages/django/views/generic/base.py", line 104, in view
    return self.dispatch(request, *args, **kwargs)
  File "/home/farsana.ka/Documents/Bus Buddy/source_code/web/env/lib/python3.10/site-packages/rest_framework/views.py", line 509, in dispatch
    response = self.handle_exception(exc)
  File "/home/farsana.ka/Documents/Bus Buddy/source_code/web/env/lib/python3.10/site-packages/rest_framework/views.py", line 469, in handle_exception
    self.raise_uncaught_exception(exc)
  File "/home/farsana.ka/Documents/Bus Buddy/source_code/web/env/lib/python3.10/site-packages/rest_framework/views.py", line 480, in raise_uncaught_exception
    raise exc
  File "/home/farsana.ka/Documents/Bus Buddy/source_code/web/env/lib/python3.10/site-packages/rest_framework/views.py", line 506, in dispatch
    response = handler(request, *args, **kwargs)
  File "/home/farsana.ka/Documents/Bus Buddy/source_code/web/bus_buddy_back_end/normal_user/views.py", line 15, in post
    if serialized_data.is_valid():
  File "/home/farsana.ka/Documents/Bus Buddy/source_code/web/env/lib/python3.10/site-packages/rest_framework/serializers.py", line 227, in is_valid
    self._validated_data = self.run_validation(self.initial_data)
  File "/home/farsana.ka/Documents/Bus Buddy/source_code/web/env/lib/python3.10/site-packages/rest_framework/serializers.py", line 426, in run_validation
    value = self.to_internal_value(data)
  File "/home/farsana.ka/Documents/Bus Buddy/source_code/web/env/lib/python3.10/site-packages/rest_framework/serializers.py", line 479, in to_internal_value
    for field in fields:
  File "/home/farsana.ka/Documents/Bus Buddy/source_code/web/env/lib/python3.10/site-packages/rest_framework/serializers.py", line 362, in _writable_fields
    for field in self.fields.values():
  File "/home/farsana.ka/Documents/Bus Buddy/source_code/web/env/lib/python3.10/site-packages/django/utils/functional.py", line 57, in __get__
    res = instance.__dict__[self.name] = self.func(instance)
  File "/home/farsana.ka/Documents/Bus Buddy/source_code/web/env/lib/python3.10/site-packages/rest_framework/serializers.py", line 356, in fields
    for key, value in self.get_fields().items():
  File "/home/farsana.ka/Documents/Bus Buddy/source_code/web/env/lib/python3.10/site-packages/rest_framework/serializers.py", line 1027, in get_fields
    assert hasattr(self, 'Meta'), (
AssertionError: Class UserModelSerializer missing "Meta" attribute
django.request ERROR 2023-10-11 08:37:24,738 log 67433 140543587771968 Internal Server Error: /user/registration/
Traceback (most recent call last):
  File "/home/farsana.ka/Documents/Bus Buddy/source_code/web/env/lib/python3.10/site-packages/django/core/handlers/exception.py", line 55, in inner
    response = get_response(request)
  File "/home/farsana.ka/Documents/Bus Buddy/source_code/web/env/lib/python3.10/site-packages/django/core/handlers/base.py", line 197, in _get_response
    response = wrapped_callback(request, *callback_args, **callback_kwargs)
  File "/home/farsana.ka/Documents/Bus Buddy/source_code/web/env/lib/python3.10/site-packages/django/views/decorators/csrf.py", line 56, in wrapper_view
    return view_func(*args, **kwargs)
  File "/home/farsana.ka/Documents/Bus Buddy/source_code/web/env/lib/python3.10/site-packages/django/views/generic/base.py", line 104, in view
    return self.dispatch(request, *args, **kwargs)
  File "/home/farsana.ka/Documents/Bus Buddy/source_code/web/env/lib/python3.10/site-packages/rest_framework/views.py", line 509, in dispatch
    response = self.handle_exception(exc)
  File "/home/farsana.ka/Documents/Bus Buddy/source_code/web/env/lib/python3.10/site-packages/rest_framework/views.py", line 469, in handle_exception
    self.raise_uncaught_exception(exc)
  File "/home/farsana.ka/Documents/Bus Buddy/source_code/web/env/lib/python3.10/site-packages/rest_framework/views.py", line 480, in raise_uncaught_exception
    raise exc
  File "/home/farsana.ka/Documents/Bus Buddy/source_code/web/env/lib/python3.10/site-packages/rest_framework/views.py", line 506, in dispatch
    response = handler(request, *args, **kwargs)
  File "/home/farsana.ka/Documents/Bus Buddy/source_code/web/bus_buddy_back_end/normal_user/views.py", line 15, in post
    if serialized_data.is_valid():
  File "/home/farsana.ka/Documents/Bus Buddy/source_code/web/env/lib/python3.10/site-packages/rest_framework/serializers.py", line 227, in is_valid
    self._validated_data = self.run_validation(self.initial_data)
  File "/home/farsana.ka/Documents/Bus Buddy/source_code/web/env/lib/python3.10/site-packages/rest_framework/serializers.py", line 426, in run_validation
    value = self.to_internal_value(data)
  File "/home/farsana.ka/Documents/Bus Buddy/source_code/web/env/lib/python3.10/site-packages/rest_framework/serializers.py", line 483, in to_internal_value
    validated_value = field.run_validation(primitive_value)
  File "/home/farsana.ka/Documents/Bus Buddy/source_code/web/env/lib/python3.10/site-packages/rest_framework/fields.py", line 548, in run_validation
    self.run_validators(value)
  File "/home/farsana.ka/Documents/Bus Buddy/source_code/web/env/lib/python3.10/site-packages/rest_framework/fields.py", line 562, in run_validators
    validator(value)
TypeError: max_digit() missing 1 required positional argument: 'value'
django.request ERROR 2023-10-11 08:42:35,333 log 67843 140370548614720 Internal Server Error: /user/registration/
Traceback (most recent call last):
  File "/home/farsana.ka/Documents/Bus Buddy/source_code/web/env/lib/python3.10/site-packages/django/core/handlers/exception.py", line 55, in inner
    response = get_response(request)
  File "/home/farsana.ka/Documents/Bus Buddy/source_code/web/env/lib/python3.10/site-packages/django/core/handlers/base.py", line 197, in _get_response
    response = wrapped_callback(request, *callback_args, **callback_kwargs)
  File "/home/farsana.ka/Documents/Bus Buddy/source_code/web/env/lib/python3.10/site-packages/django/views/decorators/csrf.py", line 56, in wrapper_view
    return view_func(*args, **kwargs)
  File "/home/farsana.ka/Documents/Bus Buddy/source_code/web/env/lib/python3.10/site-packages/django/views/generic/base.py", line 104, in view
    return self.dispatch(request, *args, **kwargs)
  File "/home/farsana.ka/Documents/Bus Buddy/source_code/web/env/lib/python3.10/site-packages/rest_framework/views.py", line 509, in dispatch
    response = self.handle_exception(exc)
  File "/home/farsana.ka/Documents/Bus Buddy/source_code/web/env/lib/python3.10/site-packages/rest_framework/views.py", line 469, in handle_exception
    self.raise_uncaught_exception(exc)
  File "/home/farsana.ka/Documents/Bus Buddy/source_code/web/env/lib/python3.10/site-packages/rest_framework/views.py", line 480, in raise_uncaught_exception
    raise exc
  File "/home/farsana.ka/Documents/Bus Buddy/source_code/web/env/lib/python3.10/site-packages/rest_framework/views.py", line 506, in dispatch
    response = handler(request, *args, **kwargs)
  File "/home/farsana.ka/Documents/Bus Buddy/source_code/web/bus_buddy_back_end/normal_user/views.py", line 15, in post
    if serialized_data.is_valid():
  File "/home/farsana.ka/Documents/Bus Buddy/source_code/web/env/lib/python3.10/site-packages/rest_framework/serializers.py", line 227, in is_valid
    self._validated_data = self.run_validation(self.initial_data)
  File "/home/farsana.ka/Documents/Bus Buddy/source_code/web/env/lib/python3.10/site-packages/rest_framework/serializers.py", line 426, in run_validation
    value = self.to_internal_value(data)
  File "/home/farsana.ka/Documents/Bus Buddy/source_code/web/env/lib/python3.10/site-packages/rest_framework/serializers.py", line 483, in to_internal_value
    validated_value = field.run_validation(primitive_value)
  File "/home/farsana.ka/Documents/Bus Buddy/source_code/web/env/lib/python3.10/site-packages/rest_framework/fields.py", line 548, in run_validation
    self.run_validators(value)
  File "/home/farsana.ka/Documents/Bus Buddy/source_code/web/env/lib/python3.10/site-packages/rest_framework/fields.py", line 562, in run_validators
    validator(value)
TypeError: max_digit() missing 1 required positional argument: 'value'
django.request ERROR 2023-10-11 10:38:29,925 log 82101 140478381028928 Internal Server Error: /bus-owner/registration/
Traceback (most recent call last):
  File "/home/farsana.ka/.local/lib/python3.10/site-packages/django/core/handlers/exception.py", line 55, in inner
    response = get_response(request)
  File "/home/farsana.ka/.local/lib/python3.10/site-packages/django/core/handlers/base.py", line 197, in _get_response
    response = wrapped_callback(request, *callback_args, **callback_kwargs)
  File "/home/farsana.ka/.local/lib/python3.10/site-packages/django/views/decorators/csrf.py", line 56, in wrapper_view
    return view_func(*args, **kwargs)
  File "/home/farsana.ka/.local/lib/python3.10/site-packages/django/views/generic/base.py", line 104, in view
    return self.dispatch(request, *args, **kwargs)
  File "/home/farsana.ka/.local/lib/python3.10/site-packages/rest_framework/views.py", line 509, in dispatch
    response = self.handle_exception(exc)
  File "/home/farsana.ka/.local/lib/python3.10/site-packages/rest_framework/views.py", line 469, in handle_exception
    self.raise_uncaught_exception(exc)
  File "/home/farsana.ka/.local/lib/python3.10/site-packages/rest_framework/views.py", line 480, in raise_uncaught_exception
    raise exc
  File "/home/farsana.ka/.local/lib/python3.10/site-packages/rest_framework/views.py", line 506, in dispatch
    response = handler(request, *args, **kwargs)
  File "/home/farsana.ka/Documents/Bus Buddy/source_code/web/bus_buddy_back_end/bus_owner/views.py", line 13, in post
    serialized_data = UMS(data=request_data)
NameError: name 'UMS' is not defined
django.request ERROR 2023-10-18 04:31:34,962 log 12678 140310585634816 Internal Server Error: /bus-owner/update-profile/3
Traceback (most recent call last):
  File "/home/farsana.ka/Documents/Bus Buddy/source_code/web/env/lib/python3.10/site-packages/django/core/handlers/exception.py", line 55, in inner
    response = get_response(request)
  File "/home/farsana.ka/Documents/Bus Buddy/source_code/web/env/lib/python3.10/site-packages/django/core/handlers/base.py", line 197, in _get_response
    response = wrapped_callback(request, *callback_args, **callback_kwargs)
  File "/home/farsana.ka/Documents/Bus Buddy/source_code/web/env/lib/python3.10/site-packages/django/views/decorators/csrf.py", line 56, in wrapper_view
    return view_func(*args, **kwargs)
  File "/home/farsana.ka/Documents/Bus Buddy/source_code/web/env/lib/python3.10/site-packages/django/views/generic/base.py", line 104, in view
    return self.dispatch(request, *args, **kwargs)
  File "/home/farsana.ka/Documents/Bus Buddy/source_code/web/env/lib/python3.10/site-packages/rest_framework/views.py", line 509, in dispatch
    response = self.handle_exception(exc)
  File "/home/farsana.ka/Documents/Bus Buddy/source_code/web/env/lib/python3.10/site-packages/rest_framework/views.py", line 469, in handle_exception
    self.raise_uncaught_exception(exc)
  File "/home/farsana.ka/Documents/Bus Buddy/source_code/web/env/lib/python3.10/site-packages/rest_framework/views.py", line 480, in raise_uncaught_exception
    raise exc
  File "/home/farsana.ka/Documents/Bus Buddy/source_code/web/env/lib/python3.10/site-packages/rest_framework/views.py", line 506, in dispatch
    response = handler(request, *args, **kwargs)
  File "/home/farsana.ka/Documents/Bus Buddy/source_code/web/bus_buddy_back_end/bus_owner/views.py", line 121, in put
    flag=update_all(request, user_id)
  File "/home/farsana.ka/Documents/Bus Buddy/source_code/web/bus_buddy_back_end/bus_owner/views.py", line 59, in update_all
    current_data = User.objects.get(id=user_id)
  File "/home/farsana.ka/Documents/Bus Buddy/source_code/web/env/lib/python3.10/site-packages/django/db/models/manager.py", line 87, in manager_method
    return getattr(self.get_queryset(), name)(*args, **kwargs)
  File "/home/farsana.ka/Documents/Bus Buddy/source_code/web/env/lib/python3.10/site-packages/django/db/models/query.py", line 637, in get
    raise self.model.DoesNotExist(
account_manage.models.User.DoesNotExist: User matching query does not exist.
django.request ERROR 2023-10-18 04:31:35,575 log 12678 140310585634816 Internal Server Error: /bus-owner/update-profile/4
Traceback (most recent call last):
  File "/home/farsana.ka/Documents/Bus Buddy/source_code/web/env/lib/python3.10/site-packages/django/core/handlers/exception.py", line 55, in inner
    response = get_response(request)
  File "/home/farsana.ka/Documents/Bus Buddy/source_code/web/env/lib/python3.10/site-packages/django/core/handlers/base.py", line 197, in _get_response
    response = wrapped_callback(request, *callback_args, **callback_kwargs)
  File "/home/farsana.ka/Documents/Bus Buddy/source_code/web/env/lib/python3.10/site-packages/django/views/decorators/csrf.py", line 56, in wrapper_view
    return view_func(*args, **kwargs)
  File "/home/farsana.ka/Documents/Bus Buddy/source_code/web/env/lib/python3.10/site-packages/django/views/generic/base.py", line 104, in view
    return self.dispatch(request, *args, **kwargs)
  File "/home/farsana.ka/Documents/Bus Buddy/source_code/web/env/lib/python3.10/site-packages/rest_framework/views.py", line 509, in dispatch
    response = self.handle_exception(exc)
  File "/home/farsana.ka/Documents/Bus Buddy/source_code/web/env/lib/python3.10/site-packages/rest_framework/views.py", line 469, in handle_exception
    self.raise_uncaught_exception(exc)
  File "/home/farsana.ka/Documents/Bus Buddy/source_code/web/env/lib/python3.10/site-packages/rest_framework/views.py", line 480, in raise_uncaught_exception
    raise exc
  File "/home/farsana.ka/Documents/Bus Buddy/source_code/web/env/lib/python3.10/site-packages/rest_framework/views.py", line 506, in dispatch
    response = handler(request, *args, **kwargs)
  File "/home/farsana.ka/Documents/Bus Buddy/source_code/web/bus_buddy_back_end/bus_owner/views.py", line 121, in put
    flag=update_all(request, user_id)
  File "/home/farsana.ka/Documents/Bus Buddy/source_code/web/bus_buddy_back_end/bus_owner/views.py", line 59, in update_all
    current_data = User.objects.get(id=user_id)
  File "/home/farsana.ka/Documents/Bus Buddy/source_code/web/env/lib/python3.10/site-packages/django/db/models/manager.py", line 87, in manager_method
    return getattr(self.get_queryset(), name)(*args, **kwargs)
  File "/home/farsana.ka/Documents/Bus Buddy/source_code/web/env/lib/python3.10/site-packages/django/db/models/query.py", line 637, in get
    raise self.model.DoesNotExist(
account_manage.models.User.DoesNotExist: User matching query does not exist.
django.request ERROR 2023-10-18 04:31:35,668 log 12678 140310585634816 Internal Server Error: /bus-owner/update-profile/5
Traceback (most recent call last):
  File "/home/farsana.ka/Documents/Bus Buddy/source_code/web/env/lib/python3.10/site-packages/django/core/handlers/exception.py", line 55, in inner
    response = get_response(request)
  File "/home/farsana.ka/Documents/Bus Buddy/source_code/web/env/lib/python3.10/site-packages/django/core/handlers/base.py", line 197, in _get_response
    response = wrapped_callback(request, *callback_args, **callback_kwargs)
  File "/home/farsana.ka/Documents/Bus Buddy/source_code/web/env/lib/python3.10/site-packages/django/views/decorators/csrf.py", line 56, in wrapper_view
    return view_func(*args, **kwargs)
  File "/home/farsana.ka/Documents/Bus Buddy/source_code/web/env/lib/python3.10/site-packages/django/views/generic/base.py", line 104, in view
    return self.dispatch(request, *args, **kwargs)
  File "/home/farsana.ka/Documents/Bus Buddy/source_code/web/env/lib/python3.10/site-packages/rest_framework/views.py", line 509, in dispatch
    response = self.handle_exception(exc)
  File "/home/farsana.ka/Documents/Bus Buddy/source_code/web/env/lib/python3.10/site-packages/rest_framework/views.py", line 469, in handle_exception
    self.raise_uncaught_exception(exc)
  File "/home/farsana.ka/Documents/Bus Buddy/source_code/web/env/lib/python3.10/site-packages/rest_framework/views.py", line 480, in raise_uncaught_exception
    raise exc
  File "/home/farsana.ka/Documents/Bus Buddy/source_code/web/env/lib/python3.10/site-packages/rest_framework/views.py", line 506, in dispatch
    response = handler(request, *args, **kwargs)
  File "/home/farsana.ka/Documents/Bus Buddy/source_code/web/bus_buddy_back_end/bus_owner/views.py", line 121, in put
    flag=update_all(request, user_id)
  File "/home/farsana.ka/Documents/Bus Buddy/source_code/web/bus_buddy_back_end/bus_owner/views.py", line 59, in update_all
    current_data = User.objects.get(id=user_id)
  File "/home/farsana.ka/Documents/Bus Buddy/source_code/web/env/lib/python3.10/site-packages/django/db/models/manager.py", line 87, in manager_method
    return getattr(self.get_queryset(), name)(*args, **kwargs)
  File "/home/farsana.ka/Documents/Bus Buddy/source_code/web/env/lib/python3.10/site-packages/django/db/models/query.py", line 637, in get
    raise self.model.DoesNotExist(
account_manage.models.User.DoesNotExist: User matching query does not exist.
django.request ERROR 2023-10-18 04:31:35,769 log 12678 140310585634816 Internal Server Error: /bus-owner/update-profile/6
Traceback (most recent call last):
  File "/home/farsana.ka/Documents/Bus Buddy/source_code/web/env/lib/python3.10/site-packages/django/core/handlers/exception.py", line 55, in inner
    response = get_response(request)
  File "/home/farsana.ka/Documents/Bus Buddy/source_code/web/env/lib/python3.10/site-packages/django/core/handlers/base.py", line 197, in _get_response
    response = wrapped_callback(request, *callback_args, **callback_kwargs)
  File "/home/farsana.ka/Documents/Bus Buddy/source_code/web/env/lib/python3.10/site-packages/django/views/decorators/csrf.py", line 56, in wrapper_view
    return view_func(*args, **kwargs)
  File "/home/farsana.ka/Documents/Bus Buddy/source_code/web/env/lib/python3.10/site-packages/django/views/generic/base.py", line 104, in view
    return self.dispatch(request, *args, **kwargs)
  File "/home/farsana.ka/Documents/Bus Buddy/source_code/web/env/lib/python3.10/site-packages/rest_framework/views.py", line 509, in dispatch
    response = self.handle_exception(exc)
  File "/home/farsana.ka/Documents/Bus Buddy/source_code/web/env/lib/python3.10/site-packages/rest_framework/views.py", line 469, in handle_exception
    self.raise_uncaught_exception(exc)
  File "/home/farsana.ka/Documents/Bus Buddy/source_code/web/env/lib/python3.10/site-packages/rest_framework/views.py", line 480, in raise_uncaught_exception
    raise exc
  File "/home/farsana.ka/Documents/Bus Buddy/source_code/web/env/lib/python3.10/site-packages/rest_framework/views.py", line 506, in dispatch
    response = handler(request, *args, **kwargs)
  File "/home/farsana.ka/Documents/Bus Buddy/source_code/web/bus_buddy_back_end/bus_owner/views.py", line 121, in put
    flag=update_all(request, user_id)
  File "/home/farsana.ka/Documents/Bus Buddy/source_code/web/bus_buddy_back_end/bus_owner/views.py", line 59, in update_all
    current_data = User.objects.get(id=user_id)
  File "/home/farsana.ka/Documents/Bus Buddy/source_code/web/env/lib/python3.10/site-packages/django/db/models/manager.py", line 87, in manager_method
    return getattr(self.get_queryset(), name)(*args, **kwargs)
  File "/home/farsana.ka/Documents/Bus Buddy/source_code/web/env/lib/python3.10/site-packages/django/db/models/query.py", line 637, in get
    raise self.model.DoesNotExist(
account_manage.models.User.DoesNotExist: User matching query does not exist.
django.request ERROR 2023-10-20 08:51:26,366 log 41037 139655697682432 Internal Server Error: /bus-owner/update-profile/4
Traceback (most recent call last):
  File "/home/farsana.ka/Documents/Bus Buddy/source_code/web/env/lib/python3.10/site-packages/django/core/handlers/exception.py", line 55, in inner
    response = get_response(request)
  File "/home/farsana.ka/Documents/Bus Buddy/source_code/web/env/lib/python3.10/site-packages/django/core/handlers/base.py", line 197, in _get_response
    response = wrapped_callback(request, *callback_args, **callback_kwargs)
  File "/home/farsana.ka/Documents/Bus Buddy/source_code/web/env/lib/python3.10/site-packages/django/views/decorators/csrf.py", line 56, in wrapper_view
    return view_func(*args, **kwargs)
  File "/home/farsana.ka/Documents/Bus Buddy/source_code/web/env/lib/python3.10/site-packages/django/views/generic/base.py", line 104, in view
    return self.dispatch(request, *args, **kwargs)
  File "/home/farsana.ka/Documents/Bus Buddy/source_code/web/env/lib/python3.10/site-packages/rest_framework/views.py", line 509, in dispatch
    response = self.handle_exception(exc)
  File "/home/farsana.ka/Documents/Bus Buddy/source_code/web/env/lib/python3.10/site-packages/rest_framework/views.py", line 469, in handle_exception
    self.raise_uncaught_exception(exc)
  File "/home/farsana.ka/Documents/Bus Buddy/source_code/web/env/lib/python3.10/site-packages/rest_framework/views.py", line 480, in raise_uncaught_exception
    raise exc
  File "/home/farsana.ka/Documents/Bus Buddy/source_code/web/env/lib/python3.10/site-packages/rest_framework/views.py", line 506, in dispatch
    response = handler(request, *args, **kwargs)
  File "/home/farsana.ka/Documents/Bus Buddy/source_code/web/bus_buddy_back_end/bus_owner/views.py", line 121, in put
    flag=update_all(request, user_id)
  File "/home/farsana.ka/Documents/Bus Buddy/source_code/web/bus_buddy_back_end/bus_owner/views.py", line 59, in update_all
    current_data = User.objects.get(id=user_id)
  File "/home/farsana.ka/Documents/Bus Buddy/source_code/web/env/lib/python3.10/site-packages/django/db/models/manager.py", line 87, in manager_method
    return getattr(self.get_queryset(), name)(*args, **kwargs)
  File "/home/farsana.ka/Documents/Bus Buddy/source_code/web/env/lib/python3.10/site-packages/django/db/models/query.py", line 637, in get
    raise self.model.DoesNotExist(
account_manage.models.User.DoesNotExist: User matching query does not exist.
django.request ERROR 2023-10-20 08:51:26,531 log 41037 139655697682432 Internal Server Error: /bus-owner/update-profile/5
Traceback (most recent call last):
  File "/home/farsana.ka/Documents/Bus Buddy/source_code/web/env/lib/python3.10/site-packages/django/core/handlers/exception.py", line 55, in inner
    response = get_response(request)
  File "/home/farsana.ka/Documents/Bus Buddy/source_code/web/env/lib/python3.10/site-packages/django/core/handlers/base.py", line 197, in _get_response
    response = wrapped_callback(request, *callback_args, **callback_kwargs)
  File "/home/farsana.ka/Documents/Bus Buddy/source_code/web/env/lib/python3.10/site-packages/django/views/decorators/csrf.py", line 56, in wrapper_view
    return view_func(*args, **kwargs)
  File "/home/farsana.ka/Documents/Bus Buddy/source_code/web/env/lib/python3.10/site-packages/django/views/generic/base.py", line 104, in view
    return self.dispatch(request, *args, **kwargs)
  File "/home/farsana.ka/Documents/Bus Buddy/source_code/web/env/lib/python3.10/site-packages/rest_framework/views.py", line 509, in dispatch
    response = self.handle_exception(exc)
  File "/home/farsana.ka/Documents/Bus Buddy/source_code/web/env/lib/python3.10/site-packages/rest_framework/views.py", line 469, in handle_exception
    self.raise_uncaught_exception(exc)
  File "/home/farsana.ka/Documents/Bus Buddy/source_code/web/env/lib/python3.10/site-packages/rest_framework/views.py", line 480, in raise_uncaught_exception
    raise exc
  File "/home/farsana.ka/Documents/Bus Buddy/source_code/web/env/lib/python3.10/site-packages/rest_framework/views.py", line 506, in dispatch
    response = handler(request, *args, **kwargs)
  File "/home/farsana.ka/Documents/Bus Buddy/source_code/web/bus_buddy_back_end/bus_owner/views.py", line 121, in put
    flag=update_all(request, user_id)
  File "/home/farsana.ka/Documents/Bus Buddy/source_code/web/bus_buddy_back_end/bus_owner/views.py", line 59, in update_all
    current_data = User.objects.get(id=user_id)
  File "/home/farsana.ka/Documents/Bus Buddy/source_code/web/env/lib/python3.10/site-packages/django/db/models/manager.py", line 87, in manager_method
    return getattr(self.get_queryset(), name)(*args, **kwargs)
  File "/home/farsana.ka/Documents/Bus Buddy/source_code/web/env/lib/python3.10/site-packages/django/db/models/query.py", line 637, in get
    raise self.model.DoesNotExist(
account_manage.models.User.DoesNotExist: User matching query does not exist.
django.request ERROR 2023-10-20 08:51:26,654 log 41037 139655697682432 Internal Server Error: /bus-owner/update-profile/6
Traceback (most recent call last):
  File "/home/farsana.ka/Documents/Bus Buddy/source_code/web/env/lib/python3.10/site-packages/django/core/handlers/exception.py", line 55, in inner
    response = get_response(request)
  File "/home/farsana.ka/Documents/Bus Buddy/source_code/web/env/lib/python3.10/site-packages/django/core/handlers/base.py", line 197, in _get_response
    response = wrapped_callback(request, *callback_args, **callback_kwargs)
  File "/home/farsana.ka/Documents/Bus Buddy/source_code/web/env/lib/python3.10/site-packages/django/views/decorators/csrf.py", line 56, in wrapper_view
    return view_func(*args, **kwargs)
  File "/home/farsana.ka/Documents/Bus Buddy/source_code/web/env/lib/python3.10/site-packages/django/views/generic/base.py", line 104, in view
    return self.dispatch(request, *args, **kwargs)
  File "/home/farsana.ka/Documents/Bus Buddy/source_code/web/env/lib/python3.10/site-packages/rest_framework/views.py", line 509, in dispatch
    response = self.handle_exception(exc)
  File "/home/farsana.ka/Documents/Bus Buddy/source_code/web/env/lib/python3.10/site-packages/rest_framework/views.py", line 469, in handle_exception
    self.raise_uncaught_exception(exc)
  File "/home/farsana.ka/Documents/Bus Buddy/source_code/web/env/lib/python3.10/site-packages/rest_framework/views.py", line 480, in raise_uncaught_exception
    raise exc
  File "/home/farsana.ka/Documents/Bus Buddy/source_code/web/env/lib/python3.10/site-packages/rest_framework/views.py", line 506, in dispatch
    response = handler(request, *args, **kwargs)
  File "/home/farsana.ka/Documents/Bus Buddy/source_code/web/bus_buddy_back_end/bus_owner/views.py", line 121, in put
    flag=update_all(request, user_id)
  File "/home/farsana.ka/Documents/Bus Buddy/source_code/web/bus_buddy_back_end/bus_owner/views.py", line 59, in update_all
    current_data = User.objects.get(id=user_id)
  File "/home/farsana.ka/Documents/Bus Buddy/source_code/web/env/lib/python3.10/site-packages/django/db/models/manager.py", line 87, in manager_method
    return getattr(self.get_queryset(), name)(*args, **kwargs)
  File "/home/farsana.ka/Documents/Bus Buddy/source_code/web/env/lib/python3.10/site-packages/django/db/models/query.py", line 637, in get
    raise self.model.DoesNotExist(
account_manage.models.User.DoesNotExist: User matching query does not exist.
django.request ERROR 2023-10-20 08:51:26,832 log 41037 139655697682432 Internal Server Error: /bus-owner/update-profile/7
Traceback (most recent call last):
  File "/home/farsana.ka/Documents/Bus Buddy/source_code/web/env/lib/python3.10/site-packages/django/core/handlers/exception.py", line 55, in inner
    response = get_response(request)
  File "/home/farsana.ka/Documents/Bus Buddy/source_code/web/env/lib/python3.10/site-packages/django/core/handlers/base.py", line 197, in _get_response
    response = wrapped_callback(request, *callback_args, **callback_kwargs)
  File "/home/farsana.ka/Documents/Bus Buddy/source_code/web/env/lib/python3.10/site-packages/django/views/decorators/csrf.py", line 56, in wrapper_view
    return view_func(*args, **kwargs)
  File "/home/farsana.ka/Documents/Bus Buddy/source_code/web/env/lib/python3.10/site-packages/django/views/generic/base.py", line 104, in view
    return self.dispatch(request, *args, **kwargs)
  File "/home/farsana.ka/Documents/Bus Buddy/source_code/web/env/lib/python3.10/site-packages/rest_framework/views.py", line 509, in dispatch
    response = self.handle_exception(exc)
  File "/home/farsana.ka/Documents/Bus Buddy/source_code/web/env/lib/python3.10/site-packages/rest_framework/views.py", line 469, in handle_exception
    self.raise_uncaught_exception(exc)
  File "/home/farsana.ka/Documents/Bus Buddy/source_code/web/env/lib/python3.10/site-packages/rest_framework/views.py", line 480, in raise_uncaught_exception
    raise exc
  File "/home/farsana.ka/Documents/Bus Buddy/source_code/web/env/lib/python3.10/site-packages/rest_framework/views.py", line 506, in dispatch
    response = handler(request, *args, **kwargs)
  File "/home/farsana.ka/Documents/Bus Buddy/source_code/web/bus_buddy_back_end/bus_owner/views.py", line 121, in put
    flag=update_all(request, user_id)
  File "/home/farsana.ka/Documents/Bus Buddy/source_code/web/bus_buddy_back_end/bus_owner/views.py", line 59, in update_all
    current_data = User.objects.get(id=user_id)
  File "/home/farsana.ka/Documents/Bus Buddy/source_code/web/env/lib/python3.10/site-packages/django/db/models/manager.py", line 87, in manager_method
    return getattr(self.get_queryset(), name)(*args, **kwargs)
  File "/home/farsana.ka/Documents/Bus Buddy/source_code/web/env/lib/python3.10/site-packages/django/db/models/query.py", line 637, in get
    raise self.model.DoesNotExist(
account_manage.models.User.DoesNotExist: User matching query does not exist.
django.request ERROR 2023-10-20 08:58:42,564 log 41487 140045926572032 Internal Server Error: /bus-owner/update-profile/1
Traceback (most recent call last):
  File "/home/farsana.ka/Documents/Bus Buddy/source_code/web/env/lib/python3.10/site-packages/django/core/handlers/exception.py", line 55, in inner
    response = get_response(request)
  File "/home/farsana.ka/Documents/Bus Buddy/source_code/web/env/lib/python3.10/site-packages/django/core/handlers/base.py", line 197, in _get_response
    response = wrapped_callback(request, *callback_args, **callback_kwargs)
  File "/home/farsana.ka/Documents/Bus Buddy/source_code/web/env/lib/python3.10/site-packages/django/views/decorators/csrf.py", line 56, in wrapper_view
    return view_func(*args, **kwargs)
  File "/home/farsana.ka/Documents/Bus Buddy/source_code/web/env/lib/python3.10/site-packages/django/views/generic/base.py", line 104, in view
    return self.dispatch(request, *args, **kwargs)
  File "/home/farsana.ka/Documents/Bus Buddy/source_code/web/env/lib/python3.10/site-packages/rest_framework/views.py", line 509, in dispatch
    response = self.handle_exception(exc)
  File "/home/farsana.ka/Documents/Bus Buddy/source_code/web/env/lib/python3.10/site-packages/rest_framework/views.py", line 469, in handle_exception
    self.raise_uncaught_exception(exc)
  File "/home/farsana.ka/Documents/Bus Buddy/source_code/web/env/lib/python3.10/site-packages/rest_framework/views.py", line 480, in raise_uncaught_exception
    raise exc
  File "/home/farsana.ka/Documents/Bus Buddy/source_code/web/env/lib/python3.10/site-packages/rest_framework/views.py", line 506, in dispatch
    response = handler(request, *args, **kwargs)
  File "/home/farsana.ka/Documents/Bus Buddy/source_code/web/bus_buddy_back_end/bus_owner/views.py", line 109, in put
    response=update_all(request, user_id)
  File "/home/farsana.ka/Documents/Bus Buddy/source_code/web/bus_buddy_back_end/bus_owner/views.py", line 59, in update_all
    current_data = User.objects.get(id=user_id)
  File "/home/farsana.ka/Documents/Bus Buddy/source_code/web/env/lib/python3.10/site-packages/django/db/models/manager.py", line 87, in manager_method
    return getattr(self.get_queryset(), name)(*args, **kwargs)
  File "/home/farsana.ka/Documents/Bus Buddy/source_code/web/env/lib/python3.10/site-packages/django/db/models/query.py", line 637, in get
    raise self.model.DoesNotExist(
account_manage.models.User.DoesNotExist: User matching query does not exist.
django.request ERROR 2023-10-20 12:20:58,690 log 52600 140479656097344 Internal Server Error: /user/update-profile/31
Traceback (most recent call last):
  File "/home/farsana.ka/Documents/Bus Buddy/source_code/web/env/lib/python3.10/site-packages/django/core/handlers/exception.py", line 55, in inner
    response = get_response(request)
  File "/home/farsana.ka/Documents/Bus Buddy/source_code/web/env/lib/python3.10/site-packages/django/core/handlers/base.py", line 220, in _get_response
    response = response.render()
  File "/home/farsana.ka/Documents/Bus Buddy/source_code/web/env/lib/python3.10/site-packages/django/template/response.py", line 114, in render
    self.content = self.rendered_content
  File "/home/farsana.ka/Documents/Bus Buddy/source_code/web/env/lib/python3.10/site-packages/rest_framework/response.py", line 70, in rendered_content
    ret = renderer.render(self.data, accepted_media_type, context)
  File "/home/farsana.ka/Documents/Bus Buddy/source_code/web/env/lib/python3.10/site-packages/rest_framework/renderers.py", line 99, in render
    ret = json.dumps(
  File "/home/farsana.ka/Documents/Bus Buddy/source_code/web/env/lib/python3.10/site-packages/rest_framework/utils/json.py", line 25, in dumps
    return json.dumps(*args, **kwargs)
  File "/usr/lib/python3.10/json/__init__.py", line 238, in dumps
    **kw).encode(obj)
  File "/usr/lib/python3.10/json/encoder.py", line 199, in encode
    chunks = self.iterencode(o, _one_shot=True)
  File "/usr/lib/python3.10/json/encoder.py", line 257, in iterencode
    return _iterencode(o, 0)
  File "/home/farsana.ka/Documents/Bus Buddy/source_code/web/env/lib/python3.10/site-packages/rest_framework/utils/encoders.py", line 67, in default
    return super().default(obj)
  File "/usr/lib/python3.10/json/encoder.py", line 179, in default
    raise TypeError(f'Object of type {o.__class__.__name__} '
TypeError: Object of type ListSerializer is not JSON serializable
django.request ERROR 2023-10-20 12:23:30,934 log 52600 140479656097344 Internal Server Error: /user/update-profile/31
Traceback (most recent call last):
  File "/home/farsana.ka/Documents/Bus Buddy/source_code/web/env/lib/python3.10/site-packages/django/core/handlers/exception.py", line 55, in inner
    response = get_response(request)
  File "/home/farsana.ka/Documents/Bus Buddy/source_code/web/env/lib/python3.10/site-packages/django/core/handlers/base.py", line 220, in _get_response
    response = response.render()
  File "/home/farsana.ka/Documents/Bus Buddy/source_code/web/env/lib/python3.10/site-packages/django/template/response.py", line 114, in render
    self.content = self.rendered_content
  File "/home/farsana.ka/Documents/Bus Buddy/source_code/web/env/lib/python3.10/site-packages/rest_framework/response.py", line 70, in rendered_content
    ret = renderer.render(self.data, accepted_media_type, context)
  File "/home/farsana.ka/Documents/Bus Buddy/source_code/web/env/lib/python3.10/site-packages/rest_framework/renderers.py", line 99, in render
    ret = json.dumps(
  File "/home/farsana.ka/Documents/Bus Buddy/source_code/web/env/lib/python3.10/site-packages/rest_framework/utils/json.py", line 25, in dumps
    return json.dumps(*args, **kwargs)
  File "/usr/lib/python3.10/json/__init__.py", line 238, in dumps
    **kw).encode(obj)
  File "/usr/lib/python3.10/json/encoder.py", line 199, in encode
    chunks = self.iterencode(o, _one_shot=True)
  File "/usr/lib/python3.10/json/encoder.py", line 257, in iterencode
    return _iterencode(o, 0)
  File "/home/farsana.ka/Documents/Bus Buddy/source_code/web/env/lib/python3.10/site-packages/rest_framework/utils/encoders.py", line 67, in default
    return super().default(obj)
  File "/usr/lib/python3.10/json/encoder.py", line 179, in default
    raise TypeError(f'Object of type {o.__class__.__name__} '
TypeError: Object of type ListSerializer is not JSON serializable
django.request ERROR 2023-10-20 12:23:36,104 log 52600 140479656097344 Internal Server Error: /user/update-profile/31
Traceback (most recent call last):
  File "/home/farsana.ka/Documents/Bus Buddy/source_code/web/env/lib/python3.10/site-packages/django/core/handlers/exception.py", line 55, in inner
    response = get_response(request)
  File "/home/farsana.ka/Documents/Bus Buddy/source_code/web/env/lib/python3.10/site-packages/django/core/handlers/base.py", line 220, in _get_response
    response = response.render()
  File "/home/farsana.ka/Documents/Bus Buddy/source_code/web/env/lib/python3.10/site-packages/django/template/response.py", line 114, in render
    self.content = self.rendered_content
  File "/home/farsana.ka/Documents/Bus Buddy/source_code/web/env/lib/python3.10/site-packages/rest_framework/response.py", line 70, in rendered_content
    ret = renderer.render(self.data, accepted_media_type, context)
  File "/home/farsana.ka/Documents/Bus Buddy/source_code/web/env/lib/python3.10/site-packages/rest_framework/renderers.py", line 99, in render
    ret = json.dumps(
  File "/home/farsana.ka/Documents/Bus Buddy/source_code/web/env/lib/python3.10/site-packages/rest_framework/utils/json.py", line 25, in dumps
    return json.dumps(*args, **kwargs)
  File "/usr/lib/python3.10/json/__init__.py", line 238, in dumps
    **kw).encode(obj)
  File "/usr/lib/python3.10/json/encoder.py", line 199, in encode
    chunks = self.iterencode(o, _one_shot=True)
  File "/usr/lib/python3.10/json/encoder.py", line 257, in iterencode
    return _iterencode(o, 0)
  File "/home/farsana.ka/Documents/Bus Buddy/source_code/web/env/lib/python3.10/site-packages/rest_framework/utils/encoders.py", line 67, in default
    return super().default(obj)
  File "/usr/lib/python3.10/json/encoder.py", line 179, in default
    raise TypeError(f'Object of type {o.__class__.__name__} '
TypeError: Object of type ListSerializer is not JSON serializable
django.request ERROR 2023-10-20 12:24:51,872 log 53114 140135549101632 Internal Server Error: /user/update-profile/31
Traceback (most recent call last):
  File "/home/farsana.ka/Documents/Bus Buddy/source_code/web/env/lib/python3.10/site-packages/django/core/handlers/exception.py", line 55, in inner
    response = get_response(request)
  File "/home/farsana.ka/Documents/Bus Buddy/source_code/web/env/lib/python3.10/site-packages/django/core/handlers/base.py", line 220, in _get_response
    response = response.render()
  File "/home/farsana.ka/Documents/Bus Buddy/source_code/web/env/lib/python3.10/site-packages/django/template/response.py", line 114, in render
    self.content = self.rendered_content
  File "/home/farsana.ka/Documents/Bus Buddy/source_code/web/env/lib/python3.10/site-packages/rest_framework/response.py", line 70, in rendered_content
    ret = renderer.render(self.data, accepted_media_type, context)
  File "/home/farsana.ka/Documents/Bus Buddy/source_code/web/env/lib/python3.10/site-packages/rest_framework/renderers.py", line 99, in render
    ret = json.dumps(
  File "/home/farsana.ka/Documents/Bus Buddy/source_code/web/env/lib/python3.10/site-packages/rest_framework/utils/json.py", line 25, in dumps
    return json.dumps(*args, **kwargs)
  File "/usr/lib/python3.10/json/__init__.py", line 238, in dumps
    **kw).encode(obj)
  File "/usr/lib/python3.10/json/encoder.py", line 199, in encode
    chunks = self.iterencode(o, _one_shot=True)
  File "/usr/lib/python3.10/json/encoder.py", line 257, in iterencode
    return _iterencode(o, 0)
  File "/home/farsana.ka/Documents/Bus Buddy/source_code/web/env/lib/python3.10/site-packages/rest_framework/utils/encoders.py", line 67, in default
    return super().default(obj)
  File "/usr/lib/python3.10/json/encoder.py", line 179, in default
    raise TypeError(f'Object of type {o.__class__.__name__} '
TypeError: Object of type User is not JSON serializable
django.request ERROR 2023-10-20 12:29:43,777 log 53386 140388583073344 Internal Server Error: /user/update-profile/31
Traceback (most recent call last):
  File "/home/farsana.ka/Documents/Bus Buddy/source_code/web/env/lib/python3.10/site-packages/django/core/handlers/exception.py", line 55, in inner
    response = get_response(request)
  File "/home/farsana.ka/Documents/Bus Buddy/source_code/web/env/lib/python3.10/site-packages/django/core/handlers/base.py", line 197, in _get_response
    response = wrapped_callback(request, *callback_args, **callback_kwargs)
  File "/home/farsana.ka/Documents/Bus Buddy/source_code/web/env/lib/python3.10/site-packages/django/views/decorators/csrf.py", line 56, in wrapper_view
    return view_func(*args, **kwargs)
  File "/home/farsana.ka/Documents/Bus Buddy/source_code/web/env/lib/python3.10/site-packages/django/views/generic/base.py", line 104, in view
    return self.dispatch(request, *args, **kwargs)
  File "/home/farsana.ka/Documents/Bus Buddy/source_code/web/env/lib/python3.10/site-packages/rest_framework/views.py", line 509, in dispatch
    response = self.handle_exception(exc)
  File "/home/farsana.ka/Documents/Bus Buddy/source_code/web/env/lib/python3.10/site-packages/rest_framework/views.py", line 469, in handle_exception
    self.raise_uncaught_exception(exc)
  File "/home/farsana.ka/Documents/Bus Buddy/source_code/web/env/lib/python3.10/site-packages/rest_framework/views.py", line 480, in raise_uncaught_exception
    raise exc
  File "/home/farsana.ka/Documents/Bus Buddy/source_code/web/env/lib/python3.10/site-packages/rest_framework/views.py", line 506, in dispatch
    response = handler(request, *args, **kwargs)
  File "/home/farsana.ka/Documents/Bus Buddy/source_code/web/bus_buddy_back_end/normal_user/views.py", line 92, in get
    return Response(serialized_data)
  File "/home/farsana.ka/Documents/Bus Buddy/source_code/web/env/lib/python3.10/site-packages/rest_framework/response.py", line 38, in __init__
    raise AssertionError(msg)
AssertionError: You passed a Serializer instance as data, but probably meant to pass serialized `.data` or `.error`. representation.
django.request ERROR 2023-10-20 12:32:46,140 log 53490 139655534077504 Internal Server Error: /user/update-profile/31
Traceback (most recent call last):
  File "/home/farsana.ka/Documents/Bus Buddy/source_code/web/env/lib/python3.10/site-packages/django/core/handlers/exception.py", line 55, in inner
    response = get_response(request)
  File "/home/farsana.ka/Documents/Bus Buddy/source_code/web/env/lib/python3.10/site-packages/django/core/handlers/base.py", line 197, in _get_response
    response = wrapped_callback(request, *callback_args, **callback_kwargs)
  File "/home/farsana.ka/Documents/Bus Buddy/source_code/web/env/lib/python3.10/site-packages/django/views/decorators/csrf.py", line 56, in wrapper_view
    return view_func(*args, **kwargs)
  File "/home/farsana.ka/Documents/Bus Buddy/source_code/web/env/lib/python3.10/site-packages/django/views/generic/base.py", line 104, in view
    return self.dispatch(request, *args, **kwargs)
  File "/home/farsana.ka/Documents/Bus Buddy/source_code/web/env/lib/python3.10/site-packages/rest_framework/views.py", line 509, in dispatch
    response = self.handle_exception(exc)
  File "/home/farsana.ka/Documents/Bus Buddy/source_code/web/env/lib/python3.10/site-packages/rest_framework/views.py", line 469, in handle_exception
    self.raise_uncaught_exception(exc)
  File "/home/farsana.ka/Documents/Bus Buddy/source_code/web/env/lib/python3.10/site-packages/rest_framework/views.py", line 480, in raise_uncaught_exception
    raise exc
  File "/home/farsana.ka/Documents/Bus Buddy/source_code/web/env/lib/python3.10/site-packages/rest_framework/views.py", line 506, in dispatch
    response = handler(request, *args, **kwargs)
  File "/home/farsana.ka/Documents/Bus Buddy/source_code/web/bus_buddy_back_end/normal_user/views.py", line 92, in get
    return Response(serialized_data)
  File "/home/farsana.ka/Documents/Bus Buddy/source_code/web/env/lib/python3.10/site-packages/rest_framework/response.py", line 38, in __init__
    raise AssertionError(msg)
AssertionError: You passed a Serializer instance as data, but probably meant to pass serialized `.data` or `.error`. representation.
