django.request ERROR 2023-10-13 14:25:45,777 log 173427 140074066862080 Internal Server Error: /user/update-profile/1
Traceback (most recent call last):
  File "/home/farsana.ka/.local/lib/python3.10/site-packages/django/core/handlers/exception.py", line 55, in inner
    response = get_response(request)
  File "/home/farsana.ka/.local/lib/python3.10/site-packages/django/core/handlers/base.py", line 197, in _get_response
    response = wrapped_callback(request, *callback_args, **callback_kwargs)
  File "/home/farsana.ka/.local/lib/python3.10/site-packages/django/views/decorators/csrf.py", line 56, in wrapper_view
    return view_func(*args, **kwargs)
  File "/home/farsana.ka/.local/lib/python3.10/site-packages/django/views/generic/base.py", line 104, in view
    return self.dispatch(request, *args, **kwargs)
  File "/home/farsana.ka/.local/lib/python3.10/site-packages/rest_framework/views.py", line 509, in dispatch
    response = self.handle_exception(exc)
  File "/home/farsana.ka/.local/lib/python3.10/site-packages/rest_framework/views.py", line 469, in handle_exception
    self.raise_uncaught_exception(exc)
  File "/home/farsana.ka/.local/lib/python3.10/site-packages/rest_framework/views.py", line 480, in raise_uncaught_exception
    raise exc
  File "/home/farsana.ka/.local/lib/python3.10/site-packages/rest_framework/views.py", line 506, in dispatch
    response = handler(request, *args, **kwargs)
  File "/home/farsana.ka/Documents/Bus Buddy/source_code/web/bus_buddy_back_end/normal_user/views.py", line 114, in put
    flag=update_all(request, id)
  File "/home/farsana.ka/Documents/Bus Buddy/source_code/web/bus_buddy_back_end/normal_user/views.py", line 56, in update_all
    current_data = User.objects.get(id=user_id)
  File "/home/farsana.ka/.local/lib/python3.10/site-packages/django/db/models/manager.py", line 87, in manager_method
    return getattr(self.get_queryset(), name)(*args, **kwargs)
  File "/home/farsana.ka/.local/lib/python3.10/site-packages/django/db/models/query.py", line 637, in get
    raise self.model.DoesNotExist(
account_manage.models.User.DoesNotExist: User matching query does not exist.
django.request ERROR 2023-10-13 14:25:46,017 log 173427 140074066862080 Internal Server Error: /user/update-profile/1
Traceback (most recent call last):
  File "/home/farsana.ka/.local/lib/python3.10/site-packages/django/core/handlers/exception.py", line 55, in inner
    response = get_response(request)
  File "/home/farsana.ka/.local/lib/python3.10/site-packages/django/core/handlers/base.py", line 197, in _get_response
    response = wrapped_callback(request, *callback_args, **callback_kwargs)
  File "/home/farsana.ka/.local/lib/python3.10/site-packages/django/views/decorators/csrf.py", line 56, in wrapper_view
    return view_func(*args, **kwargs)
  File "/home/farsana.ka/.local/lib/python3.10/site-packages/django/views/generic/base.py", line 104, in view
    return self.dispatch(request, *args, **kwargs)
  File "/home/farsana.ka/.local/lib/python3.10/site-packages/rest_framework/views.py", line 509, in dispatch
    response = self.handle_exception(exc)
  File "/home/farsana.ka/.local/lib/python3.10/site-packages/rest_framework/views.py", line 469, in handle_exception
    self.raise_uncaught_exception(exc)
  File "/home/farsana.ka/.local/lib/python3.10/site-packages/rest_framework/views.py", line 480, in raise_uncaught_exception
    raise exc
  File "/home/farsana.ka/.local/lib/python3.10/site-packages/rest_framework/views.py", line 506, in dispatch
    response = handler(request, *args, **kwargs)
  File "/home/farsana.ka/Documents/Bus Buddy/source_code/web/bus_buddy_back_end/normal_user/views.py", line 114, in put
    flag=update_all(request, id)
  File "/home/farsana.ka/Documents/Bus Buddy/source_code/web/bus_buddy_back_end/normal_user/views.py", line 56, in update_all
    current_data = User.objects.get(id=user_id)
  File "/home/farsana.ka/.local/lib/python3.10/site-packages/django/db/models/manager.py", line 87, in manager_method
    return getattr(self.get_queryset(), name)(*args, **kwargs)
  File "/home/farsana.ka/.local/lib/python3.10/site-packages/django/db/models/query.py", line 637, in get
    raise self.model.DoesNotExist(
account_manage.models.User.DoesNotExist: User matching query does not exist.
django.request ERROR 2023-10-13 14:25:46,047 log 173427 140074066862080 Internal Server Error: /user/update-profile/1
Traceback (most recent call last):
  File "/home/farsana.ka/.local/lib/python3.10/site-packages/django/core/handlers/exception.py", line 55, in inner
    response = get_response(request)
  File "/home/farsana.ka/.local/lib/python3.10/site-packages/django/core/handlers/base.py", line 197, in _get_response
    response = wrapped_callback(request, *callback_args, **callback_kwargs)
  File "/home/farsana.ka/.local/lib/python3.10/site-packages/django/views/decorators/csrf.py", line 56, in wrapper_view
    return view_func(*args, **kwargs)
  File "/home/farsana.ka/.local/lib/python3.10/site-packages/django/views/generic/base.py", line 104, in view
    return self.dispatch(request, *args, **kwargs)
  File "/home/farsana.ka/.local/lib/python3.10/site-packages/rest_framework/views.py", line 509, in dispatch
    response = self.handle_exception(exc)
  File "/home/farsana.ka/.local/lib/python3.10/site-packages/rest_framework/views.py", line 469, in handle_exception
    self.raise_uncaught_exception(exc)
  File "/home/farsana.ka/.local/lib/python3.10/site-packages/rest_framework/views.py", line 480, in raise_uncaught_exception
    raise exc
  File "/home/farsana.ka/.local/lib/python3.10/site-packages/rest_framework/views.py", line 506, in dispatch
    response = handler(request, *args, **kwargs)
  File "/home/farsana.ka/Documents/Bus Buddy/source_code/web/bus_buddy_back_end/normal_user/views.py", line 114, in put
    flag=update_all(request, id)
  File "/home/farsana.ka/Documents/Bus Buddy/source_code/web/bus_buddy_back_end/normal_user/views.py", line 56, in update_all
    current_data = User.objects.get(id=user_id)
  File "/home/farsana.ka/.local/lib/python3.10/site-packages/django/db/models/manager.py", line 87, in manager_method
    return getattr(self.get_queryset(), name)(*args, **kwargs)
  File "/home/farsana.ka/.local/lib/python3.10/site-packages/django/db/models/query.py", line 637, in get
    raise self.model.DoesNotExist(
account_manage.models.User.DoesNotExist: User matching query does not exist.
django.request ERROR 2023-10-13 14:25:46,064 log 173427 140074066862080 Internal Server Error: /user/update-profile/1
Traceback (most recent call last):
  File "/home/farsana.ka/.local/lib/python3.10/site-packages/django/core/handlers/exception.py", line 55, in inner
    response = get_response(request)
  File "/home/farsana.ka/.local/lib/python3.10/site-packages/django/core/handlers/base.py", line 197, in _get_response
    response = wrapped_callback(request, *callback_args, **callback_kwargs)
  File "/home/farsana.ka/.local/lib/python3.10/site-packages/django/views/decorators/csrf.py", line 56, in wrapper_view
    return view_func(*args, **kwargs)
  File "/home/farsana.ka/.local/lib/python3.10/site-packages/django/views/generic/base.py", line 104, in view
    return self.dispatch(request, *args, **kwargs)
  File "/home/farsana.ka/.local/lib/python3.10/site-packages/rest_framework/views.py", line 509, in dispatch
    response = self.handle_exception(exc)
  File "/home/farsana.ka/.local/lib/python3.10/site-packages/rest_framework/views.py", line 469, in handle_exception
    self.raise_uncaught_exception(exc)
  File "/home/farsana.ka/.local/lib/python3.10/site-packages/rest_framework/views.py", line 480, in raise_uncaught_exception
    raise exc
  File "/home/farsana.ka/.local/lib/python3.10/site-packages/rest_framework/views.py", line 506, in dispatch
    response = handler(request, *args, **kwargs)
  File "/home/farsana.ka/Documents/Bus Buddy/source_code/web/bus_buddy_back_end/normal_user/views.py", line 114, in put
    flag=update_all(request, id)
  File "/home/farsana.ka/Documents/Bus Buddy/source_code/web/bus_buddy_back_end/normal_user/views.py", line 56, in update_all
    current_data = User.objects.get(id=user_id)
  File "/home/farsana.ka/.local/lib/python3.10/site-packages/django/db/models/manager.py", line 87, in manager_method
    return getattr(self.get_queryset(), name)(*args, **kwargs)
  File "/home/farsana.ka/.local/lib/python3.10/site-packages/django/db/models/query.py", line 637, in get
    raise self.model.DoesNotExist(
account_manage.models.User.DoesNotExist: User matching query does not exist.
django.request ERROR 2023-10-13 14:25:46,098 log 173427 140074066862080 Internal Server Error: /user/update-profile/1
Traceback (most recent call last):
  File "/home/farsana.ka/.local/lib/python3.10/site-packages/django/core/handlers/exception.py", line 55, in inner
    response = get_response(request)
  File "/home/farsana.ka/.local/lib/python3.10/site-packages/django/core/handlers/base.py", line 197, in _get_response
    response = wrapped_callback(request, *callback_args, **callback_kwargs)
  File "/home/farsana.ka/.local/lib/python3.10/site-packages/django/views/decorators/csrf.py", line 56, in wrapper_view
    return view_func(*args, **kwargs)
  File "/home/farsana.ka/.local/lib/python3.10/site-packages/django/views/generic/base.py", line 104, in view
    return self.dispatch(request, *args, **kwargs)
  File "/home/farsana.ka/.local/lib/python3.10/site-packages/rest_framework/views.py", line 509, in dispatch
    response = self.handle_exception(exc)
  File "/home/farsana.ka/.local/lib/python3.10/site-packages/rest_framework/views.py", line 469, in handle_exception
    self.raise_uncaught_exception(exc)
  File "/home/farsana.ka/.local/lib/python3.10/site-packages/rest_framework/views.py", line 480, in raise_uncaught_exception
    raise exc
  File "/home/farsana.ka/.local/lib/python3.10/site-packages/rest_framework/views.py", line 506, in dispatch
    response = handler(request, *args, **kwargs)
  File "/home/farsana.ka/Documents/Bus Buddy/source_code/web/bus_buddy_back_end/normal_user/views.py", line 114, in put
    flag=update_all(request, id)
  File "/home/farsana.ka/Documents/Bus Buddy/source_code/web/bus_buddy_back_end/normal_user/views.py", line 56, in update_all
    current_data = User.objects.get(id=user_id)
  File "/home/farsana.ka/.local/lib/python3.10/site-packages/django/db/models/manager.py", line 87, in manager_method
    return getattr(self.get_queryset(), name)(*args, **kwargs)
  File "/home/farsana.ka/.local/lib/python3.10/site-packages/django/db/models/query.py", line 637, in get
    raise self.model.DoesNotExist(
account_manage.models.User.DoesNotExist: User matching query does not exist.
django.request ERROR 2023-10-13 14:30:29,605 log 173621 140306339852288 Internal Server Error: /user/update-profile/547
Traceback (most recent call last):
  File "/home/farsana.ka/.local/lib/python3.10/site-packages/django/core/handlers/exception.py", line 55, in inner
    response = get_response(request)
  File "/home/farsana.ka/.local/lib/python3.10/site-packages/django/core/handlers/base.py", line 197, in _get_response
    response = wrapped_callback(request, *callback_args, **callback_kwargs)
  File "/home/farsana.ka/.local/lib/python3.10/site-packages/django/views/decorators/csrf.py", line 56, in wrapper_view
    return view_func(*args, **kwargs)
  File "/home/farsana.ka/.local/lib/python3.10/site-packages/django/views/generic/base.py", line 104, in view
    return self.dispatch(request, *args, **kwargs)
  File "/home/farsana.ka/.local/lib/python3.10/site-packages/rest_framework/views.py", line 509, in dispatch
    response = self.handle_exception(exc)
  File "/home/farsana.ka/.local/lib/python3.10/site-packages/rest_framework/views.py", line 469, in handle_exception
    self.raise_uncaught_exception(exc)
  File "/home/farsana.ka/.local/lib/python3.10/site-packages/rest_framework/views.py", line 480, in raise_uncaught_exception
    raise exc
  File "/home/farsana.ka/.local/lib/python3.10/site-packages/rest_framework/views.py", line 506, in dispatch
    response = handler(request, *args, **kwargs)
  File "/home/farsana.ka/Documents/Bus Buddy/source_code/web/bus_buddy_back_end/normal_user/views.py", line 114, in put
    flag=update_all(request, id)
  File "/home/farsana.ka/Documents/Bus Buddy/source_code/web/bus_buddy_back_end/normal_user/views.py", line 56, in update_all
    current_data = User.objects.get(id=user_id)
  File "/home/farsana.ka/.local/lib/python3.10/site-packages/django/db/models/manager.py", line 87, in manager_method
    return getattr(self.get_queryset(), name)(*args, **kwargs)
  File "/home/farsana.ka/.local/lib/python3.10/site-packages/django/db/models/query.py", line 637, in get
    raise self.model.DoesNotExist(
account_manage.models.User.DoesNotExist: User matching query does not exist.
django.request ERROR 2023-10-13 14:30:29,626 log 173621 140306339852288 Internal Server Error: /user/update-profile/547
Traceback (most recent call last):
  File "/home/farsana.ka/.local/lib/python3.10/site-packages/django/core/handlers/exception.py", line 55, in inner
    response = get_response(request)
  File "/home/farsana.ka/.local/lib/python3.10/site-packages/django/core/handlers/base.py", line 197, in _get_response
    response = wrapped_callback(request, *callback_args, **callback_kwargs)
  File "/home/farsana.ka/.local/lib/python3.10/site-packages/django/views/decorators/csrf.py", line 56, in wrapper_view
    return view_func(*args, **kwargs)
  File "/home/farsana.ka/.local/lib/python3.10/site-packages/django/views/generic/base.py", line 104, in view
    return self.dispatch(request, *args, **kwargs)
  File "/home/farsana.ka/.local/lib/python3.10/site-packages/rest_framework/views.py", line 509, in dispatch
    response = self.handle_exception(exc)
  File "/home/farsana.ka/.local/lib/python3.10/site-packages/rest_framework/views.py", line 469, in handle_exception
    self.raise_uncaught_exception(exc)
  File "/home/farsana.ka/.local/lib/python3.10/site-packages/rest_framework/views.py", line 480, in raise_uncaught_exception
    raise exc
  File "/home/farsana.ka/.local/lib/python3.10/site-packages/rest_framework/views.py", line 506, in dispatch
    response = handler(request, *args, **kwargs)
  File "/home/farsana.ka/Documents/Bus Buddy/source_code/web/bus_buddy_back_end/normal_user/views.py", line 114, in put
    flag=update_all(request, id)
  File "/home/farsana.ka/Documents/Bus Buddy/source_code/web/bus_buddy_back_end/normal_user/views.py", line 56, in update_all
    current_data = User.objects.get(id=user_id)
  File "/home/farsana.ka/.local/lib/python3.10/site-packages/django/db/models/manager.py", line 87, in manager_method
    return getattr(self.get_queryset(), name)(*args, **kwargs)
  File "/home/farsana.ka/.local/lib/python3.10/site-packages/django/db/models/query.py", line 637, in get
    raise self.model.DoesNotExist(
account_manage.models.User.DoesNotExist: User matching query does not exist.
django.request ERROR 2023-10-13 14:30:29,669 log 173621 140306339852288 Internal Server Error: /user/update-profile/547
Traceback (most recent call last):
  File "/home/farsana.ka/.local/lib/python3.10/site-packages/django/core/handlers/exception.py", line 55, in inner
    response = get_response(request)
  File "/home/farsana.ka/.local/lib/python3.10/site-packages/django/core/handlers/base.py", line 197, in _get_response
    response = wrapped_callback(request, *callback_args, **callback_kwargs)
  File "/home/farsana.ka/.local/lib/python3.10/site-packages/django/views/decorators/csrf.py", line 56, in wrapper_view
    return view_func(*args, **kwargs)
  File "/home/farsana.ka/.local/lib/python3.10/site-packages/django/views/generic/base.py", line 104, in view
    return self.dispatch(request, *args, **kwargs)
  File "/home/farsana.ka/.local/lib/python3.10/site-packages/rest_framework/views.py", line 509, in dispatch
    response = self.handle_exception(exc)
  File "/home/farsana.ka/.local/lib/python3.10/site-packages/rest_framework/views.py", line 469, in handle_exception
    self.raise_uncaught_exception(exc)
  File "/home/farsana.ka/.local/lib/python3.10/site-packages/rest_framework/views.py", line 480, in raise_uncaught_exception
    raise exc
  File "/home/farsana.ka/.local/lib/python3.10/site-packages/rest_framework/views.py", line 506, in dispatch
    response = handler(request, *args, **kwargs)
  File "/home/farsana.ka/Documents/Bus Buddy/source_code/web/bus_buddy_back_end/normal_user/views.py", line 114, in put
    flag=update_all(request, id)
  File "/home/farsana.ka/Documents/Bus Buddy/source_code/web/bus_buddy_back_end/normal_user/views.py", line 56, in update_all
    current_data = User.objects.get(id=user_id)
  File "/home/farsana.ka/.local/lib/python3.10/site-packages/django/db/models/manager.py", line 87, in manager_method
    return getattr(self.get_queryset(), name)(*args, **kwargs)
  File "/home/farsana.ka/.local/lib/python3.10/site-packages/django/db/models/query.py", line 637, in get
    raise self.model.DoesNotExist(
account_manage.models.User.DoesNotExist: User matching query does not exist.
django.request ERROR 2023-10-13 14:30:29,681 log 173621 140306339852288 Internal Server Error: /user/update-profile/547
Traceback (most recent call last):
  File "/home/farsana.ka/.local/lib/python3.10/site-packages/django/core/handlers/exception.py", line 55, in inner
    response = get_response(request)
  File "/home/farsana.ka/.local/lib/python3.10/site-packages/django/core/handlers/base.py", line 197, in _get_response
    response = wrapped_callback(request, *callback_args, **callback_kwargs)
  File "/home/farsana.ka/.local/lib/python3.10/site-packages/django/views/decorators/csrf.py", line 56, in wrapper_view
    return view_func(*args, **kwargs)
  File "/home/farsana.ka/.local/lib/python3.10/site-packages/django/views/generic/base.py", line 104, in view
    return self.dispatch(request, *args, **kwargs)
  File "/home/farsana.ka/.local/lib/python3.10/site-packages/rest_framework/views.py", line 509, in dispatch
    response = self.handle_exception(exc)
  File "/home/farsana.ka/.local/lib/python3.10/site-packages/rest_framework/views.py", line 469, in handle_exception
    self.raise_uncaught_exception(exc)
  File "/home/farsana.ka/.local/lib/python3.10/site-packages/rest_framework/views.py", line 480, in raise_uncaught_exception
    raise exc
  File "/home/farsana.ka/.local/lib/python3.10/site-packages/rest_framework/views.py", line 506, in dispatch
    response = handler(request, *args, **kwargs)
  File "/home/farsana.ka/Documents/Bus Buddy/source_code/web/bus_buddy_back_end/normal_user/views.py", line 114, in put
    flag=update_all(request, id)
  File "/home/farsana.ka/Documents/Bus Buddy/source_code/web/bus_buddy_back_end/normal_user/views.py", line 56, in update_all
    current_data = User.objects.get(id=user_id)
  File "/home/farsana.ka/.local/lib/python3.10/site-packages/django/db/models/manager.py", line 87, in manager_method
    return getattr(self.get_queryset(), name)(*args, **kwargs)
  File "/home/farsana.ka/.local/lib/python3.10/site-packages/django/db/models/query.py", line 637, in get
    raise self.model.DoesNotExist(
account_manage.models.User.DoesNotExist: User matching query does not exist.
django.request ERROR 2023-10-13 14:30:29,695 log 173621 140306339852288 Internal Server Error: /user/update-profile/547
Traceback (most recent call last):
  File "/home/farsana.ka/.local/lib/python3.10/site-packages/django/core/handlers/exception.py", line 55, in inner
    response = get_response(request)
  File "/home/farsana.ka/.local/lib/python3.10/site-packages/django/core/handlers/base.py", line 197, in _get_response
    response = wrapped_callback(request, *callback_args, **callback_kwargs)
  File "/home/farsana.ka/.local/lib/python3.10/site-packages/django/views/decorators/csrf.py", line 56, in wrapper_view
    return view_func(*args, **kwargs)
  File "/home/farsana.ka/.local/lib/python3.10/site-packages/django/views/generic/base.py", line 104, in view
    return self.dispatch(request, *args, **kwargs)
  File "/home/farsana.ka/.local/lib/python3.10/site-packages/rest_framework/views.py", line 509, in dispatch
    response = self.handle_exception(exc)
  File "/home/farsana.ka/.local/lib/python3.10/site-packages/rest_framework/views.py", line 469, in handle_exception
    self.raise_uncaught_exception(exc)
  File "/home/farsana.ka/.local/lib/python3.10/site-packages/rest_framework/views.py", line 480, in raise_uncaught_exception
    raise exc
  File "/home/farsana.ka/.local/lib/python3.10/site-packages/rest_framework/views.py", line 506, in dispatch
    response = handler(request, *args, **kwargs)
  File "/home/farsana.ka/Documents/Bus Buddy/source_code/web/bus_buddy_back_end/normal_user/views.py", line 114, in put
    flag=update_all(request, id)
  File "/home/farsana.ka/Documents/Bus Buddy/source_code/web/bus_buddy_back_end/normal_user/views.py", line 56, in update_all
    current_data = User.objects.get(id=user_id)
  File "/home/farsana.ka/.local/lib/python3.10/site-packages/django/db/models/manager.py", line 87, in manager_method
    return getattr(self.get_queryset(), name)(*args, **kwargs)
  File "/home/farsana.ka/.local/lib/python3.10/site-packages/django/db/models/query.py", line 637, in get
    raise self.model.DoesNotExist(
account_manage.models.User.DoesNotExist: User matching query does not exist.
django.request ERROR 2023-10-13 14:34:49,250 log 173831 140298257063936 Internal Server Error: /user/update-profile/4
Traceback (most recent call last):
  File "/home/farsana.ka/.local/lib/python3.10/site-packages/django/core/handlers/exception.py", line 55, in inner
    response = get_response(request)
  File "/home/farsana.ka/.local/lib/python3.10/site-packages/django/core/handlers/base.py", line 197, in _get_response
    response = wrapped_callback(request, *callback_args, **callback_kwargs)
  File "/home/farsana.ka/.local/lib/python3.10/site-packages/django/views/decorators/csrf.py", line 56, in wrapper_view
    return view_func(*args, **kwargs)
  File "/home/farsana.ka/.local/lib/python3.10/site-packages/django/views/generic/base.py", line 104, in view
    return self.dispatch(request, *args, **kwargs)
  File "/home/farsana.ka/.local/lib/python3.10/site-packages/rest_framework/views.py", line 509, in dispatch
    response = self.handle_exception(exc)
  File "/home/farsana.ka/.local/lib/python3.10/site-packages/rest_framework/views.py", line 469, in handle_exception
    self.raise_uncaught_exception(exc)
  File "/home/farsana.ka/.local/lib/python3.10/site-packages/rest_framework/views.py", line 480, in raise_uncaught_exception
    raise exc
  File "/home/farsana.ka/.local/lib/python3.10/site-packages/rest_framework/views.py", line 506, in dispatch
    response = handler(request, *args, **kwargs)
  File "/home/farsana.ka/Documents/Bus Buddy/source_code/web/bus_buddy_back_end/normal_user/views.py", line 114, in put
    flag=update_all(request, id)
  File "/home/farsana.ka/Documents/Bus Buddy/source_code/web/bus_buddy_back_end/normal_user/views.py", line 56, in update_all
    current_data = User.objects.get(id=user_id)
  File "/home/farsana.ka/.local/lib/python3.10/site-packages/django/db/models/manager.py", line 87, in manager_method
    return getattr(self.get_queryset(), name)(*args, **kwargs)
  File "/home/farsana.ka/.local/lib/python3.10/site-packages/django/db/models/query.py", line 637, in get
    raise self.model.DoesNotExist(
account_manage.models.User.DoesNotExist: User matching query does not exist.
django.request ERROR 2023-10-13 14:34:49,269 log 173831 140298257063936 Internal Server Error: /user/update-profile/4
Traceback (most recent call last):
  File "/home/farsana.ka/.local/lib/python3.10/site-packages/django/core/handlers/exception.py", line 55, in inner
    response = get_response(request)
  File "/home/farsana.ka/.local/lib/python3.10/site-packages/django/core/handlers/base.py", line 197, in _get_response
    response = wrapped_callback(request, *callback_args, **callback_kwargs)
  File "/home/farsana.ka/.local/lib/python3.10/site-packages/django/views/decorators/csrf.py", line 56, in wrapper_view
    return view_func(*args, **kwargs)
  File "/home/farsana.ka/.local/lib/python3.10/site-packages/django/views/generic/base.py", line 104, in view
    return self.dispatch(request, *args, **kwargs)
  File "/home/farsana.ka/.local/lib/python3.10/site-packages/rest_framework/views.py", line 509, in dispatch
    response = self.handle_exception(exc)
  File "/home/farsana.ka/.local/lib/python3.10/site-packages/rest_framework/views.py", line 469, in handle_exception
    self.raise_uncaught_exception(exc)
  File "/home/farsana.ka/.local/lib/python3.10/site-packages/rest_framework/views.py", line 480, in raise_uncaught_exception
    raise exc
  File "/home/farsana.ka/.local/lib/python3.10/site-packages/rest_framework/views.py", line 506, in dispatch
    response = handler(request, *args, **kwargs)
  File "/home/farsana.ka/Documents/Bus Buddy/source_code/web/bus_buddy_back_end/normal_user/views.py", line 114, in put
    flag=update_all(request, id)
  File "/home/farsana.ka/Documents/Bus Buddy/source_code/web/bus_buddy_back_end/normal_user/views.py", line 56, in update_all
    current_data = User.objects.get(id=user_id)
  File "/home/farsana.ka/.local/lib/python3.10/site-packages/django/db/models/manager.py", line 87, in manager_method
    return getattr(self.get_queryset(), name)(*args, **kwargs)
  File "/home/farsana.ka/.local/lib/python3.10/site-packages/django/db/models/query.py", line 637, in get
    raise self.model.DoesNotExist(
account_manage.models.User.DoesNotExist: User matching query does not exist.
django.request ERROR 2023-10-13 14:34:49,292 log 173831 140298257063936 Internal Server Error: /user/update-profile/4
Traceback (most recent call last):
  File "/home/farsana.ka/.local/lib/python3.10/site-packages/django/core/handlers/exception.py", line 55, in inner
    response = get_response(request)
  File "/home/farsana.ka/.local/lib/python3.10/site-packages/django/core/handlers/base.py", line 197, in _get_response
    response = wrapped_callback(request, *callback_args, **callback_kwargs)
  File "/home/farsana.ka/.local/lib/python3.10/site-packages/django/views/decorators/csrf.py", line 56, in wrapper_view
    return view_func(*args, **kwargs)
  File "/home/farsana.ka/.local/lib/python3.10/site-packages/django/views/generic/base.py", line 104, in view
    return self.dispatch(request, *args, **kwargs)
  File "/home/farsana.ka/.local/lib/python3.10/site-packages/rest_framework/views.py", line 509, in dispatch
    response = self.handle_exception(exc)
  File "/home/farsana.ka/.local/lib/python3.10/site-packages/rest_framework/views.py", line 469, in handle_exception
    self.raise_uncaught_exception(exc)
  File "/home/farsana.ka/.local/lib/python3.10/site-packages/rest_framework/views.py", line 480, in raise_uncaught_exception
    raise exc
  File "/home/farsana.ka/.local/lib/python3.10/site-packages/rest_framework/views.py", line 506, in dispatch
    response = handler(request, *args, **kwargs)
  File "/home/farsana.ka/Documents/Bus Buddy/source_code/web/bus_buddy_back_end/normal_user/views.py", line 114, in put
    flag=update_all(request, id)
  File "/home/farsana.ka/Documents/Bus Buddy/source_code/web/bus_buddy_back_end/normal_user/views.py", line 56, in update_all
    current_data = User.objects.get(id=user_id)
  File "/home/farsana.ka/.local/lib/python3.10/site-packages/django/db/models/manager.py", line 87, in manager_method
    return getattr(self.get_queryset(), name)(*args, **kwargs)
  File "/home/farsana.ka/.local/lib/python3.10/site-packages/django/db/models/query.py", line 637, in get
    raise self.model.DoesNotExist(
account_manage.models.User.DoesNotExist: User matching query does not exist.
django.request ERROR 2023-10-13 14:34:49,305 log 173831 140298257063936 Internal Server Error: /user/update-profile/4
Traceback (most recent call last):
  File "/home/farsana.ka/.local/lib/python3.10/site-packages/django/core/handlers/exception.py", line 55, in inner
    response = get_response(request)
  File "/home/farsana.ka/.local/lib/python3.10/site-packages/django/core/handlers/base.py", line 197, in _get_response
    response = wrapped_callback(request, *callback_args, **callback_kwargs)
  File "/home/farsana.ka/.local/lib/python3.10/site-packages/django/views/decorators/csrf.py", line 56, in wrapper_view
    return view_func(*args, **kwargs)
  File "/home/farsana.ka/.local/lib/python3.10/site-packages/django/views/generic/base.py", line 104, in view
    return self.dispatch(request, *args, **kwargs)
  File "/home/farsana.ka/.local/lib/python3.10/site-packages/rest_framework/views.py", line 509, in dispatch
    response = self.handle_exception(exc)
  File "/home/farsana.ka/.local/lib/python3.10/site-packages/rest_framework/views.py", line 469, in handle_exception
    self.raise_uncaught_exception(exc)
  File "/home/farsana.ka/.local/lib/python3.10/site-packages/rest_framework/views.py", line 480, in raise_uncaught_exception
    raise exc
  File "/home/farsana.ka/.local/lib/python3.10/site-packages/rest_framework/views.py", line 506, in dispatch
    response = handler(request, *args, **kwargs)
  File "/home/farsana.ka/Documents/Bus Buddy/source_code/web/bus_buddy_back_end/normal_user/views.py", line 114, in put
    flag=update_all(request, id)
  File "/home/farsana.ka/Documents/Bus Buddy/source_code/web/bus_buddy_back_end/normal_user/views.py", line 56, in update_all
    current_data = User.objects.get(id=user_id)
  File "/home/farsana.ka/.local/lib/python3.10/site-packages/django/db/models/manager.py", line 87, in manager_method
    return getattr(self.get_queryset(), name)(*args, **kwargs)
  File "/home/farsana.ka/.local/lib/python3.10/site-packages/django/db/models/query.py", line 637, in get
    raise self.model.DoesNotExist(
account_manage.models.User.DoesNotExist: User matching query does not exist.
django.request ERROR 2023-10-13 14:34:49,318 log 173831 140298257063936 Internal Server Error: /user/update-profile/4
Traceback (most recent call last):
  File "/home/farsana.ka/.local/lib/python3.10/site-packages/django/core/handlers/exception.py", line 55, in inner
    response = get_response(request)
  File "/home/farsana.ka/.local/lib/python3.10/site-packages/django/core/handlers/base.py", line 197, in _get_response
    response = wrapped_callback(request, *callback_args, **callback_kwargs)
  File "/home/farsana.ka/.local/lib/python3.10/site-packages/django/views/decorators/csrf.py", line 56, in wrapper_view
    return view_func(*args, **kwargs)
  File "/home/farsana.ka/.local/lib/python3.10/site-packages/django/views/generic/base.py", line 104, in view
    return self.dispatch(request, *args, **kwargs)
  File "/home/farsana.ka/.local/lib/python3.10/site-packages/rest_framework/views.py", line 509, in dispatch
    response = self.handle_exception(exc)
  File "/home/farsana.ka/.local/lib/python3.10/site-packages/rest_framework/views.py", line 469, in handle_exception
    self.raise_uncaught_exception(exc)
  File "/home/farsana.ka/.local/lib/python3.10/site-packages/rest_framework/views.py", line 480, in raise_uncaught_exception
    raise exc
  File "/home/farsana.ka/.local/lib/python3.10/site-packages/rest_framework/views.py", line 506, in dispatch
    response = handler(request, *args, **kwargs)
  File "/home/farsana.ka/Documents/Bus Buddy/source_code/web/bus_buddy_back_end/normal_user/views.py", line 114, in put
    flag=update_all(request, id)
  File "/home/farsana.ka/Documents/Bus Buddy/source_code/web/bus_buddy_back_end/normal_user/views.py", line 56, in update_all
    current_data = User.objects.get(id=user_id)
  File "/home/farsana.ka/.local/lib/python3.10/site-packages/django/db/models/manager.py", line 87, in manager_method
    return getattr(self.get_queryset(), name)(*args, **kwargs)
  File "/home/farsana.ka/.local/lib/python3.10/site-packages/django/db/models/query.py", line 637, in get
    raise self.model.DoesNotExist(
account_manage.models.User.DoesNotExist: User matching query does not exist.
django.request ERROR 2023-10-13 14:37:19,720 log 173982 140121047220224 Internal Server Error: /user/update-profile/1
Traceback (most recent call last):
  File "/home/farsana.ka/.local/lib/python3.10/site-packages/django/core/handlers/exception.py", line 55, in inner
    response = get_response(request)
  File "/home/farsana.ka/.local/lib/python3.10/site-packages/django/core/handlers/base.py", line 197, in _get_response
    response = wrapped_callback(request, *callback_args, **callback_kwargs)
  File "/home/farsana.ka/.local/lib/python3.10/site-packages/django/views/decorators/csrf.py", line 56, in wrapper_view
    return view_func(*args, **kwargs)
  File "/home/farsana.ka/.local/lib/python3.10/site-packages/django/views/generic/base.py", line 104, in view
    return self.dispatch(request, *args, **kwargs)
  File "/home/farsana.ka/.local/lib/python3.10/site-packages/rest_framework/views.py", line 509, in dispatch
    response = self.handle_exception(exc)
  File "/home/farsana.ka/.local/lib/python3.10/site-packages/rest_framework/views.py", line 469, in handle_exception
    self.raise_uncaught_exception(exc)
  File "/home/farsana.ka/.local/lib/python3.10/site-packages/rest_framework/views.py", line 480, in raise_uncaught_exception
    raise exc
  File "/home/farsana.ka/.local/lib/python3.10/site-packages/rest_framework/views.py", line 506, in dispatch
    response = handler(request, *args, **kwargs)
  File "/home/farsana.ka/Documents/Bus Buddy/source_code/web/bus_buddy_back_end/normal_user/views.py", line 114, in put
    flag=update_all(request, id)
  File "/home/farsana.ka/Documents/Bus Buddy/source_code/web/bus_buddy_back_end/normal_user/views.py", line 56, in update_all
    current_data = User.objects.get(id=user_id)
  File "/home/farsana.ka/.local/lib/python3.10/site-packages/django/db/models/manager.py", line 87, in manager_method
    return getattr(self.get_queryset(), name)(*args, **kwargs)
  File "/home/farsana.ka/.local/lib/python3.10/site-packages/django/db/models/query.py", line 637, in get
    raise self.model.DoesNotExist(
account_manage.models.User.DoesNotExist: User matching query does not exist.
django.request ERROR 2023-10-13 14:37:19,740 log 173982 140121047220224 Internal Server Error: /user/update-profile/1
Traceback (most recent call last):
  File "/home/farsana.ka/.local/lib/python3.10/site-packages/django/core/handlers/exception.py", line 55, in inner
    response = get_response(request)
  File "/home/farsana.ka/.local/lib/python3.10/site-packages/django/core/handlers/base.py", line 197, in _get_response
    response = wrapped_callback(request, *callback_args, **callback_kwargs)
  File "/home/farsana.ka/.local/lib/python3.10/site-packages/django/views/decorators/csrf.py", line 56, in wrapper_view
    return view_func(*args, **kwargs)
  File "/home/farsana.ka/.local/lib/python3.10/site-packages/django/views/generic/base.py", line 104, in view
    return self.dispatch(request, *args, **kwargs)
  File "/home/farsana.ka/.local/lib/python3.10/site-packages/rest_framework/views.py", line 509, in dispatch
    response = self.handle_exception(exc)
  File "/home/farsana.ka/.local/lib/python3.10/site-packages/rest_framework/views.py", line 469, in handle_exception
    self.raise_uncaught_exception(exc)
  File "/home/farsana.ka/.local/lib/python3.10/site-packages/rest_framework/views.py", line 480, in raise_uncaught_exception
    raise exc
  File "/home/farsana.ka/.local/lib/python3.10/site-packages/rest_framework/views.py", line 506, in dispatch
    response = handler(request, *args, **kwargs)
  File "/home/farsana.ka/Documents/Bus Buddy/source_code/web/bus_buddy_back_end/normal_user/views.py", line 114, in put
    flag=update_all(request, id)
  File "/home/farsana.ka/Documents/Bus Buddy/source_code/web/bus_buddy_back_end/normal_user/views.py", line 56, in update_all
    current_data = User.objects.get(id=user_id)
  File "/home/farsana.ka/.local/lib/python3.10/site-packages/django/db/models/manager.py", line 87, in manager_method
    return getattr(self.get_queryset(), name)(*args, **kwargs)
  File "/home/farsana.ka/.local/lib/python3.10/site-packages/django/db/models/query.py", line 637, in get
    raise self.model.DoesNotExist(
account_manage.models.User.DoesNotExist: User matching query does not exist.
django.request ERROR 2023-10-13 14:37:19,778 log 173982 140121047220224 Internal Server Error: /user/update-profile/1
Traceback (most recent call last):
  File "/home/farsana.ka/.local/lib/python3.10/site-packages/django/core/handlers/exception.py", line 55, in inner
    response = get_response(request)
  File "/home/farsana.ka/.local/lib/python3.10/site-packages/django/core/handlers/base.py", line 197, in _get_response
    response = wrapped_callback(request, *callback_args, **callback_kwargs)
  File "/home/farsana.ka/.local/lib/python3.10/site-packages/django/views/decorators/csrf.py", line 56, in wrapper_view
    return view_func(*args, **kwargs)
  File "/home/farsana.ka/.local/lib/python3.10/site-packages/django/views/generic/base.py", line 104, in view
    return self.dispatch(request, *args, **kwargs)
  File "/home/farsana.ka/.local/lib/python3.10/site-packages/rest_framework/views.py", line 509, in dispatch
    response = self.handle_exception(exc)
  File "/home/farsana.ka/.local/lib/python3.10/site-packages/rest_framework/views.py", line 469, in handle_exception
    self.raise_uncaught_exception(exc)
  File "/home/farsana.ka/.local/lib/python3.10/site-packages/rest_framework/views.py", line 480, in raise_uncaught_exception
    raise exc
  File "/home/farsana.ka/.local/lib/python3.10/site-packages/rest_framework/views.py", line 506, in dispatch
    response = handler(request, *args, **kwargs)
  File "/home/farsana.ka/Documents/Bus Buddy/source_code/web/bus_buddy_back_end/normal_user/views.py", line 114, in put
    flag=update_all(request, id)
  File "/home/farsana.ka/Documents/Bus Buddy/source_code/web/bus_buddy_back_end/normal_user/views.py", line 56, in update_all
    current_data = User.objects.get(id=user_id)
  File "/home/farsana.ka/.local/lib/python3.10/site-packages/django/db/models/manager.py", line 87, in manager_method
    return getattr(self.get_queryset(), name)(*args, **kwargs)
  File "/home/farsana.ka/.local/lib/python3.10/site-packages/django/db/models/query.py", line 637, in get
    raise self.model.DoesNotExist(
account_manage.models.User.DoesNotExist: User matching query does not exist.
django.request ERROR 2023-10-13 14:37:19,808 log 173982 140121047220224 Internal Server Error: /user/update-profile/1
Traceback (most recent call last):
  File "/home/farsana.ka/.local/lib/python3.10/site-packages/django/core/handlers/exception.py", line 55, in inner
    response = get_response(request)
  File "/home/farsana.ka/.local/lib/python3.10/site-packages/django/core/handlers/base.py", line 197, in _get_response
    response = wrapped_callback(request, *callback_args, **callback_kwargs)
  File "/home/farsana.ka/.local/lib/python3.10/site-packages/django/views/decorators/csrf.py", line 56, in wrapper_view
    return view_func(*args, **kwargs)
  File "/home/farsana.ka/.local/lib/python3.10/site-packages/django/views/generic/base.py", line 104, in view
    return self.dispatch(request, *args, **kwargs)
  File "/home/farsana.ka/.local/lib/python3.10/site-packages/rest_framework/views.py", line 509, in dispatch
    response = self.handle_exception(exc)
  File "/home/farsana.ka/.local/lib/python3.10/site-packages/rest_framework/views.py", line 469, in handle_exception
    self.raise_uncaught_exception(exc)
  File "/home/farsana.ka/.local/lib/python3.10/site-packages/rest_framework/views.py", line 480, in raise_uncaught_exception
    raise exc
  File "/home/farsana.ka/.local/lib/python3.10/site-packages/rest_framework/views.py", line 506, in dispatch
    response = handler(request, *args, **kwargs)
  File "/home/farsana.ka/Documents/Bus Buddy/source_code/web/bus_buddy_back_end/normal_user/views.py", line 114, in put
    flag=update_all(request, id)
  File "/home/farsana.ka/Documents/Bus Buddy/source_code/web/bus_buddy_back_end/normal_user/views.py", line 56, in update_all
    current_data = User.objects.get(id=user_id)
  File "/home/farsana.ka/.local/lib/python3.10/site-packages/django/db/models/manager.py", line 87, in manager_method
    return getattr(self.get_queryset(), name)(*args, **kwargs)
  File "/home/farsana.ka/.local/lib/python3.10/site-packages/django/db/models/query.py", line 637, in get
    raise self.model.DoesNotExist(
account_manage.models.User.DoesNotExist: User matching query does not exist.
django.request ERROR 2023-10-13 14:37:19,824 log 173982 140121047220224 Internal Server Error: /user/update-profile/1
Traceback (most recent call last):
  File "/home/farsana.ka/.local/lib/python3.10/site-packages/django/core/handlers/exception.py", line 55, in inner
    response = get_response(request)
  File "/home/farsana.ka/.local/lib/python3.10/site-packages/django/core/handlers/base.py", line 197, in _get_response
    response = wrapped_callback(request, *callback_args, **callback_kwargs)
  File "/home/farsana.ka/.local/lib/python3.10/site-packages/django/views/decorators/csrf.py", line 56, in wrapper_view
    return view_func(*args, **kwargs)
  File "/home/farsana.ka/.local/lib/python3.10/site-packages/django/views/generic/base.py", line 104, in view
    return self.dispatch(request, *args, **kwargs)
  File "/home/farsana.ka/.local/lib/python3.10/site-packages/rest_framework/views.py", line 509, in dispatch
    response = self.handle_exception(exc)
  File "/home/farsana.ka/.local/lib/python3.10/site-packages/rest_framework/views.py", line 469, in handle_exception
    self.raise_uncaught_exception(exc)
  File "/home/farsana.ka/.local/lib/python3.10/site-packages/rest_framework/views.py", line 480, in raise_uncaught_exception
    raise exc
  File "/home/farsana.ka/.local/lib/python3.10/site-packages/rest_framework/views.py", line 506, in dispatch
    response = handler(request, *args, **kwargs)
  File "/home/farsana.ka/Documents/Bus Buddy/source_code/web/bus_buddy_back_end/normal_user/views.py", line 114, in put
    flag=update_all(request, id)
  File "/home/farsana.ka/Documents/Bus Buddy/source_code/web/bus_buddy_back_end/normal_user/views.py", line 56, in update_all
    current_data = User.objects.get(id=user_id)
  File "/home/farsana.ka/.local/lib/python3.10/site-packages/django/db/models/manager.py", line 87, in manager_method
    return getattr(self.get_queryset(), name)(*args, **kwargs)
  File "/home/farsana.ka/.local/lib/python3.10/site-packages/django/db/models/query.py", line 637, in get
    raise self.model.DoesNotExist(
account_manage.models.User.DoesNotExist: User matching query does not exist.
django.request ERROR 2023-10-24 05:25:17,423 log 19348 140247504512576 Internal Server Error: /bus-owner/add-seat-details
Traceback (most recent call last):
  File "/home/farsana.ka/Documents/Bus Buddy/source_code/web/env/lib/python3.10/site-packages/django/core/handlers/exception.py", line 55, in inner
    response = get_response(request)
  File "/home/farsana.ka/Documents/Bus Buddy/source_code/web/env/lib/python3.10/site-packages/django/utils/deprecation.py", line 136, in __call__
    response = self.process_response(request, response)
  File "/home/farsana.ka/Documents/Bus Buddy/source_code/web/env/lib/python3.10/site-packages/django/middleware/common.py", line 108, in process_response
    return self.response_redirect_class(self.get_full_path_with_slash(request))
  File "/home/farsana.ka/Documents/Bus Buddy/source_code/web/env/lib/python3.10/site-packages/django/middleware/common.py", line 87, in get_full_path_with_slash
    raise RuntimeError(
RuntimeError: You called this URL via POST, but the URL doesn't end in a slash and you have APPEND_SLASH set. Django can't redirect to the slash URL while maintaining POST data. Change your form to point to 127.0.0.1:8000/bus-owner/add-seat-details/ (note the trailing slash), or set APPEND_SLASH=False in your Django settings.
django.request ERROR 2023-10-24 05:25:38,363 log 19348 140247504512576 Internal Server Error: /bus-owner/add-seat-details/
Traceback (most recent call last):
  File "/home/farsana.ka/Documents/Bus Buddy/source_code/web/env/lib/python3.10/site-packages/django/core/handlers/exception.py", line 55, in inner
    response = get_response(request)
  File "/home/farsana.ka/Documents/Bus Buddy/source_code/web/env/lib/python3.10/site-packages/django/core/handlers/base.py", line 197, in _get_response
    response = wrapped_callback(request, *callback_args, **callback_kwargs)
  File "/home/farsana.ka/Documents/Bus Buddy/source_code/web/env/lib/python3.10/site-packages/django/views/decorators/csrf.py", line 56, in wrapper_view
    return view_func(*args, **kwargs)
  File "/home/farsana.ka/Documents/Bus Buddy/source_code/web/env/lib/python3.10/site-packages/django/views/generic/base.py", line 104, in view
    return self.dispatch(request, *args, **kwargs)
  File "/home/farsana.ka/Documents/Bus Buddy/source_code/web/env/lib/python3.10/site-packages/rest_framework/views.py", line 509, in dispatch
    response = self.handle_exception(exc)
  File "/home/farsana.ka/Documents/Bus Buddy/source_code/web/env/lib/python3.10/site-packages/rest_framework/views.py", line 469, in handle_exception
    self.raise_uncaught_exception(exc)
  File "/home/farsana.ka/Documents/Bus Buddy/source_code/web/env/lib/python3.10/site-packages/rest_framework/views.py", line 480, in raise_uncaught_exception
    raise exc
  File "/home/farsana.ka/Documents/Bus Buddy/source_code/web/env/lib/python3.10/site-packages/rest_framework/views.py", line 506, in dispatch
    response = handler(request, *args, **kwargs)
TypeError: AddSeatDetails.post() missing 1 required positional argument: 'id'
django.request ERROR 2023-10-24 05:27:01,461 log 19659 140082361132608 Internal Server Error: /bus-owner/add-seat-details/
Traceback (most recent call last):
  File "/home/farsana.ka/Documents/Bus Buddy/source_code/web/env/lib/python3.10/site-packages/django/core/handlers/exception.py", line 55, in inner
    response = get_response(request)
  File "/home/farsana.ka/Documents/Bus Buddy/source_code/web/env/lib/python3.10/site-packages/django/core/handlers/base.py", line 197, in _get_response
    response = wrapped_callback(request, *callback_args, **callback_kwargs)
  File "/home/farsana.ka/Documents/Bus Buddy/source_code/web/env/lib/python3.10/site-packages/django/views/decorators/csrf.py", line 56, in wrapper_view
    return view_func(*args, **kwargs)
  File "/home/farsana.ka/Documents/Bus Buddy/source_code/web/env/lib/python3.10/site-packages/django/views/generic/base.py", line 104, in view
    return self.dispatch(request, *args, **kwargs)
  File "/home/farsana.ka/Documents/Bus Buddy/source_code/web/env/lib/python3.10/site-packages/rest_framework/views.py", line 509, in dispatch
    response = self.handle_exception(exc)
  File "/home/farsana.ka/Documents/Bus Buddy/source_code/web/env/lib/python3.10/site-packages/rest_framework/views.py", line 469, in handle_exception
    self.raise_uncaught_exception(exc)
  File "/home/farsana.ka/Documents/Bus Buddy/source_code/web/env/lib/python3.10/site-packages/rest_framework/views.py", line 480, in raise_uncaught_exception
    raise exc
  File "/home/farsana.ka/Documents/Bus Buddy/source_code/web/env/lib/python3.10/site-packages/rest_framework/views.py", line 506, in dispatch
    response = handler(request, *args, **kwargs)
TypeError: AddSeatDetails.post() missing 1 required positional argument: 'id'
